NAMESPACE       LAST SEEN   TYPE      REASON                 OBJECT                                                                                   MESSAGE
kubescape       9m17s       Warning   FailedScheduling       pod/kubescape-exporter-29595390-8z6nw                                                    0/3 nodes are available: 1 Insufficient cpu, 1 node(s) had untolerated taint {node-role.kubernetes.io/control-plane: }, 1 node(s) had untolerated taint {node.kubernetes.io/unreachable: }. preemption: 0/3 nodes are available: 1 No preemption victims found for incoming pod, 2 Preemption is not helpful for scheduling..
kubescape       9m17s       Warning   FailedScheduling       pod/kubescape-exporter-29595465-kx4wx                                                    0/3 nodes are available: 1 Insufficient cpu, 1 node(s) had untolerated taint {node-role.kubernetes.io/control-plane: }, 1 node(s) had untolerated taint {node.kubernetes.io/unreachable: }. preemption: 0/3 nodes are available: 1 No preemption victims found for incoming pod, 2 Preemption is not helpful for scheduling..
free5gc         9m16s       Warning   FailedScheduling       pod/free5gc-free5gc-udm-udm-7d8c49654f-dfrrm                                             0/3 nodes are available: 1 Insufficient cpu, 1 node(s) had untolerated taint {node-role.kubernetes.io/control-plane: }, 1 node(s) had untolerated taint {node.kubernetes.io/unreachable: }. preemption: 0/3 nodes are available: 1 No preemption victims found for incoming pod, 2 Preemption is not helpful for scheduling..
trivy-system    25m         Warning   FailedScheduling       pod/scan-vulnerabilityreport-f8bcff7cd-vqtxj                                             skip schedule deleting pod: trivy-system/scan-vulnerabilityreport-f8bcff7cd-vqtxj
trivy-system    29m         Warning   FailedScheduling       pod/scan-vulnerabilityreport-f8bcff7cd-vqtxj                                             0/3 nodes are available: 1 Insufficient cpu, 1 node(s) had untolerated taint {node-role.kubernetes.io/control-plane: }, 1 node(s) had untolerated taint {node.kubernetes.io/unreachable: }. preemption: 0/3 nodes are available: 1 No preemption victims found for incoming pod, 2 Preemption is not helpful for scheduling..
trivy-system    35m         Warning   FailedScheduling       pod/scan-vulnerabilityreport-f8bcff7cd-vqtxj                                             0/3 nodes are available: 1 Insufficient cpu, 1 node(s) had untolerated taint {node-role.kubernetes.io/control-plane: }, 1 node(s) had untolerated taint {node.kubernetes.io/unreachable: }. preemption: 0/3 nodes are available: 1 No preemption victims found for incoming pod, 2 Preemption is not helpful for scheduling..
trivy-system    15m         Warning   FailedScheduling       pod/scan-vulnerabilityreport-d778d5cc4-277zj                                             skip schedule deleting pod: trivy-system/scan-vulnerabilityreport-d778d5cc4-277zj
trivy-system    19m         Warning   FailedScheduling       pod/scan-vulnerabilityreport-d778d5cc4-277zj                                             0/3 nodes are available: 1 Insufficient cpu, 1 node(s) had untolerated taint {node-role.kubernetes.io/control-plane: }, 1 node(s) had untolerated taint {node.kubernetes.io/unreachable: }. preemption: 0/3 nodes are available: 1 No preemption victims found for incoming pod, 2 Preemption is not helpful for scheduling..
trivy-system    25m         Warning   FailedScheduling       pod/scan-vulnerabilityreport-d778d5cc4-277zj                                             0/3 nodes are available: 1 Insufficient cpu, 1 node(s) had untolerated taint {node-role.kubernetes.io/control-plane: }, 1 node(s) had untolerated taint {node.kubernetes.io/unreachable: }. preemption: 0/3 nodes are available: 1 No preemption victims found for incoming pod, 2 Preemption is not helpful for scheduling..
trivy-system    56m         Warning   FailedScheduling       pod/scan-vulnerabilityreport-c7b79b858-5cqj8                                             skip schedule deleting pod: trivy-system/scan-vulnerabilityreport-c7b79b858-5cqj8
trivy-system    59m         Warning   FailedScheduling       pod/scan-vulnerabilityreport-c7b79b858-5cqj8                                             0/3 nodes are available: 1 Insufficient cpu, 1 node(s) had untolerated taint {node-role.kubernetes.io/control-plane: }, 1 node(s) had untolerated taint {node.kubernetes.io/unreachable: }. preemption: 0/3 nodes are available: 1 No preemption victims found for incoming pod, 2 Preemption is not helpful for scheduling..
trivy-system    5m50s       Warning   FailedScheduling       pod/scan-vulnerabilityreport-8585759d76-d2tg9                                            skip schedule deleting pod: trivy-system/scan-vulnerabilityreport-8585759d76-d2tg9
trivy-system    9m15s       Warning   FailedScheduling       pod/scan-vulnerabilityreport-8585759d76-d2tg9                                            0/3 nodes are available: 1 Insufficient cpu, 1 node(s) had untolerated taint {node-role.kubernetes.io/control-plane: }, 1 node(s) had untolerated taint {node.kubernetes.io/unreachable: }. preemption: 0/3 nodes are available: 1 No preemption victims found for incoming pod, 2 Preemption is not helpful for scheduling..
trivy-system    15m         Warning   FailedScheduling       pod/scan-vulnerabilityreport-8585759d76-d2tg9                                            0/3 nodes are available: 1 Insufficient cpu, 1 node(s) had untolerated taint {node-role.kubernetes.io/control-plane: }, 1 node(s) had untolerated taint {node.kubernetes.io/unreachable: }. preemption: 0/3 nodes are available: 1 No preemption victims found for incoming pod, 2 Preemption is not helpful for scheduling..
trivy-system    56m         Warning   FailedScheduling       pod/scan-vulnerabilityreport-8585759d76-bxrqt                                            skip schedule deleting pod: trivy-system/scan-vulnerabilityreport-8585759d76-bxrqt
trivy-system    59m         Warning   FailedScheduling       pod/scan-vulnerabilityreport-8585759d76-bxrqt                                            0/3 nodes are available: 1 Insufficient cpu, 1 node(s) had untolerated taint {node-role.kubernetes.io/control-plane: }, 1 node(s) had untolerated taint {node.kubernetes.io/unreachable: }. preemption: 0/3 nodes are available: 1 No preemption victims found for incoming pod, 2 Preemption is not helpful for scheduling..
trivy-system    5m48s       Warning   FailedScheduling       pod/scan-vulnerabilityreport-7d59678b4f-x466d                                            skip schedule deleting pod: trivy-system/scan-vulnerabilityreport-7d59678b4f-x466d
trivy-system    9m15s       Warning   FailedScheduling       pod/scan-vulnerabilityreport-7d59678b4f-x466d                                            0/3 nodes are available: 1 Insufficient cpu, 1 node(s) had untolerated taint {node-role.kubernetes.io/control-plane: }, 1 node(s) had untolerated taint {node.kubernetes.io/unreachable: }. preemption: 0/3 nodes are available: 1 No preemption victims found for incoming pod, 2 Preemption is not helpful for scheduling..
kubescape       9m16s       Warning   FailedScheduling       pod/kubescape-exporter-29594040-q4ctc                                                    0/3 nodes are available: 1 Insufficient cpu, 1 node(s) had untolerated taint {node-role.kubernetes.io/control-plane: }, 1 node(s) had untolerated taint {node.kubernetes.io/unreachable: }. preemption: 0/3 nodes are available: 1 No preemption victims found for incoming pod, 2 Preemption is not helpful for scheduling..
kubescape       9m16s       Warning   FailedScheduling       pod/kubescape-exporter-29594045-xtjts                                                    0/3 nodes are available: 1 Insufficient cpu, 1 node(s) had untolerated taint {node-role.kubernetes.io/control-plane: }, 1 node(s) had untolerated taint {node.kubernetes.io/unreachable: }. preemption: 0/3 nodes are available: 1 No preemption victims found for incoming pod, 2 Preemption is not helpful for scheduling..
kubescape       9m16s       Warning   FailedScheduling       pod/kubescape-exporter-29594050-8qmkn                                                    0/3 nodes are available: 1 Insufficient cpu, 1 node(s) had untolerated taint {node-role.kubernetes.io/control-plane: }, 1 node(s) had untolerated taint {node.kubernetes.io/unreachable: }. preemption: 0/3 nodes are available: 1 No preemption victims found for incoming pod, 2 Preemption is not helpful for scheduling..
kubescape       9m16s       Warning   FailedScheduling       pod/kubescape-exporter-29594055-4s6jf                                                    0/3 nodes are available: 1 Insufficient cpu, 1 node(s) had untolerated taint {node-role.kubernetes.io/control-plane: }, 1 node(s) had untolerated taint {node.kubernetes.io/unreachable: }. preemption: 0/3 nodes are available: 1 No preemption victims found for incoming pod, 2 Preemption is not helpful for scheduling..
kubescape       9m15s       Warning   FailedScheduling       pod/kubescape-exporter-29594060-b4gg9                                                    0/3 nodes are available: 1 Insufficient cpu, 1 node(s) had untolerated taint {node-role.kubernetes.io/control-plane: }, 1 node(s) had untolerated taint {node.kubernetes.io/unreachable: }. preemption: 0/3 nodes are available: 1 No preemption victims found for incoming pod, 2 Preemption is not helpful for scheduling..
kubescape       9m16s       Warning   FailedScheduling       pod/kubescape-exporter-29594065-sc6nv                                                    0/3 nodes are available: 1 Insufficient cpu, 1 node(s) had untolerated taint {node-role.kubernetes.io/control-plane: }, 1 node(s) had untolerated taint {node.kubernetes.io/unreachable: }. preemption: 0/3 nodes are available: 1 No preemption victims found for incoming pod, 2 Preemption is not helpful for scheduling..
kubescape       9m15s       Warning   FailedScheduling       pod/kubescape-exporter-29594070-2gmqn                                                    0/3 nodes are available: 1 Insufficient cpu, 1 node(s) had untolerated taint {node-role.kubernetes.io/control-plane: }, 1 node(s) had untolerated taint {node.kubernetes.io/unreachable: }. preemption: 0/3 nodes are available: 1 No preemption victims found for incoming pod, 2 Preemption is not helpful for scheduling..
kubescape       9m15s       Warning   FailedScheduling       pod/kubescape-exporter-29594075-dwg5x                                                    0/3 nodes are available: 1 Insufficient cpu, 1 node(s) had untolerated taint {node-role.kubernetes.io/control-plane: }, 1 node(s) had untolerated taint {node.kubernetes.io/unreachable: }. preemption: 0/3 nodes are available: 1 No preemption victims found for incoming pod, 2 Preemption is not helpful for scheduling..
kubescape       9m15s       Warning   FailedScheduling       pod/kubescape-exporter-29594080-w78br                                                    0/3 nodes are available: 1 Insufficient cpu, 1 node(s) had untolerated taint {node-role.kubernetes.io/control-plane: }, 1 node(s) had untolerated taint {node.kubernetes.io/unreachable: }. preemption: 0/3 nodes are available: 1 No preemption victims found for incoming pod, 2 Preemption is not helpful for scheduling..
kubescape       9m15s       Warning   FailedScheduling       pod/kubescape-exporter-29594085-nxj9b                                                    0/3 nodes are available: 1 Insufficient cpu, 1 node(s) had untolerated taint {node-role.kubernetes.io/control-plane: }, 1 node(s) had untolerated taint {node.kubernetes.io/unreachable: }. preemption: 0/3 nodes are available: 1 No preemption victims found for incoming pod, 2 Preemption is not helpful for scheduling..
kubescape       9m16s       Warning   FailedScheduling       pod/kubescape-exporter-29594090-bk9xh                                                    0/3 nodes are available: 1 Insufficient cpu, 1 node(s) had untolerated taint {node-role.kubernetes.io/control-plane: }, 1 node(s) had untolerated taint {node.kubernetes.io/unreachable: }. preemption: 0/3 nodes are available: 1 No preemption victims found for incoming pod, 2 Preemption is not helpful for scheduling..
kubescape       9m16s       Warning   FailedScheduling       pod/kubescape-exporter-29594095-fznzb                                                    0/3 nodes are available: 1 Insufficient cpu, 1 node(s) had untolerated taint {node-role.kubernetes.io/control-plane: }, 1 node(s) had untolerated taint {node.kubernetes.io/unreachable: }. preemption: 0/3 nodes are available: 1 No preemption victims found for incoming pod, 2 Preemption is not helpful for scheduling..
kubescape       9m16s       Warning   FailedScheduling       pod/kubescape-exporter-29594100-r6dw6                                                    0/3 nodes are available: 1 Insufficient cpu, 1 node(s) had untolerated taint {node-role.kubernetes.io/control-plane: }, 1 node(s) had untolerated taint {node.kubernetes.io/unreachable: }. preemption: 0/3 nodes are available: 1 No preemption victims found for incoming pod, 2 Preemption is not helpful for scheduling..
kubescape       9m16s       Warning   FailedScheduling       pod/kubescape-exporter-29594105-fxr8n                                                    0/3 nodes are available: 1 Insufficient cpu, 1 node(s) had untolerated taint {node-role.kubernetes.io/control-plane: }, 1 node(s) had untolerated taint {node.kubernetes.io/unreachable: }. preemption: 0/3 nodes are available: 1 No preemption victims found for incoming pod, 2 Preemption is not helpful for scheduling..
kubescape       9m17s       Warning   FailedScheduling       pod/kubescape-exporter-29594110-lth22                                                    0/3 nodes are available: 1 Insufficient cpu, 1 node(s) had untolerated taint {node-role.kubernetes.io/control-plane: }, 1 node(s) had untolerated taint {node.kubernetes.io/unreachable: }. preemption: 0/3 nodes are available: 1 No preemption victims found for incoming pod, 2 Preemption is not helpful for scheduling..
kubescape       9m17s       Warning   FailedScheduling       pod/kubescape-exporter-29594115-2n8jq                                                    0/3 nodes are available: 1 Insufficient cpu, 1 node(s) had untolerated taint {node-role.kubernetes.io/control-plane: }, 1 node(s) had untolerated taint {node.kubernetes.io/unreachable: }. preemption: 0/3 nodes are available: 1 No preemption victims found for incoming pod, 2 Preemption is not helpful for scheduling..
kubescape       9m17s       Warning   FailedScheduling       pod/kubescape-exporter-29594120-kpskt                                                    0/3 nodes are available: 1 Insufficient cpu, 1 node(s) had untolerated taint {node-role.kubernetes.io/control-plane: }, 1 node(s) had untolerated taint {node.kubernetes.io/unreachable: }. preemption: 0/3 nodes are available: 1 No preemption victims found for incoming pod, 2 Preemption is not helpful for scheduling..
kubescape       9m17s       Warning   FailedScheduling       pod/kubescape-exporter-29594125-ssnch                                                    0/3 nodes are available: 1 Insufficient cpu, 1 node(s) had untolerated taint {node-role.kubernetes.io/control-plane: }, 1 node(s) had untolerated taint {node.kubernetes.io/unreachable: }. preemption: 0/3 nodes are available: 1 No preemption victims found for incoming pod, 2 Preemption is not helpful for scheduling..
kubescape       9m17s       Warning   FailedScheduling       pod/kubescape-exporter-29594130-kqz8z                                                    0/3 nodes are available: 1 Insufficient cpu, 1 node(s) had untolerated taint {node-role.kubernetes.io/control-plane: }, 1 node(s) had untolerated taint {node.kubernetes.io/unreachable: }. preemption: 0/3 nodes are available: 1 No preemption victims found for incoming pod, 2 Preemption is not helpful for scheduling..
kubescape       9m17s       Warning   FailedScheduling       pod/kubescape-exporter-29594135-rdsbp                                                    0/3 nodes are available: 1 Insufficient cpu, 1 node(s) had untolerated taint {node-role.kubernetes.io/control-plane: }, 1 node(s) had untolerated taint {node.kubernetes.io/unreachable: }. preemption: 0/3 nodes are available: 1 No preemption victims found for incoming pod, 2 Preemption is not helpful for scheduling..
kubescape       9m17s       Warning   FailedScheduling       pod/kubescape-exporter-29594140-6fn7x                                                    0/3 nodes are available: 1 Insufficient cpu, 1 node(s) had untolerated taint {node-role.kubernetes.io/control-plane: }, 1 node(s) had untolerated taint {node.kubernetes.io/unreachable: }. preemption: 0/3 nodes are available: 1 No preemption victims found for incoming pod, 2 Preemption is not helpful for scheduling..
kubescape       9m17s       Warning   FailedScheduling       pod/kubescape-exporter-29594145-x788r                                                    0/3 nodes are available: 1 Insufficient cpu, 1 node(s) had untolerated taint {node-role.kubernetes.io/control-plane: }, 1 node(s) had untolerated taint {node.kubernetes.io/unreachable: }. preemption: 0/3 nodes are available: 1 No preemption victims found for incoming pod, 2 Preemption is not helpful for scheduling..
kubescape       9m17s       Warning   FailedScheduling       pod/kubescape-exporter-29594150-q2nhz                                                    0/3 nodes are available: 1 Insufficient cpu, 1 node(s) had untolerated taint {node-role.kubernetes.io/control-plane: }, 1 node(s) had untolerated taint {node.kubernetes.io/unreachable: }. preemption: 0/3 nodes are available: 1 No preemption victims found for incoming pod, 2 Preemption is not helpful for scheduling..
kubescape       9m17s       Warning   FailedScheduling       pod/kubescape-exporter-29594155-cfvxq                                                    0/3 nodes are available: 1 Insufficient cpu, 1 node(s) had untolerated taint {node-role.kubernetes.io/control-plane: }, 1 node(s) had untolerated taint {node.kubernetes.io/unreachable: }. preemption: 0/3 nodes are available: 1 No preemption victims found for incoming pod, 2 Preemption is not helpful for scheduling..
kubescape       9m17s       Warning   FailedScheduling       pod/kubescape-exporter-29594160-h846t                                                    0/3 nodes are available: 1 Insufficient cpu, 1 node(s) had untolerated taint {node-role.kubernetes.io/control-plane: }, 1 node(s) had untolerated taint {node.kubernetes.io/unreachable: }. preemption: 0/3 nodes are available: 1 No preemption victims found for incoming pod, 2 Preemption is not helpful for scheduling..
kubescape       9m17s       Warning   FailedScheduling       pod/kubescape-exporter-29594165-tjk7m                                                    0/3 nodes are available: 1 Insufficient cpu, 1 node(s) had untolerated taint {node-role.kubernetes.io/control-plane: }, 1 node(s) had untolerated taint {node.kubernetes.io/unreachable: }. preemption: 0/3 nodes are available: 1 No preemption victims found for incoming pod, 2 Preemption is not helpful for scheduling..
kubescape       9m17s       Warning   FailedScheduling       pod/kubescape-exporter-29594170-9d8vb                                                    0/3 nodes are available: 1 Insufficient cpu, 1 node(s) had untolerated taint {node-role.kubernetes.io/control-plane: }, 1 node(s) had untolerated taint {node.kubernetes.io/unreachable: }. preemption: 0/3 nodes are available: 1 No preemption victims found for incoming pod, 2 Preemption is not helpful for scheduling..
kubescape       9m17s       Warning   FailedScheduling       pod/kubescape-exporter-29594175-c278l                                                    0/3 nodes are available: 1 Insufficient cpu, 1 node(s) had untolerated taint {node-role.kubernetes.io/control-plane: }, 1 node(s) had untolerated taint {node.kubernetes.io/unreachable: }. preemption: 0/3 nodes are available: 1 No preemption victims found for incoming pod, 2 Preemption is not helpful for scheduling..
kubescape       9m17s       Warning   FailedScheduling       pod/kubescape-exporter-29594180-rj6m4                                                    0/3 nodes are available: 1 Insufficient cpu, 1 node(s) had untolerated taint {node-role.kubernetes.io/control-plane: }, 1 node(s) had untolerated taint {node.kubernetes.io/unreachable: }. preemption: 0/3 nodes are available: 1 No preemption victims found for incoming pod, 2 Preemption is not helpful for scheduling..
kubescape       9m17s       Warning   FailedScheduling       pod/kubescape-exporter-29594185-m54ld                                                    0/3 nodes are available: 1 Insufficient cpu, 1 node(s) had untolerated taint {node-role.kubernetes.io/control-plane: }, 1 node(s) had untolerated taint {node.kubernetes.io/unreachable: }. preemption: 0/3 nodes are available: 1 No preemption victims found for incoming pod, 2 Preemption is not helpful for scheduling..
kubescape       9m17s       Warning   FailedScheduling       pod/kubescape-exporter-29594190-7w9f5                                                    0/3 nodes are available: 1 Insufficient cpu, 1 node(s) had untolerated taint {node-role.kubernetes.io/control-plane: }, 1 node(s) had untolerated taint {node.kubernetes.io/unreachable: }. preemption: 0/3 nodes are available: 1 No preemption victims found for incoming pod, 2 Preemption is not helpful for scheduling..
kubescape       9m17s       Warning   FailedScheduling       pod/kubescape-exporter-29594195-bw46p                                                    0/3 nodes are available: 1 Insufficient cpu, 1 node(s) had untolerated taint {node-role.kubernetes.io/control-plane: }, 1 node(s) had untolerated taint {node.kubernetes.io/unreachable: }. preemption: 0/3 nodes are available: 1 No preemption victims found for incoming pod, 2 Preemption is not helpful for scheduling..
kubescape       9m17s       Warning   FailedScheduling       pod/kubescape-exporter-29594200-nfll6                                                    0/3 nodes are available: 1 Insufficient cpu, 1 node(s) had untolerated taint {node-role.kubernetes.io/control-plane: }, 1 node(s) had untolerated taint {node.kubernetes.io/unreachable: }. preemption: 0/3 nodes are available: 1 No preemption victims found for incoming pod, 2 Preemption is not helpful for scheduling..
kubescape       9m17s       Warning   FailedScheduling       pod/kubescape-exporter-29594205-jh9m7                                                    0/3 nodes are available: 1 Insufficient cpu, 1 node(s) had untolerated taint {node-role.kubernetes.io/control-plane: }, 1 node(s) had untolerated taint {node.kubernetes.io/unreachable: }. preemption: 0/3 nodes are available: 1 No preemption victims found for incoming pod, 2 Preemption is not helpful for scheduling..
kubescape       9m17s       Warning   FailedScheduling       pod/kubescape-exporter-29594210-knnmb                                                    0/3 nodes are available: 1 Insufficient cpu, 1 node(s) had untolerated taint {node-role.kubernetes.io/control-plane: }, 1 node(s) had untolerated taint {node.kubernetes.io/unreachable: }. preemption: 0/3 nodes are available: 1 No preemption victims found for incoming pod, 2 Preemption is not helpful for scheduling..
kubescape       9m17s       Warning   FailedScheduling       pod/kubescape-exporter-29594215-kbcxr                                                    0/3 nodes are available: 1 Insufficient cpu, 1 node(s) had untolerated taint {node-role.kubernetes.io/control-plane: }, 1 node(s) had untolerated taint {node.kubernetes.io/unreachable: }. preemption: 0/3 nodes are available: 1 No preemption victims found for incoming pod, 2 Preemption is not helpful for scheduling..
kubescape       9m17s       Warning   FailedScheduling       pod/kubescape-exporter-29594220-8mk2w                                                    0/3 nodes are available: 1 Insufficient cpu, 1 node(s) had untolerated taint {node-role.kubernetes.io/control-plane: }, 1 node(s) had untolerated taint {node.kubernetes.io/unreachable: }. preemption: 0/3 nodes are available: 1 No preemption victims found for incoming pod, 2 Preemption is not helpful for scheduling..
kubescape       9m17s       Warning   FailedScheduling       pod/kubescape-exporter-29594225-w8wgp                                                    0/3 nodes are available: 1 Insufficient cpu, 1 node(s) had untolerated taint {node-role.kubernetes.io/control-plane: }, 1 node(s) had untolerated taint {node.kubernetes.io/unreachable: }. preemption: 0/3 nodes are available: 1 No preemption victims found for incoming pod, 2 Preemption is not helpful for scheduling..
kubescape       9m17s       Warning   FailedScheduling       pod/kubescape-exporter-29594230-wcw2x                                                    0/3 nodes are available: 1 Insufficient cpu, 1 node(s) had untolerated taint {node-role.kubernetes.io/control-plane: }, 1 node(s) had untolerated taint {node.kubernetes.io/unreachable: }. preemption: 0/3 nodes are available: 1 No preemption victims found for incoming pod, 2 Preemption is not helpful for scheduling..
kubescape       9m17s       Warning   FailedScheduling       pod/kubescape-exporter-29594235-tncvs                                                    0/3 nodes are available: 1 Insufficient cpu, 1 node(s) had untolerated taint {node-role.kubernetes.io/control-plane: }, 1 node(s) had untolerated taint {node.kubernetes.io/unreachable: }. preemption: 0/3 nodes are available: 1 No preemption victims found for incoming pod, 2 Preemption is not helpful for scheduling..
kubescape       9m17s       Warning   FailedScheduling       pod/kubescape-exporter-29594240-25bf7                                                    0/3 nodes are available: 1 Insufficient cpu, 1 node(s) had untolerated taint {node-role.kubernetes.io/control-plane: }, 1 node(s) had untolerated taint {node.kubernetes.io/unreachable: }. preemption: 0/3 nodes are available: 1 No preemption victims found for incoming pod, 2 Preemption is not helpful for scheduling..
kubescape       9m17s       Warning   FailedScheduling       pod/kubescape-exporter-29594245-rhkls                                                    0/3 nodes are available: 1 Insufficient cpu, 1 node(s) had untolerated taint {node-role.kubernetes.io/control-plane: }, 1 node(s) had untolerated taint {node.kubernetes.io/unreachable: }. preemption: 0/3 nodes are available: 1 No preemption victims found for incoming pod, 2 Preemption is not helpful for scheduling..
kubescape       9m17s       Warning   FailedScheduling       pod/kubescape-exporter-29594250-p5k5d                                                    0/3 nodes are available: 1 Insufficient cpu, 1 node(s) had untolerated taint {node-role.kubernetes.io/control-plane: }, 1 node(s) had untolerated taint {node.kubernetes.io/unreachable: }. preemption: 0/3 nodes are available: 1 No preemption victims found for incoming pod, 2 Preemption is not helpful for scheduling..
kubescape       9m17s       Warning   FailedScheduling       pod/kubescape-exporter-29594255-b6b27                                                    0/3 nodes are available: 1 Insufficient cpu, 1 node(s) had untolerated taint {node-role.kubernetes.io/control-plane: }, 1 node(s) had untolerated taint {node.kubernetes.io/unreachable: }. preemption: 0/3 nodes are available: 1 No preemption victims found for incoming pod, 2 Preemption is not helpful for scheduling..
kubescape       9m17s       Warning   FailedScheduling       pod/kubescape-exporter-29594260-wjkj4                                                    0/3 nodes are available: 1 Insufficient cpu, 1 node(s) had untolerated taint {node-role.kubernetes.io/control-plane: }, 1 node(s) had untolerated taint {node.kubernetes.io/unreachable: }. preemption: 0/3 nodes are available: 1 No preemption victims found for incoming pod, 2 Preemption is not helpful for scheduling..
kubescape       9m17s       Warning   FailedScheduling       pod/kubescape-exporter-29594265-ljf2l                                                    0/3 nodes are available: 1 Insufficient cpu, 1 node(s) had untolerated taint {node-role.kubernetes.io/control-plane: }, 1 node(s) had untolerated taint {node.kubernetes.io/unreachable: }. preemption: 0/3 nodes are available: 1 No preemption victims found for incoming pod, 2 Preemption is not helpful for scheduling..
kubescape       9m17s       Warning   FailedScheduling       pod/kubescape-exporter-29594270-ngv26                                                    0/3 nodes are available: 1 Insufficient cpu, 1 node(s) had untolerated taint {node-role.kubernetes.io/control-plane: }, 1 node(s) had untolerated taint {node.kubernetes.io/unreachable: }. preemption: 0/3 nodes are available: 1 No preemption victims found for incoming pod, 2 Preemption is not helpful for scheduling..
kubescape       9m17s       Warning   FailedScheduling       pod/kubescape-exporter-29594275-d928c                                                    0/3 nodes are available: 1 Insufficient cpu, 1 node(s) had untolerated taint {node-role.kubernetes.io/control-plane: }, 1 node(s) had untolerated taint {node.kubernetes.io/unreachable: }. preemption: 0/3 nodes are available: 1 No preemption victims found for incoming pod, 2 Preemption is not helpful for scheduling..
kubescape       9m17s       Warning   FailedScheduling       pod/kubescape-exporter-29594280-qn4hk                                                    0/3 nodes are available: 1 Insufficient cpu, 1 node(s) had untolerated taint {node-role.kubernetes.io/control-plane: }, 1 node(s) had untolerated taint {node.kubernetes.io/unreachable: }. preemption: 0/3 nodes are available: 1 No preemption victims found for incoming pod, 2 Preemption is not helpful for scheduling..
kubescape       9m17s       Warning   FailedScheduling       pod/kubescape-exporter-29594285-hcqcm                                                    0/3 nodes are available: 1 Insufficient cpu, 1 node(s) had untolerated taint {node-role.kubernetes.io/control-plane: }, 1 node(s) had untolerated taint {node.kubernetes.io/unreachable: }. preemption: 0/3 nodes are available: 1 No preemption victims found for incoming pod, 2 Preemption is not helpful for scheduling..
kubescape       9m17s       Warning   FailedScheduling       pod/kubescape-exporter-29594290-fm4wq                                                    0/3 nodes are available: 1 Insufficient cpu, 1 node(s) had untolerated taint {node-role.kubernetes.io/control-plane: }, 1 node(s) had untolerated taint {node.kubernetes.io/unreachable: }. preemption: 0/3 nodes are available: 1 No preemption victims found for incoming pod, 2 Preemption is not helpful for scheduling..
kubescape       9m17s       Warning   FailedScheduling       pod/kubescape-exporter-29594295-lnxrn                                                    0/3 nodes are available: 1 Insufficient cpu, 1 node(s) had untolerated taint {node-role.kubernetes.io/control-plane: }, 1 node(s) had untolerated taint {node.kubernetes.io/unreachable: }. preemption: 0/3 nodes are available: 1 No preemption victims found for incoming pod, 2 Preemption is not helpful for scheduling..
kubescape       9m17s       Warning   FailedScheduling       pod/kubescape-exporter-29594300-856f5                                                    0/3 nodes are available: 1 Insufficient cpu, 1 node(s) had untolerated taint {node-role.kubernetes.io/control-plane: }, 1 node(s) had untolerated taint {node.kubernetes.io/unreachable: }. preemption: 0/3 nodes are available: 1 No preemption victims found for incoming pod, 2 Preemption is not helpful for scheduling..
kubescape       9m17s       Warning   FailedScheduling       pod/kubescape-exporter-29594305-p46mz                                                    0/3 nodes are available: 1 Insufficient cpu, 1 node(s) had untolerated taint {node-role.kubernetes.io/control-plane: }, 1 node(s) had untolerated taint {node.kubernetes.io/unreachable: }. preemption: 0/3 nodes are available: 1 No preemption victims found for incoming pod, 2 Preemption is not helpful for scheduling..
kubescape       9m17s       Warning   FailedScheduling       pod/kubescape-exporter-29594310-cz8s8                                                    0/3 nodes are available: 1 Insufficient cpu, 1 node(s) had untolerated taint {node-role.kubernetes.io/control-plane: }, 1 node(s) had untolerated taint {node.kubernetes.io/unreachable: }. preemption: 0/3 nodes are available: 1 No preemption victims found for incoming pod, 2 Preemption is not helpful for scheduling..
kubescape       9m17s       Warning   FailedScheduling       pod/kubescape-exporter-29594315-pxr6d                                                    0/3 nodes are available: 1 Insufficient cpu, 1 node(s) had untolerated taint {node-role.kubernetes.io/control-plane: }, 1 node(s) had untolerated taint {node.kubernetes.io/unreachable: }. preemption: 0/3 nodes are available: 1 No preemption victims found for incoming pod, 2 Preemption is not helpful for scheduling..
kubescape       9m17s       Warning   FailedScheduling       pod/kubescape-exporter-29594320-xgq72                                                    0/3 nodes are available: 1 Insufficient cpu, 1 node(s) had untolerated taint {node-role.kubernetes.io/control-plane: }, 1 node(s) had untolerated taint {node.kubernetes.io/unreachable: }. preemption: 0/3 nodes are available: 1 No preemption victims found for incoming pod, 2 Preemption is not helpful for scheduling..
kubescape       9m17s       Warning   FailedScheduling       pod/kubescape-exporter-29594325-cv8cg                                                    0/3 nodes are available: 1 Insufficient cpu, 1 node(s) had untolerated taint {node-role.kubernetes.io/control-plane: }, 1 node(s) had untolerated taint {node.kubernetes.io/unreachable: }. preemption: 0/3 nodes are available: 1 No preemption victims found for incoming pod, 2 Preemption is not helpful for scheduling..
kubescape       9m17s       Warning   FailedScheduling       pod/kubescape-exporter-29594330-p7gj9                                                    0/3 nodes are available: 1 Insufficient cpu, 1 node(s) had untolerated taint {node-role.kubernetes.io/control-plane: }, 1 node(s) had untolerated taint {node.kubernetes.io/unreachable: }. preemption: 0/3 nodes are available: 1 No preemption victims found for incoming pod, 2 Preemption is not helpful for scheduling..
kubescape       9m17s       Warning   FailedScheduling       pod/kubescape-exporter-29594335-7qzj2                                                    0/3 nodes are available: 1 Insufficient cpu, 1 node(s) had untolerated taint {node-role.kubernetes.io/control-plane: }, 1 node(s) had untolerated taint {node.kubernetes.io/unreachable: }. preemption: 0/3 nodes are available: 1 No preemption victims found for incoming pod, 2 Preemption is not helpful for scheduling..
kubescape       9m17s       Warning   FailedScheduling       pod/kubescape-exporter-29594340-l9r72                                                    0/3 nodes are available: 1 Insufficient cpu, 1 node(s) had untolerated taint {node-role.kubernetes.io/control-plane: }, 1 node(s) had untolerated taint {node.kubernetes.io/unreachable: }. preemption: 0/3 nodes are available: 1 No preemption victims found for incoming pod, 2 Preemption is not helpful for scheduling..
kubescape       9m17s       Warning   FailedScheduling       pod/kubescape-exporter-29594345-7wwpc                                                    0/3 nodes are available: 1 Insufficient cpu, 1 node(s) had untolerated taint {node-role.kubernetes.io/control-plane: }, 1 node(s) had untolerated taint {node.kubernetes.io/unreachable: }. preemption: 0/3 nodes are available: 1 No preemption victims found for incoming pod, 2 Preemption is not helpful for scheduling..
kubescape       9m17s       Warning   FailedScheduling       pod/kubescape-exporter-29594350-n2lkk                                                    0/3 nodes are available: 1 Insufficient cpu, 1 node(s) had untolerated taint {node-role.kubernetes.io/control-plane: }, 1 node(s) had untolerated taint {node.kubernetes.io/unreachable: }. preemption: 0/3 nodes are available: 1 No preemption victims found for incoming pod, 2 Preemption is not helpful for scheduling..
kubescape       9m17s       Warning   FailedScheduling       pod/kubescape-exporter-29594355-d7ktq                                                    0/3 nodes are available: 1 Insufficient cpu, 1 node(s) had untolerated taint {node-role.kubernetes.io/control-plane: }, 1 node(s) had untolerated taint {node.kubernetes.io/unreachable: }. preemption: 0/3 nodes are available: 1 No preemption victims found for incoming pod, 2 Preemption is not helpful for scheduling..
kubescape       9m17s       Warning   FailedScheduling       pod/kubescape-exporter-29594360-jrgk6                                                    0/3 nodes are available: 1 Insufficient cpu, 1 node(s) had untolerated taint {node-role.kubernetes.io/control-plane: }, 1 node(s) had untolerated taint {node.kubernetes.io/unreachable: }. preemption: 0/3 nodes are available: 1 No preemption victims found for incoming pod, 2 Preemption is not helpful for scheduling..
kubescape       9m17s       Warning   FailedScheduling       pod/kubescape-exporter-29594365-bm5cj                                                    0/3 nodes are available: 1 Insufficient cpu, 1 node(s) had untolerated taint {node-role.kubernetes.io/control-plane: }, 1 node(s) had untolerated taint {node.kubernetes.io/unreachable: }. preemption: 0/3 nodes are available: 1 No preemption victims found for incoming pod, 2 Preemption is not helpful for scheduling..
kubescape       9m17s       Warning   FailedScheduling       pod/kubescape-exporter-29594370-t7wgx                                                    0/3 nodes are available: 1 Insufficient cpu, 1 node(s) had untolerated taint {node-role.kubernetes.io/control-plane: }, 1 node(s) had untolerated taint {node.kubernetes.io/unreachable: }. preemption: 0/3 nodes are available: 1 No preemption victims found for incoming pod, 2 Preemption is not helpful for scheduling..
kubescape       9m17s       Warning   FailedScheduling       pod/kubescape-exporter-29594375-xpd2j                                                    0/3 nodes are available: 1 Insufficient cpu, 1 node(s) had untolerated taint {node-role.kubernetes.io/control-plane: }, 1 node(s) had untolerated taint {node.kubernetes.io/unreachable: }. preemption: 0/3 nodes are available: 1 No preemption victims found for incoming pod, 2 Preemption is not helpful for scheduling..
kubescape       9m17s       Warning   FailedScheduling       pod/kubescape-exporter-29594380-k9d68                                                    0/3 nodes are available: 1 Insufficient cpu, 1 node(s) had untolerated taint {node-role.kubernetes.io/control-plane: }, 1 node(s) had untolerated taint {node.kubernetes.io/unreachable: }. preemption: 0/3 nodes are available: 1 No preemption victims found for incoming pod, 2 Preemption is not helpful for scheduling..
kubescape       9m17s       Warning   FailedScheduling       pod/kubescape-exporter-29594385-bkcl6                                                    0/3 nodes are available: 1 Insufficient cpu, 1 node(s) had untolerated taint {node-role.kubernetes.io/control-plane: }, 1 node(s) had untolerated taint {node.kubernetes.io/unreachable: }. preemption: 0/3 nodes are available: 1 No preemption victims found for incoming pod, 2 Preemption is not helpful for scheduling..
kubescape       9m17s       Warning   FailedScheduling       pod/kubescape-exporter-29594390-v7vnc                                                    0/3 nodes are available: 1 Insufficient cpu, 1 node(s) had untolerated taint {node-role.kubernetes.io/control-plane: }, 1 node(s) had untolerated taint {node.kubernetes.io/unreachable: }. preemption: 0/3 nodes are available: 1 No preemption victims found for incoming pod, 2 Preemption is not helpful for scheduling..
kubescape       9m17s       Warning   FailedScheduling       pod/kubescape-exporter-29594395-4sgx6                                                    0/3 nodes are available: 1 Insufficient cpu, 1 node(s) had untolerated taint {node-role.kubernetes.io/control-plane: }, 1 node(s) had untolerated taint {node.kubernetes.io/unreachable: }. preemption: 0/3 nodes are available: 1 No preemption victims found for incoming pod, 2 Preemption is not helpful for scheduling..
kubescape       9m17s       Warning   FailedScheduling       pod/kubescape-exporter-29594400-7t58j                                                    0/3 nodes are available: 1 Insufficient cpu, 1 node(s) had untolerated taint {node-role.kubernetes.io/control-plane: }, 1 node(s) had untolerated taint {node.kubernetes.io/unreachable: }. preemption: 0/3 nodes are available: 1 No preemption victims found for incoming pod, 2 Preemption is not helpful for scheduling..
kubescape       9m17s       Warning   FailedScheduling       pod/kubescape-exporter-29594405-4j7rm                                                    0/3 nodes are available: 1 Insufficient cpu, 1 node(s) had untolerated taint {node-role.kubernetes.io/control-plane: }, 1 node(s) had untolerated taint {node.kubernetes.io/unreachable: }. preemption: 0/3 nodes are available: 1 No preemption victims found for incoming pod, 2 Preemption is not helpful for scheduling..
kubescape       9m17s       Warning   FailedScheduling       pod/kubescape-exporter-29594410-kqz7s                                                    0/3 nodes are available: 1 Insufficient cpu, 1 node(s) had untolerated taint {node-role.kubernetes.io/control-plane: }, 1 node(s) had untolerated taint {node.kubernetes.io/unreachable: }. preemption: 0/3 nodes are available: 1 No preemption victims found for incoming pod, 2 Preemption is not helpful for scheduling..
kubescape       9m17s       Warning   FailedScheduling       pod/kubescape-exporter-29594415-tj8rd                                                    0/3 nodes are available: 1 Insufficient cpu, 1 node(s) had untolerated taint {node-role.kubernetes.io/control-plane: }, 1 node(s) had untolerated taint {node.kubernetes.io/unreachable: }. preemption: 0/3 nodes are available: 1 No preemption victims found for incoming pod, 2 Preemption is not helpful for scheduling..
kubescape       9m17s       Warning   FailedScheduling       pod/kubescape-exporter-29594420-mhkcx                                                    0/3 nodes are available: 1 Insufficient cpu, 1 node(s) had untolerated taint {node-role.kubernetes.io/control-plane: }, 1 node(s) had untolerated taint {node.kubernetes.io/unreachable: }. preemption: 0/3 nodes are available: 1 No preemption victims found for incoming pod, 2 Preemption is not helpful for scheduling..
kubescape       9m17s       Warning   FailedScheduling       pod/kubescape-exporter-29594425-bzvcn                                                    0/3 nodes are available: 1 Insufficient cpu, 1 node(s) had untolerated taint {node-role.kubernetes.io/control-plane: }, 1 node(s) had untolerated taint {node.kubernetes.io/unreachable: }. preemption: 0/3 nodes are available: 1 No preemption victims found for incoming pod, 2 Preemption is not helpful for scheduling..
kubescape       9m17s       Warning   FailedScheduling       pod/kubescape-exporter-29594430-8t6bb                                                    0/3 nodes are available: 1 Insufficient cpu, 1 node(s) had untolerated taint {node-role.kubernetes.io/control-plane: }, 1 node(s) had untolerated taint {node.kubernetes.io/unreachable: }. preemption: 0/3 nodes are available: 1 No preemption victims found for incoming pod, 2 Preemption is not helpful for scheduling..
kubescape       9m17s       Warning   FailedScheduling       pod/kubescape-exporter-29594435-g9lxc                                                    0/3 nodes are available: 1 Insufficient cpu, 1 node(s) had untolerated taint {node-role.kubernetes.io/control-plane: }, 1 node(s) had untolerated taint {node.kubernetes.io/unreachable: }. preemption: 0/3 nodes are available: 1 No preemption victims found for incoming pod, 2 Preemption is not helpful for scheduling..
kubescape       9m16s       Warning   FailedScheduling       pod/kubescape-exporter-29594440-cfxgr                                                    0/3 nodes are available: 1 Insufficient cpu, 1 node(s) had untolerated taint {node-role.kubernetes.io/control-plane: }, 1 node(s) had untolerated taint {node.kubernetes.io/unreachable: }. preemption: 0/3 nodes are available: 1 No preemption victims found for incoming pod, 2 Preemption is not helpful for scheduling..
kubescape       9m17s       Warning   FailedScheduling       pod/kubescape-exporter-29594445-2v7rq                                                    0/3 nodes are available: 1 Insufficient cpu, 1 node(s) had untolerated taint {node-role.kubernetes.io/control-plane: }, 1 node(s) had untolerated taint {node.kubernetes.io/unreachable: }. preemption: 0/3 nodes are available: 1 No preemption victims found for incoming pod, 2 Preemption is not helpful for scheduling..
kubescape       9m16s       Warning   FailedScheduling       pod/kubescape-exporter-29594450-7ns8b                                                    0/3 nodes are available: 1 Insufficient cpu, 1 node(s) had untolerated taint {node-role.kubernetes.io/control-plane: }, 1 node(s) had untolerated taint {node.kubernetes.io/unreachable: }. preemption: 0/3 nodes are available: 1 No preemption victims found for incoming pod, 2 Preemption is not helpful for scheduling..
kubescape       9m16s       Warning   FailedScheduling       pod/kubescape-exporter-29594455-tr5nf                                                    0/3 nodes are available: 1 Insufficient cpu, 1 node(s) had untolerated taint {node-role.kubernetes.io/control-plane: }, 1 node(s) had untolerated taint {node.kubernetes.io/unreachable: }. preemption: 0/3 nodes are available: 1 No preemption victims found for incoming pod, 2 Preemption is not helpful for scheduling..
kubescape       9m16s       Warning   FailedScheduling       pod/kubescape-exporter-29594460-z2gbs                                                    0/3 nodes are available: 1 Insufficient cpu, 1 node(s) had untolerated taint {node-role.kubernetes.io/control-plane: }, 1 node(s) had untolerated taint {node.kubernetes.io/unreachable: }. preemption: 0/3 nodes are available: 1 No preemption victims found for incoming pod, 2 Preemption is not helpful for scheduling..
kubescape       9m16s       Warning   FailedScheduling       pod/kubescape-exporter-29594465-flfw4                                                    0/3 nodes are available: 1 Insufficient cpu, 1 node(s) had untolerated taint {node-role.kubernetes.io/control-plane: }, 1 node(s) had untolerated taint {node.kubernetes.io/unreachable: }. preemption: 0/3 nodes are available: 1 No preemption victims found for incoming pod, 2 Preemption is not helpful for scheduling..
kubescape       9m16s       Warning   FailedScheduling       pod/kubescape-exporter-29594470-pwzfg                                                    0/3 nodes are available: 1 Insufficient cpu, 1 node(s) had untolerated taint {node-role.kubernetes.io/control-plane: }, 1 node(s) had untolerated taint {node.kubernetes.io/unreachable: }. preemption: 0/3 nodes are available: 1 No preemption victims found for incoming pod, 2 Preemption is not helpful for scheduling..
kubescape       9m16s       Warning   FailedScheduling       pod/kubescape-exporter-29594475-kwhq7                                                    0/3 nodes are available: 1 Insufficient cpu, 1 node(s) had untolerated taint {node-role.kubernetes.io/control-plane: }, 1 node(s) had untolerated taint {node.kubernetes.io/unreachable: }. preemption: 0/3 nodes are available: 1 No preemption victims found for incoming pod, 2 Preemption is not helpful for scheduling..
kubescape       9m16s       Warning   FailedScheduling       pod/kubescape-exporter-29594480-trtwt                                                    0/3 nodes are available: 1 Insufficient cpu, 1 node(s) had untolerated taint {node-role.kubernetes.io/control-plane: }, 1 node(s) had untolerated taint {node.kubernetes.io/unreachable: }. preemption: 0/3 nodes are available: 1 No preemption victims found for incoming pod, 2 Preemption is not helpful for scheduling..
kubescape       9m16s       Warning   FailedScheduling       pod/kubescape-exporter-29594485-cg25n                                                    0/3 nodes are available: 1 Insufficient cpu, 1 node(s) had untolerated taint {node-role.kubernetes.io/control-plane: }, 1 node(s) had untolerated taint {node.kubernetes.io/unreachable: }. preemption: 0/3 nodes are available: 1 No preemption victims found for incoming pod, 2 Preemption is not helpful for scheduling..
kubescape       9m17s       Warning   FailedScheduling       pod/kubescape-exporter-29594490-rrvl2                                                    0/3 nodes are available: 1 Insufficient cpu, 1 node(s) had untolerated taint {node-role.kubernetes.io/control-plane: }, 1 node(s) had untolerated taint {node.kubernetes.io/unreachable: }. preemption: 0/3 nodes are available: 1 No preemption victims found for incoming pod, 2 Preemption is not helpful for scheduling..
kubescape       9m17s       Warning   FailedScheduling       pod/kubescape-exporter-29594495-zgctn                                                    0/3 nodes are available: 1 Insufficient cpu, 1 node(s) had untolerated taint {node-role.kubernetes.io/control-plane: }, 1 node(s) had untolerated taint {node.kubernetes.io/unreachable: }. preemption: 0/3 nodes are available: 1 No preemption victims found for incoming pod, 2 Preemption is not helpful for scheduling..
kubescape       9m17s       Warning   FailedScheduling       pod/kubescape-exporter-29594500-26q8x                                                    0/3 nodes are available: 1 Insufficient cpu, 1 node(s) had untolerated taint {node-role.kubernetes.io/control-plane: }, 1 node(s) had untolerated taint {node.kubernetes.io/unreachable: }. preemption: 0/3 nodes are available: 1 No preemption victims found for incoming pod, 2 Preemption is not helpful for scheduling..
kubescape       9m17s       Warning   FailedScheduling       pod/kubescape-exporter-29594505-t69vl                                                    0/3 nodes are available: 1 Insufficient cpu, 1 node(s) had untolerated taint {node-role.kubernetes.io/control-plane: }, 1 node(s) had untolerated taint {node.kubernetes.io/unreachable: }. preemption: 0/3 nodes are available: 1 No preemption victims found for incoming pod, 2 Preemption is not helpful for scheduling..
kubescape       9m17s       Warning   FailedScheduling       pod/kubescape-exporter-29594510-vdmcg                                                    0/3 nodes are available: 1 Insufficient cpu, 1 node(s) had untolerated taint {node-role.kubernetes.io/control-plane: }, 1 node(s) had untolerated taint {node.kubernetes.io/unreachable: }. preemption: 0/3 nodes are available: 1 No preemption victims found for incoming pod, 2 Preemption is not helpful for scheduling..
kubescape       9m17s       Warning   FailedScheduling       pod/kubescape-exporter-29594515-5dq9w                                                    0/3 nodes are available: 1 Insufficient cpu, 1 node(s) had untolerated taint {node-role.kubernetes.io/control-plane: }, 1 node(s) had untolerated taint {node.kubernetes.io/unreachable: }. preemption: 0/3 nodes are available: 1 No preemption victims found for incoming pod, 2 Preemption is not helpful for scheduling..
kubescape       9m17s       Warning   FailedScheduling       pod/kubescape-exporter-29594520-c98kn                                                    0/3 nodes are available: 1 Insufficient cpu, 1 node(s) had untolerated taint {node-role.kubernetes.io/control-plane: }, 1 node(s) had untolerated taint {node.kubernetes.io/unreachable: }. preemption: 0/3 nodes are available: 1 No preemption victims found for incoming pod, 2 Preemption is not helpful for scheduling..
kubescape       9m17s       Warning   FailedScheduling       pod/kubescape-exporter-29594525-rr2mt                                                    0/3 nodes are available: 1 Insufficient cpu, 1 node(s) had untolerated taint {node-role.kubernetes.io/control-plane: }, 1 node(s) had untolerated taint {node.kubernetes.io/unreachable: }. preemption: 0/3 nodes are available: 1 No preemption victims found for incoming pod, 2 Preemption is not helpful for scheduling..
kubescape       9m17s       Warning   FailedScheduling       pod/kubescape-exporter-29594530-r9562                                                    0/3 nodes are available: 1 Insufficient cpu, 1 node(s) had untolerated taint {node-role.kubernetes.io/control-plane: }, 1 node(s) had untolerated taint {node.kubernetes.io/unreachable: }. preemption: 0/3 nodes are available: 1 No preemption victims found for incoming pod, 2 Preemption is not helpful for scheduling..
kubescape       9m17s       Warning   FailedScheduling       pod/kubescape-exporter-29594535-7zw89                                                    0/3 nodes are available: 1 Insufficient cpu, 1 node(s) had untolerated taint {node-role.kubernetes.io/control-plane: }, 1 node(s) had untolerated taint {node.kubernetes.io/unreachable: }. preemption: 0/3 nodes are available: 1 No preemption victims found for incoming pod, 2 Preemption is not helpful for scheduling..
kubescape       9m17s       Warning   FailedScheduling       pod/kubescape-exporter-29594540-gslxl                                                    0/3 nodes are available: 1 Insufficient cpu, 1 node(s) had untolerated taint {node-role.kubernetes.io/control-plane: }, 1 node(s) had untolerated taint {node.kubernetes.io/unreachable: }. preemption: 0/3 nodes are available: 1 No preemption victims found for incoming pod, 2 Preemption is not helpful for scheduling..
kubescape       9m17s       Warning   FailedScheduling       pod/kubescape-exporter-29594545-9w27b                                                    0/3 nodes are available: 1 Insufficient cpu, 1 node(s) had untolerated taint {node-role.kubernetes.io/control-plane: }, 1 node(s) had untolerated taint {node.kubernetes.io/unreachable: }. preemption: 0/3 nodes are available: 1 No preemption victims found for incoming pod, 2 Preemption is not helpful for scheduling..
kubescape       9m17s       Warning   FailedScheduling       pod/kubescape-exporter-29594550-d7rr8                                                    0/3 nodes are available: 1 Insufficient cpu, 1 node(s) had untolerated taint {node-role.kubernetes.io/control-plane: }, 1 node(s) had untolerated taint {node.kubernetes.io/unreachable: }. preemption: 0/3 nodes are available: 1 No preemption victims found for incoming pod, 2 Preemption is not helpful for scheduling..
kubescape       9m17s       Warning   FailedScheduling       pod/kubescape-exporter-29594555-ntwgk                                                    0/3 nodes are available: 1 Insufficient cpu, 1 node(s) had untolerated taint {node-role.kubernetes.io/control-plane: }, 1 node(s) had untolerated taint {node.kubernetes.io/unreachable: }. preemption: 0/3 nodes are available: 1 No preemption victims found for incoming pod, 2 Preemption is not helpful for scheduling..
kubescape       9m17s       Warning   FailedScheduling       pod/kubescape-exporter-29594560-lgw2w                                                    0/3 nodes are available: 1 Insufficient cpu, 1 node(s) had untolerated taint {node-role.kubernetes.io/control-plane: }, 1 node(s) had untolerated taint {node.kubernetes.io/unreachable: }. preemption: 0/3 nodes are available: 1 No preemption victims found for incoming pod, 2 Preemption is not helpful for scheduling..
kubescape       9m17s       Warning   FailedScheduling       pod/kubescape-exporter-29594565-zq9mr                                                    0/3 nodes are available: 1 Insufficient cpu, 1 node(s) had untolerated taint {node-role.kubernetes.io/control-plane: }, 1 node(s) had untolerated taint {node.kubernetes.io/unreachable: }. preemption: 0/3 nodes are available: 1 No preemption victims found for incoming pod, 2 Preemption is not helpful for scheduling..
kubescape       9m17s       Warning   FailedScheduling       pod/kubescape-exporter-29594570-25wcx                                                    0/3 nodes are available: 1 Insufficient cpu, 1 node(s) had untolerated taint {node-role.kubernetes.io/control-plane: }, 1 node(s) had untolerated taint {node.kubernetes.io/unreachable: }. preemption: 0/3 nodes are available: 1 No preemption victims found for incoming pod, 2 Preemption is not helpful for scheduling..
kubescape       9m17s       Warning   FailedScheduling       pod/kubescape-exporter-29594575-jsrsl                                                    0/3 nodes are available: 1 Insufficient cpu, 1 node(s) had untolerated taint {node-role.kubernetes.io/control-plane: }, 1 node(s) had untolerated taint {node.kubernetes.io/unreachable: }. preemption: 0/3 nodes are available: 1 No preemption victims found for incoming pod, 2 Preemption is not helpful for scheduling..
kubescape       9m17s       Warning   FailedScheduling       pod/kubescape-exporter-29594580-jz6xk                                                    0/3 nodes are available: 1 Insufficient cpu, 1 node(s) had untolerated taint {node-role.kubernetes.io/control-plane: }, 1 node(s) had untolerated taint {node.kubernetes.io/unreachable: }. preemption: 0/3 nodes are available: 1 No preemption victims found for incoming pod, 2 Preemption is not helpful for scheduling..
kubescape       9m17s       Warning   FailedScheduling       pod/kubescape-exporter-29594585-7nb85                                                    0/3 nodes are available: 1 Insufficient cpu, 1 node(s) had untolerated taint {node-role.kubernetes.io/control-plane: }, 1 node(s) had untolerated taint {node.kubernetes.io/unreachable: }. preemption: 0/3 nodes are available: 1 No preemption victims found for incoming pod, 2 Preemption is not helpful for scheduling..
kubescape       9m17s       Warning   FailedScheduling       pod/kubescape-exporter-29594590-4zp44                                                    0/3 nodes are available: 1 Insufficient cpu, 1 node(s) had untolerated taint {node-role.kubernetes.io/control-plane: }, 1 node(s) had untolerated taint {node.kubernetes.io/unreachable: }. preemption: 0/3 nodes are available: 1 No preemption victims found for incoming pod, 2 Preemption is not helpful for scheduling..
kubescape       9m17s       Warning   FailedScheduling       pod/kubescape-exporter-29594595-7lvsw                                                    0/3 nodes are available: 1 Insufficient cpu, 1 node(s) had untolerated taint {node-role.kubernetes.io/control-plane: }, 1 node(s) had untolerated taint {node.kubernetes.io/unreachable: }. preemption: 0/3 nodes are available: 1 No preemption victims found for incoming pod, 2 Preemption is not helpful for scheduling..
kubescape       9m17s       Warning   FailedScheduling       pod/kubescape-exporter-29594600-z45nj                                                    0/3 nodes are available: 1 Insufficient cpu, 1 node(s) had untolerated taint {node-role.kubernetes.io/control-plane: }, 1 node(s) had untolerated taint {node.kubernetes.io/unreachable: }. preemption: 0/3 nodes are available: 1 No preemption victims found for incoming pod, 2 Preemption is not helpful for scheduling..
kubescape       9m17s       Warning   FailedScheduling       pod/kubescape-exporter-29594605-zh7m6                                                    0/3 nodes are available: 1 Insufficient cpu, 1 node(s) had untolerated taint {node-role.kubernetes.io/control-plane: }, 1 node(s) had untolerated taint {node.kubernetes.io/unreachable: }. preemption: 0/3 nodes are available: 1 No preemption victims found for incoming pod, 2 Preemption is not helpful for scheduling..
kubescape       9m17s       Warning   FailedScheduling       pod/kubescape-exporter-29594610-4wnkg                                                    0/3 nodes are available: 1 Insufficient cpu, 1 node(s) had untolerated taint {node-role.kubernetes.io/control-plane: }, 1 node(s) had untolerated taint {node.kubernetes.io/unreachable: }. preemption: 0/3 nodes are available: 1 No preemption victims found for incoming pod, 2 Preemption is not helpful for scheduling..
kubescape       9m17s       Warning   FailedScheduling       pod/kubescape-exporter-29594615-crbh9                                                    0/3 nodes are available: 1 Insufficient cpu, 1 node(s) had untolerated taint {node-role.kubernetes.io/control-plane: }, 1 node(s) had untolerated taint {node.kubernetes.io/unreachable: }. preemption: 0/3 nodes are available: 1 No preemption victims found for incoming pod, 2 Preemption is not helpful for scheduling..
kubescape       9m16s       Warning   FailedScheduling       pod/kubescape-exporter-29594620-wl96j                                                    0/3 nodes are available: 1 Insufficient cpu, 1 node(s) had untolerated taint {node-role.kubernetes.io/control-plane: }, 1 node(s) had untolerated taint {node.kubernetes.io/unreachable: }. preemption: 0/3 nodes are available: 1 No preemption victims found for incoming pod, 2 Preemption is not helpful for scheduling..
kubescape       9m16s       Warning   FailedScheduling       pod/kubescape-exporter-29594625-27tmx                                                    0/3 nodes are available: 1 Insufficient cpu, 1 node(s) had untolerated taint {node-role.kubernetes.io/control-plane: }, 1 node(s) had untolerated taint {node.kubernetes.io/unreachable: }. preemption: 0/3 nodes are available: 1 No preemption victims found for incoming pod, 2 Preemption is not helpful for scheduling..
kubescape       9m16s       Warning   FailedScheduling       pod/kubescape-exporter-29594630-stnqr                                                    0/3 nodes are available: 1 Insufficient cpu, 1 node(s) had untolerated taint {node-role.kubernetes.io/control-plane: }, 1 node(s) had untolerated taint {node.kubernetes.io/unreachable: }. preemption: 0/3 nodes are available: 1 No preemption victims found for incoming pod, 2 Preemption is not helpful for scheduling..
kubescape       9m16s       Warning   FailedScheduling       pod/kubescape-exporter-29594635-z78m6                                                    0/3 nodes are available: 1 Insufficient cpu, 1 node(s) had untolerated taint {node-role.kubernetes.io/control-plane: }, 1 node(s) had untolerated taint {node.kubernetes.io/unreachable: }. preemption: 0/3 nodes are available: 1 No preemption victims found for incoming pod, 2 Preemption is not helpful for scheduling..
kubescape       9m16s       Warning   FailedScheduling       pod/kubescape-exporter-29594640-rjbb2                                                    0/3 nodes are available: 1 Insufficient cpu, 1 node(s) had untolerated taint {node-role.kubernetes.io/control-plane: }, 1 node(s) had untolerated taint {node.kubernetes.io/unreachable: }. preemption: 0/3 nodes are available: 1 No preemption victims found for incoming pod, 2 Preemption is not helpful for scheduling..
kubescape       9m17s       Warning   FailedScheduling       pod/kubescape-exporter-29594645-fc59c                                                    0/3 nodes are available: 1 Insufficient cpu, 1 node(s) had untolerated taint {node-role.kubernetes.io/control-plane: }, 1 node(s) had untolerated taint {node.kubernetes.io/unreachable: }. preemption: 0/3 nodes are available: 1 No preemption victims found for incoming pod, 2 Preemption is not helpful for scheduling..
kubescape       9m16s       Warning   FailedScheduling       pod/kubescape-exporter-29594650-lp7bj                                                    0/3 nodes are available: 1 Insufficient cpu, 1 node(s) had untolerated taint {node-role.kubernetes.io/control-plane: }, 1 node(s) had untolerated taint {node.kubernetes.io/unreachable: }. preemption: 0/3 nodes are available: 1 No preemption victims found for incoming pod, 2 Preemption is not helpful for scheduling..
kubescape       9m16s       Warning   FailedScheduling       pod/kubescape-exporter-29594655-tvlld                                                    0/3 nodes are available: 1 Insufficient cpu, 1 node(s) had untolerated taint {node-role.kubernetes.io/control-plane: }, 1 node(s) had untolerated taint {node.kubernetes.io/unreachable: }. preemption: 0/3 nodes are available: 1 No preemption victims found for incoming pod, 2 Preemption is not helpful for scheduling..
kubescape       9m16s       Warning   FailedScheduling       pod/kubescape-exporter-29594660-gm6g7                                                    0/3 nodes are available: 1 Insufficient cpu, 1 node(s) had untolerated taint {node-role.kubernetes.io/control-plane: }, 1 node(s) had untolerated taint {node.kubernetes.io/unreachable: }. preemption: 0/3 nodes are available: 1 No preemption victims found for incoming pod, 2 Preemption is not helpful for scheduling..
kubescape       9m16s       Warning   FailedScheduling       pod/kubescape-exporter-29594665-r7rdb                                                    0/3 nodes are available: 1 Insufficient cpu, 1 node(s) had untolerated taint {node-role.kubernetes.io/control-plane: }, 1 node(s) had untolerated taint {node.kubernetes.io/unreachable: }. preemption: 0/3 nodes are available: 1 No preemption victims found for incoming pod, 2 Preemption is not helpful for scheduling..
kubescape       9m16s       Warning   FailedScheduling       pod/kubescape-exporter-29594670-kn9jt                                                    0/3 nodes are available: 1 Insufficient cpu, 1 node(s) had untolerated taint {node-role.kubernetes.io/control-plane: }, 1 node(s) had untolerated taint {node.kubernetes.io/unreachable: }. preemption: 0/3 nodes are available: 1 No preemption victims found for incoming pod, 2 Preemption is not helpful for scheduling..
kubescape       9m16s       Warning   FailedScheduling       pod/kubescape-exporter-29594675-2thz6                                                    0/3 nodes are available: 1 Insufficient cpu, 1 node(s) had untolerated taint {node-role.kubernetes.io/control-plane: }, 1 node(s) had untolerated taint {node.kubernetes.io/unreachable: }. preemption: 0/3 nodes are available: 1 No preemption victims found for incoming pod, 2 Preemption is not helpful for scheduling..
kubescape       9m16s       Warning   FailedScheduling       pod/kubescape-exporter-29594680-dd8kt                                                    0/3 nodes are available: 1 Insufficient cpu, 1 node(s) had untolerated taint {node-role.kubernetes.io/control-plane: }, 1 node(s) had untolerated taint {node.kubernetes.io/unreachable: }. preemption: 0/3 nodes are available: 1 No preemption victims found for incoming pod, 2 Preemption is not helpful for scheduling..
kubescape       9m16s       Warning   FailedScheduling       pod/kubescape-exporter-29594685-k9s5j                                                    0/3 nodes are available: 1 Insufficient cpu, 1 node(s) had untolerated taint {node-role.kubernetes.io/control-plane: }, 1 node(s) had untolerated taint {node.kubernetes.io/unreachable: }. preemption: 0/3 nodes are available: 1 No preemption victims found for incoming pod, 2 Preemption is not helpful for scheduling..
kubescape       9m16s       Warning   FailedScheduling       pod/kubescape-exporter-29594690-tdrrb                                                    0/3 nodes are available: 1 Insufficient cpu, 1 node(s) had untolerated taint {node-role.kubernetes.io/control-plane: }, 1 node(s) had untolerated taint {node.kubernetes.io/unreachable: }. preemption: 0/3 nodes are available: 1 No preemption victims found for incoming pod, 2 Preemption is not helpful for scheduling..
kubescape       9m16s       Warning   FailedScheduling       pod/kubescape-exporter-29594695-ptsvf                                                    0/3 nodes are available: 1 Insufficient cpu, 1 node(s) had untolerated taint {node-role.kubernetes.io/control-plane: }, 1 node(s) had untolerated taint {node.kubernetes.io/unreachable: }. preemption: 0/3 nodes are available: 1 No preemption victims found for incoming pod, 2 Preemption is not helpful for scheduling..
kubescape       9m16s       Warning   FailedScheduling       pod/kubescape-exporter-29594700-tfttf                                                    0/3 nodes are available: 1 Insufficient cpu, 1 node(s) had untolerated taint {node-role.kubernetes.io/control-plane: }, 1 node(s) had untolerated taint {node.kubernetes.io/unreachable: }. preemption: 0/3 nodes are available: 1 No preemption victims found for incoming pod, 2 Preemption is not helpful for scheduling..
kubescape       9m16s       Warning   FailedScheduling       pod/kubescape-exporter-29594705-6l6s2                                                    0/3 nodes are available: 1 Insufficient cpu, 1 node(s) had untolerated taint {node-role.kubernetes.io/control-plane: }, 1 node(s) had untolerated taint {node.kubernetes.io/unreachable: }. preemption: 0/3 nodes are available: 1 No preemption victims found for incoming pod, 2 Preemption is not helpful for scheduling..
kubescape       9m16s       Warning   FailedScheduling       pod/kubescape-exporter-29594710-jbq4d                                                    0/3 nodes are available: 1 Insufficient cpu, 1 node(s) had untolerated taint {node-role.kubernetes.io/control-plane: }, 1 node(s) had untolerated taint {node.kubernetes.io/unreachable: }. preemption: 0/3 nodes are available: 1 No preemption victims found for incoming pod, 2 Preemption is not helpful for scheduling..
kubescape       9m16s       Warning   FailedScheduling       pod/kubescape-exporter-29594715-7jpc2                                                    0/3 nodes are available: 1 Insufficient cpu, 1 node(s) had untolerated taint {node-role.kubernetes.io/control-plane: }, 1 node(s) had untolerated taint {node.kubernetes.io/unreachable: }. preemption: 0/3 nodes are available: 1 No preemption victims found for incoming pod, 2 Preemption is not helpful for scheduling..
kubescape       9m16s       Warning   FailedScheduling       pod/kubescape-exporter-29594720-zbg9n                                                    0/3 nodes are available: 1 Insufficient cpu, 1 node(s) had untolerated taint {node-role.kubernetes.io/control-plane: }, 1 node(s) had untolerated taint {node.kubernetes.io/unreachable: }. preemption: 0/3 nodes are available: 1 No preemption victims found for incoming pod, 2 Preemption is not helpful for scheduling..
kubescape       9m16s       Warning   FailedScheduling       pod/kubescape-exporter-29594725-nx8tf                                                    0/3 nodes are available: 1 Insufficient cpu, 1 node(s) had untolerated taint {node-role.kubernetes.io/control-plane: }, 1 node(s) had untolerated taint {node.kubernetes.io/unreachable: }. preemption: 0/3 nodes are available: 1 No preemption victims found for incoming pod, 2 Preemption is not helpful for scheduling..
kubescape       9m16s       Warning   FailedScheduling       pod/kubescape-exporter-29594730-dwbcf                                                    0/3 nodes are available: 1 Insufficient cpu, 1 node(s) had untolerated taint {node-role.kubernetes.io/control-plane: }, 1 node(s) had untolerated taint {node.kubernetes.io/unreachable: }. preemption: 0/3 nodes are available: 1 No preemption victims found for incoming pod, 2 Preemption is not helpful for scheduling..
kubescape       9m16s       Warning   FailedScheduling       pod/kubescape-exporter-29594735-2ttgz                                                    0/3 nodes are available: 1 Insufficient cpu, 1 node(s) had untolerated taint {node-role.kubernetes.io/control-plane: }, 1 node(s) had untolerated taint {node.kubernetes.io/unreachable: }. preemption: 0/3 nodes are available: 1 No preemption victims found for incoming pod, 2 Preemption is not helpful for scheduling..
kubescape       9m16s       Warning   FailedScheduling       pod/kubescape-exporter-29594740-fhnmn                                                    0/3 nodes are available: 1 Insufficient cpu, 1 node(s) had untolerated taint {node-role.kubernetes.io/control-plane: }, 1 node(s) had untolerated taint {node.kubernetes.io/unreachable: }. preemption: 0/3 nodes are available: 1 No preemption victims found for incoming pod, 2 Preemption is not helpful for scheduling..
kubescape       9m16s       Warning   FailedScheduling       pod/kubescape-exporter-29594745-6xpq5                                                    0/3 nodes are available: 1 Insufficient cpu, 1 node(s) had untolerated taint {node-role.kubernetes.io/control-plane: }, 1 node(s) had untolerated taint {node.kubernetes.io/unreachable: }. preemption: 0/3 nodes are available: 1 No preemption victims found for incoming pod, 2 Preemption is not helpful for scheduling..
kubescape       9m16s       Warning   FailedScheduling       pod/kubescape-exporter-29594750-fxnf4                                                    0/3 nodes are available: 1 Insufficient cpu, 1 node(s) had untolerated taint {node-role.kubernetes.io/control-plane: }, 1 node(s) had untolerated taint {node.kubernetes.io/unreachable: }. preemption: 0/3 nodes are available: 1 No preemption victims found for incoming pod, 2 Preemption is not helpful for scheduling..
kubescape       9m16s       Warning   FailedScheduling       pod/kubescape-exporter-29594755-zsgmn                                                    0/3 nodes are available: 1 Insufficient cpu, 1 node(s) had untolerated taint {node-role.kubernetes.io/control-plane: }, 1 node(s) had untolerated taint {node.kubernetes.io/unreachable: }. preemption: 0/3 nodes are available: 1 No preemption victims found for incoming pod, 2 Preemption is not helpful for scheduling..
kubescape       9m16s       Warning   FailedScheduling       pod/kubescape-exporter-29594760-82r52                                                    0/3 nodes are available: 1 Insufficient cpu, 1 node(s) had untolerated taint {node-role.kubernetes.io/control-plane: }, 1 node(s) had untolerated taint {node.kubernetes.io/unreachable: }. preemption: 0/3 nodes are available: 1 No preemption victims found for incoming pod, 2 Preemption is not helpful for scheduling..
kubescape       9m16s       Warning   FailedScheduling       pod/kubescape-exporter-29594765-ffv77                                                    0/3 nodes are available: 1 Insufficient cpu, 1 node(s) had untolerated taint {node-role.kubernetes.io/control-plane: }, 1 node(s) had untolerated taint {node.kubernetes.io/unreachable: }. preemption: 0/3 nodes are available: 1 No preemption victims found for incoming pod, 2 Preemption is not helpful for scheduling..
kubescape       9m16s       Warning   FailedScheduling       pod/kubescape-exporter-29594770-l5g7q                                                    0/3 nodes are available: 1 Insufficient cpu, 1 node(s) had untolerated taint {node-role.kubernetes.io/control-plane: }, 1 node(s) had untolerated taint {node.kubernetes.io/unreachable: }. preemption: 0/3 nodes are available: 1 No preemption victims found for incoming pod, 2 Preemption is not helpful for scheduling..
default         9m16s       Warning   FailedScheduling       pod/free5gc-free5gc-upf-upf-7f6cc6757c-s7lz7                                             0/3 nodes are available: 1 Insufficient cpu, 1 Insufficient memory, 1 node(s) had untolerated taint {node-role.kubernetes.io/control-plane: }, 1 node(s) had untolerated taint {node.kubernetes.io/unreachable: }. preemption: 0/3 nodes are available: 1 No preemption victims found for incoming pod, 2 Preemption is not helpful for scheduling..
kubescape       9m16s       Warning   FailedScheduling       pod/kubescape-exporter-29594780-x7w7h                                                    0/3 nodes are available: 1 Insufficient cpu, 1 node(s) had untolerated taint {node-role.kubernetes.io/control-plane: }, 1 node(s) had untolerated taint {node.kubernetes.io/unreachable: }. preemption: 0/3 nodes are available: 1 No preemption victims found for incoming pod, 2 Preemption is not helpful for scheduling..
kubescape       9m16s       Warning   FailedScheduling       pod/kubescape-exporter-29594785-t6mbp                                                    0/3 nodes are available: 1 Insufficient cpu, 1 node(s) had untolerated taint {node-role.kubernetes.io/control-plane: }, 1 node(s) had untolerated taint {node.kubernetes.io/unreachable: }. preemption: 0/3 nodes are available: 1 No preemption victims found for incoming pod, 2 Preemption is not helpful for scheduling..
kubescape       9m16s       Warning   FailedScheduling       pod/kubescape-exporter-29594790-rpk6x                                                    0/3 nodes are available: 1 Insufficient cpu, 1 node(s) had untolerated taint {node-role.kubernetes.io/control-plane: }, 1 node(s) had untolerated taint {node.kubernetes.io/unreachable: }. preemption: 0/3 nodes are available: 1 No preemption victims found for incoming pod, 2 Preemption is not helpful for scheduling..
kubescape       9m16s       Warning   FailedScheduling       pod/kubescape-exporter-29594795-j575k                                                    0/3 nodes are available: 1 Insufficient cpu, 1 node(s) had untolerated taint {node-role.kubernetes.io/control-plane: }, 1 node(s) had untolerated taint {node.kubernetes.io/unreachable: }. preemption: 0/3 nodes are available: 1 No preemption victims found for incoming pod, 2 Preemption is not helpful for scheduling..
kubescape       9m16s       Warning   FailedScheduling       pod/kubescape-exporter-29594800-kmkqj                                                    0/3 nodes are available: 1 Insufficient cpu, 1 node(s) had untolerated taint {node-role.kubernetes.io/control-plane: }, 1 node(s) had untolerated taint {node.kubernetes.io/unreachable: }. preemption: 0/3 nodes are available: 1 No preemption victims found for incoming pod, 2 Preemption is not helpful for scheduling..
kubescape       9m16s       Warning   FailedScheduling       pod/kubescape-exporter-29594805-v6kww                                                    0/3 nodes are available: 1 Insufficient cpu, 1 node(s) had untolerated taint {node-role.kubernetes.io/control-plane: }, 1 node(s) had untolerated taint {node.kubernetes.io/unreachable: }. preemption: 0/3 nodes are available: 1 No preemption victims found for incoming pod, 2 Preemption is not helpful for scheduling..
kubescape       9m16s       Warning   FailedScheduling       pod/kubescape-exporter-29594810-9nnvw                                                    0/3 nodes are available: 1 Insufficient cpu, 1 node(s) had untolerated taint {node-role.kubernetes.io/control-plane: }, 1 node(s) had untolerated taint {node.kubernetes.io/unreachable: }. preemption: 0/3 nodes are available: 1 No preemption victims found for incoming pod, 2 Preemption is not helpful for scheduling..
kubescape       9m16s       Warning   FailedScheduling       pod/kubescape-exporter-29594815-rs47l                                                    0/3 nodes are available: 1 Insufficient cpu, 1 node(s) had untolerated taint {node-role.kubernetes.io/control-plane: }, 1 node(s) had untolerated taint {node.kubernetes.io/unreachable: }. preemption: 0/3 nodes are available: 1 No preemption victims found for incoming pod, 2 Preemption is not helpful for scheduling..
kubescape       9m16s       Warning   FailedScheduling       pod/kubescape-exporter-29594820-d98nq                                                    0/3 nodes are available: 1 Insufficient cpu, 1 node(s) had untolerated taint {node-role.kubernetes.io/control-plane: }, 1 node(s) had untolerated taint {node.kubernetes.io/unreachable: }. preemption: 0/3 nodes are available: 1 No preemption victims found for incoming pod, 2 Preemption is not helpful for scheduling..
kubescape       9m16s       Warning   FailedScheduling       pod/kubescape-exporter-29594825-6mdnk                                                    0/3 nodes are available: 1 Insufficient cpu, 1 node(s) had untolerated taint {node-role.kubernetes.io/control-plane: }, 1 node(s) had untolerated taint {node.kubernetes.io/unreachable: }. preemption: 0/3 nodes are available: 1 No preemption victims found for incoming pod, 2 Preemption is not helpful for scheduling..
kubescape       9m16s       Warning   FailedScheduling       pod/kubescape-exporter-29594830-6rngv                                                    0/3 nodes are available: 1 Insufficient cpu, 1 node(s) had untolerated taint {node-role.kubernetes.io/control-plane: }, 1 node(s) had untolerated taint {node.kubernetes.io/unreachable: }. preemption: 0/3 nodes are available: 1 No preemption victims found for incoming pod, 2 Preemption is not helpful for scheduling..
kubescape       9m16s       Warning   FailedScheduling       pod/kubescape-exporter-29594835-xsnwt                                                    0/3 nodes are available: 1 Insufficient cpu, 1 node(s) had untolerated taint {node-role.kubernetes.io/control-plane: }, 1 node(s) had untolerated taint {node.kubernetes.io/unreachable: }. preemption: 0/3 nodes are available: 1 No preemption victims found for incoming pod, 2 Preemption is not helpful for scheduling..
kubescape       9m16s       Warning   FailedScheduling       pod/kubescape-exporter-29594840-qp2lk                                                    0/3 nodes are available: 1 Insufficient cpu, 1 node(s) had untolerated taint {node-role.kubernetes.io/control-plane: }, 1 node(s) had untolerated taint {node.kubernetes.io/unreachable: }. preemption: 0/3 nodes are available: 1 No preemption victims found for incoming pod, 2 Preemption is not helpful for scheduling..
kubescape       9m16s       Warning   FailedScheduling       pod/kubescape-exporter-29594845-hjm2k                                                    0/3 nodes are available: 1 Insufficient cpu, 1 node(s) had untolerated taint {node-role.kubernetes.io/control-plane: }, 1 node(s) had untolerated taint {node.kubernetes.io/unreachable: }. preemption: 0/3 nodes are available: 1 No preemption victims found for incoming pod, 2 Preemption is not helpful for scheduling..
kubescape       9m16s       Warning   FailedScheduling       pod/kubescape-exporter-29594850-w988f                                                    0/3 nodes are available: 1 Insufficient cpu, 1 node(s) had untolerated taint {node-role.kubernetes.io/control-plane: }, 1 node(s) had untolerated taint {node.kubernetes.io/unreachable: }. preemption: 0/3 nodes are available: 1 No preemption victims found for incoming pod, 2 Preemption is not helpful for scheduling..
kubescape       9m16s       Warning   FailedScheduling       pod/kubescape-exporter-29594855-nknnq                                                    0/3 nodes are available: 1 Insufficient cpu, 1 node(s) had untolerated taint {node-role.kubernetes.io/control-plane: }, 1 node(s) had untolerated taint {node.kubernetes.io/unreachable: }. preemption: 0/3 nodes are available: 1 No preemption victims found for incoming pod, 2 Preemption is not helpful for scheduling..
kubescape       9m16s       Warning   FailedScheduling       pod/kubescape-exporter-29594860-j5kmc                                                    0/3 nodes are available: 1 Insufficient cpu, 1 node(s) had untolerated taint {node-role.kubernetes.io/control-plane: }, 1 node(s) had untolerated taint {node.kubernetes.io/unreachable: }. preemption: 0/3 nodes are available: 1 No preemption victims found for incoming pod, 2 Preemption is not helpful for scheduling..
kubescape       9m16s       Warning   FailedScheduling       pod/kubescape-exporter-29594865-rtfzp                                                    0/3 nodes are available: 1 Insufficient cpu, 1 node(s) had untolerated taint {node-role.kubernetes.io/control-plane: }, 1 node(s) had untolerated taint {node.kubernetes.io/unreachable: }. preemption: 0/3 nodes are available: 1 No preemption victims found for incoming pod, 2 Preemption is not helpful for scheduling..
kubescape       9m16s       Warning   FailedScheduling       pod/kubescape-exporter-29594870-tft99                                                    0/3 nodes are available: 1 Insufficient cpu, 1 node(s) had untolerated taint {node-role.kubernetes.io/control-plane: }, 1 node(s) had untolerated taint {node.kubernetes.io/unreachable: }. preemption: 0/3 nodes are available: 1 No preemption victims found for incoming pod, 2 Preemption is not helpful for scheduling..
kubescape       9m16s       Warning   FailedScheduling       pod/kubescape-exporter-29594875-8w9dv                                                    0/3 nodes are available: 1 Insufficient cpu, 1 node(s) had untolerated taint {node-role.kubernetes.io/control-plane: }, 1 node(s) had untolerated taint {node.kubernetes.io/unreachable: }. preemption: 0/3 nodes are available: 1 No preemption victims found for incoming pod, 2 Preemption is not helpful for scheduling..
kubescape       9m16s       Warning   FailedScheduling       pod/kubescape-exporter-29594880-xx85z                                                    0/3 nodes are available: 1 Insufficient cpu, 1 node(s) had untolerated taint {node-role.kubernetes.io/control-plane: }, 1 node(s) had untolerated taint {node.kubernetes.io/unreachable: }. preemption: 0/3 nodes are available: 1 No preemption victims found for incoming pod, 2 Preemption is not helpful for scheduling..
kubescape       9m16s       Warning   FailedScheduling       pod/kubescape-exporter-29594885-kzqd7                                                    0/3 nodes are available: 1 Insufficient cpu, 1 node(s) had untolerated taint {node-role.kubernetes.io/control-plane: }, 1 node(s) had untolerated taint {node.kubernetes.io/unreachable: }. preemption: 0/3 nodes are available: 1 No preemption victims found for incoming pod, 2 Preemption is not helpful for scheduling..
kubescape       9m16s       Warning   FailedScheduling       pod/kubescape-exporter-29594890-cvvhw                                                    0/3 nodes are available: 1 Insufficient cpu, 1 node(s) had untolerated taint {node-role.kubernetes.io/control-plane: }, 1 node(s) had untolerated taint {node.kubernetes.io/unreachable: }. preemption: 0/3 nodes are available: 1 No preemption victims found for incoming pod, 2 Preemption is not helpful for scheduling..
kubescape       9m16s       Warning   FailedScheduling       pod/kubescape-exporter-29594895-thjbq                                                    0/3 nodes are available: 1 Insufficient cpu, 1 node(s) had untolerated taint {node-role.kubernetes.io/control-plane: }, 1 node(s) had untolerated taint {node.kubernetes.io/unreachable: }. preemption: 0/3 nodes are available: 1 No preemption victims found for incoming pod, 2 Preemption is not helpful for scheduling..
kubescape       9m16s       Warning   FailedScheduling       pod/kubescape-exporter-29594900-svbfz                                                    0/3 nodes are available: 1 Insufficient cpu, 1 node(s) had untolerated taint {node-role.kubernetes.io/control-plane: }, 1 node(s) had untolerated taint {node.kubernetes.io/unreachable: }. preemption: 0/3 nodes are available: 1 No preemption victims found for incoming pod, 2 Preemption is not helpful for scheduling..
kubescape       9m16s       Warning   FailedScheduling       pod/kubescape-exporter-29594905-rkzcf                                                    0/3 nodes are available: 1 Insufficient cpu, 1 node(s) had untolerated taint {node-role.kubernetes.io/control-plane: }, 1 node(s) had untolerated taint {node.kubernetes.io/unreachable: }. preemption: 0/3 nodes are available: 1 No preemption victims found for incoming pod, 2 Preemption is not helpful for scheduling..
kubescape       9m16s       Warning   FailedScheduling       pod/kubescape-exporter-29594910-gvctc                                                    0/3 nodes are available: 1 Insufficient cpu, 1 node(s) had untolerated taint {node-role.kubernetes.io/control-plane: }, 1 node(s) had untolerated taint {node.kubernetes.io/unreachable: }. preemption: 0/3 nodes are available: 1 No preemption victims found for incoming pod, 2 Preemption is not helpful for scheduling..
kubescape       9m16s       Warning   FailedScheduling       pod/kubescape-exporter-29594915-bx8fj                                                    0/3 nodes are available: 1 Insufficient cpu, 1 node(s) had untolerated taint {node-role.kubernetes.io/control-plane: }, 1 node(s) had untolerated taint {node.kubernetes.io/unreachable: }. preemption: 0/3 nodes are available: 1 No preemption victims found for incoming pod, 2 Preemption is not helpful for scheduling..
kubescape       9m16s       Warning   FailedScheduling       pod/kubescape-exporter-29594920-d8ng7                                                    0/3 nodes are available: 1 Insufficient cpu, 1 node(s) had untolerated taint {node-role.kubernetes.io/control-plane: }, 1 node(s) had untolerated taint {node.kubernetes.io/unreachable: }. preemption: 0/3 nodes are available: 1 No preemption victims found for incoming pod, 2 Preemption is not helpful for scheduling..
kubescape       9m16s       Warning   FailedScheduling       pod/kubescape-exporter-29594925-tjct8                                                    0/3 nodes are available: 1 Insufficient cpu, 1 node(s) had untolerated taint {node-role.kubernetes.io/control-plane: }, 1 node(s) had untolerated taint {node.kubernetes.io/unreachable: }. preemption: 0/3 nodes are available: 1 No preemption victims found for incoming pod, 2 Preemption is not helpful for scheduling..
kubescape       9m16s       Warning   FailedScheduling       pod/kubescape-exporter-29594930-4ps68                                                    0/3 nodes are available: 1 Insufficient cpu, 1 node(s) had untolerated taint {node-role.kubernetes.io/control-plane: }, 1 node(s) had untolerated taint {node.kubernetes.io/unreachable: }. preemption: 0/3 nodes are available: 1 No preemption victims found for incoming pod, 2 Preemption is not helpful for scheduling..
kubescape       9m16s       Warning   FailedScheduling       pod/kubescape-exporter-29594935-dwzs6                                                    0/3 nodes are available: 1 Insufficient cpu, 1 node(s) had untolerated taint {node-role.kubernetes.io/control-plane: }, 1 node(s) had untolerated taint {node.kubernetes.io/unreachable: }. preemption: 0/3 nodes are available: 1 No preemption victims found for incoming pod, 2 Preemption is not helpful for scheduling..
kubescape       9m16s       Warning   FailedScheduling       pod/kubescape-exporter-29594940-l925g                                                    0/3 nodes are available: 1 Insufficient cpu, 1 node(s) had untolerated taint {node-role.kubernetes.io/control-plane: }, 1 node(s) had untolerated taint {node.kubernetes.io/unreachable: }. preemption: 0/3 nodes are available: 1 No preemption victims found for incoming pod, 2 Preemption is not helpful for scheduling..
kubescape       9m16s       Warning   FailedScheduling       pod/kubescape-exporter-29594945-bt54p                                                    0/3 nodes are available: 1 Insufficient cpu, 1 node(s) had untolerated taint {node-role.kubernetes.io/control-plane: }, 1 node(s) had untolerated taint {node.kubernetes.io/unreachable: }. preemption: 0/3 nodes are available: 1 No preemption victims found for incoming pod, 2 Preemption is not helpful for scheduling..
kubescape       9m16s       Warning   FailedScheduling       pod/kubescape-exporter-29594950-s7dd5                                                    0/3 nodes are available: 1 Insufficient cpu, 1 node(s) had untolerated taint {node-role.kubernetes.io/control-plane: }, 1 node(s) had untolerated taint {node.kubernetes.io/unreachable: }. preemption: 0/3 nodes are available: 1 No preemption victims found for incoming pod, 2 Preemption is not helpful for scheduling..
kubescape       9m16s       Warning   FailedScheduling       pod/kubescape-exporter-29594955-x9lrl                                                    0/3 nodes are available: 1 Insufficient cpu, 1 node(s) had untolerated taint {node-role.kubernetes.io/control-plane: }, 1 node(s) had untolerated taint {node.kubernetes.io/unreachable: }. preemption: 0/3 nodes are available: 1 No preemption victims found for incoming pod, 2 Preemption is not helpful for scheduling..
kubescape       9m16s       Warning   FailedScheduling       pod/kubescape-exporter-29594960-rwmfv                                                    0/3 nodes are available: 1 Insufficient cpu, 1 node(s) had untolerated taint {node-role.kubernetes.io/control-plane: }, 1 node(s) had untolerated taint {node.kubernetes.io/unreachable: }. preemption: 0/3 nodes are available: 1 No preemption victims found for incoming pod, 2 Preemption is not helpful for scheduling..
kubescape       9m16s       Warning   FailedScheduling       pod/kubescape-exporter-29594965-2f6fg                                                    0/3 nodes are available: 1 Insufficient cpu, 1 node(s) had untolerated taint {node-role.kubernetes.io/control-plane: }, 1 node(s) had untolerated taint {node.kubernetes.io/unreachable: }. preemption: 0/3 nodes are available: 1 No preemption victims found for incoming pod, 2 Preemption is not helpful for scheduling..
kubescape       9m16s       Warning   FailedScheduling       pod/kubescape-exporter-29594970-4tw26                                                    0/3 nodes are available: 1 Insufficient cpu, 1 node(s) had untolerated taint {node-role.kubernetes.io/control-plane: }, 1 node(s) had untolerated taint {node.kubernetes.io/unreachable: }. preemption: 0/3 nodes are available: 1 No preemption victims found for incoming pod, 2 Preemption is not helpful for scheduling..
kubescape       9m16s       Warning   FailedScheduling       pod/kubescape-exporter-29594975-s5l6m                                                    0/3 nodes are available: 1 Insufficient cpu, 1 node(s) had untolerated taint {node-role.kubernetes.io/control-plane: }, 1 node(s) had untolerated taint {node.kubernetes.io/unreachable: }. preemption: 0/3 nodes are available: 1 No preemption victims found for incoming pod, 2 Preemption is not helpful for scheduling..
kubescape       9m16s       Warning   FailedScheduling       pod/kubescape-exporter-29594980-872hd                                                    0/3 nodes are available: 1 Insufficient cpu, 1 node(s) had untolerated taint {node-role.kubernetes.io/control-plane: }, 1 node(s) had untolerated taint {node.kubernetes.io/unreachable: }. preemption: 0/3 nodes are available: 1 No preemption victims found for incoming pod, 2 Preemption is not helpful for scheduling..
kubescape       9m16s       Warning   FailedScheduling       pod/kubescape-exporter-29594985-g4g8n                                                    0/3 nodes are available: 1 Insufficient cpu, 1 node(s) had untolerated taint {node-role.kubernetes.io/control-plane: }, 1 node(s) had untolerated taint {node.kubernetes.io/unreachable: }. preemption: 0/3 nodes are available: 1 No preemption victims found for incoming pod, 2 Preemption is not helpful for scheduling..
kubescape       9m16s       Warning   FailedScheduling       pod/kubescape-exporter-29594990-fc8mw                                                    0/3 nodes are available: 1 Insufficient cpu, 1 node(s) had untolerated taint {node-role.kubernetes.io/control-plane: }, 1 node(s) had untolerated taint {node.kubernetes.io/unreachable: }. preemption: 0/3 nodes are available: 1 No preemption victims found for incoming pod, 2 Preemption is not helpful for scheduling..
kubescape       9m16s       Warning   FailedScheduling       pod/kubescape-exporter-29594995-qbc7j                                                    0/3 nodes are available: 1 Insufficient cpu, 1 node(s) had untolerated taint {node-role.kubernetes.io/control-plane: }, 1 node(s) had untolerated taint {node.kubernetes.io/unreachable: }. preemption: 0/3 nodes are available: 1 No preemption victims found for incoming pod, 2 Preemption is not helpful for scheduling..
kubescape       9m16s       Warning   FailedScheduling       pod/kubescape-exporter-29595000-vnbg6                                                    0/3 nodes are available: 1 Insufficient cpu, 1 node(s) had untolerated taint {node-role.kubernetes.io/control-plane: }, 1 node(s) had untolerated taint {node.kubernetes.io/unreachable: }. preemption: 0/3 nodes are available: 1 No preemption victims found for incoming pod, 2 Preemption is not helpful for scheduling..
kubescape       9m16s       Warning   FailedScheduling       pod/kubescape-exporter-29595005-v8ps7                                                    0/3 nodes are available: 1 Insufficient cpu, 1 node(s) had untolerated taint {node-role.kubernetes.io/control-plane: }, 1 node(s) had untolerated taint {node.kubernetes.io/unreachable: }. preemption: 0/3 nodes are available: 1 No preemption victims found for incoming pod, 2 Preemption is not helpful for scheduling..
kubescape       9m16s       Warning   FailedScheduling       pod/kubescape-exporter-29595010-4nqk5                                                    0/3 nodes are available: 1 Insufficient cpu, 1 node(s) had untolerated taint {node-role.kubernetes.io/control-plane: }, 1 node(s) had untolerated taint {node.kubernetes.io/unreachable: }. preemption: 0/3 nodes are available: 1 No preemption victims found for incoming pod, 2 Preemption is not helpful for scheduling..
kubescape       9m16s       Warning   FailedScheduling       pod/kubescape-exporter-29595015-vrjw5                                                    0/3 nodes are available: 1 Insufficient cpu, 1 node(s) had untolerated taint {node-role.kubernetes.io/control-plane: }, 1 node(s) had untolerated taint {node.kubernetes.io/unreachable: }. preemption: 0/3 nodes are available: 1 No preemption victims found for incoming pod, 2 Preemption is not helpful for scheduling..
kubescape       9m16s       Warning   FailedScheduling       pod/kubescape-exporter-29595020-z966c                                                    0/3 nodes are available: 1 Insufficient cpu, 1 node(s) had untolerated taint {node-role.kubernetes.io/control-plane: }, 1 node(s) had untolerated taint {node.kubernetes.io/unreachable: }. preemption: 0/3 nodes are available: 1 No preemption victims found for incoming pod, 2 Preemption is not helpful for scheduling..
kubescape       9m16s       Warning   FailedScheduling       pod/kubescape-exporter-29595025-9hsfn                                                    0/3 nodes are available: 1 Insufficient cpu, 1 node(s) had untolerated taint {node-role.kubernetes.io/control-plane: }, 1 node(s) had untolerated taint {node.kubernetes.io/unreachable: }. preemption: 0/3 nodes are available: 1 No preemption victims found for incoming pod, 2 Preemption is not helpful for scheduling..
kubescape       9m16s       Warning   FailedScheduling       pod/kubescape-exporter-29595030-vlvf4                                                    0/3 nodes are available: 1 Insufficient cpu, 1 node(s) had untolerated taint {node-role.kubernetes.io/control-plane: }, 1 node(s) had untolerated taint {node.kubernetes.io/unreachable: }. preemption: 0/3 nodes are available: 1 No preemption victims found for incoming pod, 2 Preemption is not helpful for scheduling..
kubescape       9m16s       Warning   FailedScheduling       pod/kubescape-exporter-29595035-s7gj5                                                    0/3 nodes are available: 1 Insufficient cpu, 1 node(s) had untolerated taint {node-role.kubernetes.io/control-plane: }, 1 node(s) had untolerated taint {node.kubernetes.io/unreachable: }. preemption: 0/3 nodes are available: 1 No preemption victims found for incoming pod, 2 Preemption is not helpful for scheduling..
kubescape       9m16s       Warning   FailedScheduling       pod/kubescape-exporter-29595040-j5xbw                                                    0/3 nodes are available: 1 Insufficient cpu, 1 node(s) had untolerated taint {node-role.kubernetes.io/control-plane: }, 1 node(s) had untolerated taint {node.kubernetes.io/unreachable: }. preemption: 0/3 nodes are available: 1 No preemption victims found for incoming pod, 2 Preemption is not helpful for scheduling..
kubescape       9m16s       Warning   FailedScheduling       pod/kubescape-exporter-29595045-fk6q2                                                    0/3 nodes are available: 1 Insufficient cpu, 1 node(s) had untolerated taint {node-role.kubernetes.io/control-plane: }, 1 node(s) had untolerated taint {node.kubernetes.io/unreachable: }. preemption: 0/3 nodes are available: 1 No preemption victims found for incoming pod, 2 Preemption is not helpful for scheduling..
kubescape       9m16s       Warning   FailedScheduling       pod/kubescape-exporter-29595050-vd2cz                                                    0/3 nodes are available: 1 Insufficient cpu, 1 node(s) had untolerated taint {node-role.kubernetes.io/control-plane: }, 1 node(s) had untolerated taint {node.kubernetes.io/unreachable: }. preemption: 0/3 nodes are available: 1 No preemption victims found for incoming pod, 2 Preemption is not helpful for scheduling..
kubescape       9m16s       Warning   FailedScheduling       pod/kubescape-exporter-29595055-7p7lj                                                    0/3 nodes are available: 1 Insufficient cpu, 1 node(s) had untolerated taint {node-role.kubernetes.io/control-plane: }, 1 node(s) had untolerated taint {node.kubernetes.io/unreachable: }. preemption: 0/3 nodes are available: 1 No preemption victims found for incoming pod, 2 Preemption is not helpful for scheduling..
kubescape       9m17s       Warning   FailedScheduling       pod/kubescape-exporter-29595060-wcz8r                                                    0/3 nodes are available: 1 Insufficient cpu, 1 node(s) had untolerated taint {node-role.kubernetes.io/control-plane: }, 1 node(s) had untolerated taint {node.kubernetes.io/unreachable: }. preemption: 0/3 nodes are available: 1 No preemption victims found for incoming pod, 2 Preemption is not helpful for scheduling..
kubescape       9m17s       Warning   FailedScheduling       pod/kubescape-exporter-29595065-wvnj9                                                    0/3 nodes are available: 1 Insufficient cpu, 1 node(s) had untolerated taint {node-role.kubernetes.io/control-plane: }, 1 node(s) had untolerated taint {node.kubernetes.io/unreachable: }. preemption: 0/3 nodes are available: 1 No preemption victims found for incoming pod, 2 Preemption is not helpful for scheduling..
kubescape       9m17s       Warning   FailedScheduling       pod/kubescape-exporter-29595070-6bmhm                                                    0/3 nodes are available: 1 Insufficient cpu, 1 node(s) had untolerated taint {node-role.kubernetes.io/control-plane: }, 1 node(s) had untolerated taint {node.kubernetes.io/unreachable: }. preemption: 0/3 nodes are available: 1 No preemption victims found for incoming pod, 2 Preemption is not helpful for scheduling..
kubescape       9m17s       Warning   FailedScheduling       pod/kubescape-exporter-29595075-jwkqd                                                    0/3 nodes are available: 1 Insufficient cpu, 1 node(s) had untolerated taint {node-role.kubernetes.io/control-plane: }, 1 node(s) had untolerated taint {node.kubernetes.io/unreachable: }. preemption: 0/3 nodes are available: 1 No preemption victims found for incoming pod, 2 Preemption is not helpful for scheduling..
kubescape       9m17s       Warning   FailedScheduling       pod/kubescape-exporter-29595080-j66sn                                                    0/3 nodes are available: 1 Insufficient cpu, 1 node(s) had untolerated taint {node-role.kubernetes.io/control-plane: }, 1 node(s) had untolerated taint {node.kubernetes.io/unreachable: }. preemption: 0/3 nodes are available: 1 No preemption victims found for incoming pod, 2 Preemption is not helpful for scheduling..
kubescape       9m17s       Warning   FailedScheduling       pod/kubescape-exporter-29595085-xls27                                                    0/3 nodes are available: 1 Insufficient cpu, 1 node(s) had untolerated taint {node-role.kubernetes.io/control-plane: }, 1 node(s) had untolerated taint {node.kubernetes.io/unreachable: }. preemption: 0/3 nodes are available: 1 No preemption victims found for incoming pod, 2 Preemption is not helpful for scheduling..
kubescape       9m17s       Warning   FailedScheduling       pod/kubescape-exporter-29595090-fjrgc                                                    0/3 nodes are available: 1 Insufficient cpu, 1 node(s) had untolerated taint {node-role.kubernetes.io/control-plane: }, 1 node(s) had untolerated taint {node.kubernetes.io/unreachable: }. preemption: 0/3 nodes are available: 1 No preemption victims found for incoming pod, 2 Preemption is not helpful for scheduling..
kubescape       9m17s       Warning   FailedScheduling       pod/kubescape-exporter-29595095-pm6jl                                                    0/3 nodes are available: 1 Insufficient cpu, 1 node(s) had untolerated taint {node-role.kubernetes.io/control-plane: }, 1 node(s) had untolerated taint {node.kubernetes.io/unreachable: }. preemption: 0/3 nodes are available: 1 No preemption victims found for incoming pod, 2 Preemption is not helpful for scheduling..
kubescape       9m17s       Warning   FailedScheduling       pod/kubescape-exporter-29595100-xtmsv                                                    0/3 nodes are available: 1 Insufficient cpu, 1 node(s) had untolerated taint {node-role.kubernetes.io/control-plane: }, 1 node(s) had untolerated taint {node.kubernetes.io/unreachable: }. preemption: 0/3 nodes are available: 1 No preemption victims found for incoming pod, 2 Preemption is not helpful for scheduling..
kubescape       9m17s       Warning   FailedScheduling       pod/kubescape-exporter-29595105-nd9jr                                                    0/3 nodes are available: 1 Insufficient cpu, 1 node(s) had untolerated taint {node-role.kubernetes.io/control-plane: }, 1 node(s) had untolerated taint {node.kubernetes.io/unreachable: }. preemption: 0/3 nodes are available: 1 No preemption victims found for incoming pod, 2 Preemption is not helpful for scheduling..
kubescape       9m17s       Warning   FailedScheduling       pod/kubescape-exporter-29595110-mvf2p                                                    0/3 nodes are available: 1 Insufficient cpu, 1 node(s) had untolerated taint {node-role.kubernetes.io/control-plane: }, 1 node(s) had untolerated taint {node.kubernetes.io/unreachable: }. preemption: 0/3 nodes are available: 1 No preemption victims found for incoming pod, 2 Preemption is not helpful for scheduling..
kubescape       9m17s       Warning   FailedScheduling       pod/kubescape-exporter-29595115-25v4g                                                    0/3 nodes are available: 1 Insufficient cpu, 1 node(s) had untolerated taint {node-role.kubernetes.io/control-plane: }, 1 node(s) had untolerated taint {node.kubernetes.io/unreachable: }. preemption: 0/3 nodes are available: 1 No preemption victims found for incoming pod, 2 Preemption is not helpful for scheduling..
kubescape       9m17s       Warning   FailedScheduling       pod/kubescape-exporter-29595120-vtv8r                                                    0/3 nodes are available: 1 Insufficient cpu, 1 node(s) had untolerated taint {node-role.kubernetes.io/control-plane: }, 1 node(s) had untolerated taint {node.kubernetes.io/unreachable: }. preemption: 0/3 nodes are available: 1 No preemption victims found for incoming pod, 2 Preemption is not helpful for scheduling..
kubescape       9m17s       Warning   FailedScheduling       pod/kubescape-exporter-29595125-2xznn                                                    0/3 nodes are available: 1 Insufficient cpu, 1 node(s) had untolerated taint {node-role.kubernetes.io/control-plane: }, 1 node(s) had untolerated taint {node.kubernetes.io/unreachable: }. preemption: 0/3 nodes are available: 1 No preemption victims found for incoming pod, 2 Preemption is not helpful for scheduling..
kubescape       9m17s       Warning   FailedScheduling       pod/kubescape-exporter-29595130-szb5r                                                    0/3 nodes are available: 1 Insufficient cpu, 1 node(s) had untolerated taint {node-role.kubernetes.io/control-plane: }, 1 node(s) had untolerated taint {node.kubernetes.io/unreachable: }. preemption: 0/3 nodes are available: 1 No preemption victims found for incoming pod, 2 Preemption is not helpful for scheduling..
kubescape       9m17s       Warning   FailedScheduling       pod/kubescape-exporter-29595135-26dx5                                                    0/3 nodes are available: 1 Insufficient cpu, 1 node(s) had untolerated taint {node-role.kubernetes.io/control-plane: }, 1 node(s) had untolerated taint {node.kubernetes.io/unreachable: }. preemption: 0/3 nodes are available: 1 No preemption victims found for incoming pod, 2 Preemption is not helpful for scheduling..
kubescape       9m17s       Warning   FailedScheduling       pod/kubescape-exporter-29595140-kjfcr                                                    0/3 nodes are available: 1 Insufficient cpu, 1 node(s) had untolerated taint {node-role.kubernetes.io/control-plane: }, 1 node(s) had untolerated taint {node.kubernetes.io/unreachable: }. preemption: 0/3 nodes are available: 1 No preemption victims found for incoming pod, 2 Preemption is not helpful for scheduling..
kubescape       9m17s       Warning   FailedScheduling       pod/kubescape-exporter-29595145-r25f7                                                    0/3 nodes are available: 1 Insufficient cpu, 1 node(s) had untolerated taint {node-role.kubernetes.io/control-plane: }, 1 node(s) had untolerated taint {node.kubernetes.io/unreachable: }. preemption: 0/3 nodes are available: 1 No preemption victims found for incoming pod, 2 Preemption is not helpful for scheduling..
kubescape       9m17s       Warning   FailedScheduling       pod/kubescape-exporter-29595150-h85l5                                                    0/3 nodes are available: 1 Insufficient cpu, 1 node(s) had untolerated taint {node-role.kubernetes.io/control-plane: }, 1 node(s) had untolerated taint {node.kubernetes.io/unreachable: }. preemption: 0/3 nodes are available: 1 No preemption victims found for incoming pod, 2 Preemption is not helpful for scheduling..
kubescape       9m17s       Warning   FailedScheduling       pod/kubescape-exporter-29595155-mhbm5                                                    0/3 nodes are available: 1 Insufficient cpu, 1 node(s) had untolerated taint {node-role.kubernetes.io/control-plane: }, 1 node(s) had untolerated taint {node.kubernetes.io/unreachable: }. preemption: 0/3 nodes are available: 1 No preemption victims found for incoming pod, 2 Preemption is not helpful for scheduling..
kubescape       9m17s       Warning   FailedScheduling       pod/kubescape-exporter-29595160-xnpq6                                                    0/3 nodes are available: 1 Insufficient cpu, 1 node(s) had untolerated taint {node-role.kubernetes.io/control-plane: }, 1 node(s) had untolerated taint {node.kubernetes.io/unreachable: }. preemption: 0/3 nodes are available: 1 No preemption victims found for incoming pod, 2 Preemption is not helpful for scheduling..
kubescape       9m17s       Warning   FailedScheduling       pod/kubescape-exporter-29595165-kngkj                                                    0/3 nodes are available: 1 Insufficient cpu, 1 node(s) had untolerated taint {node-role.kubernetes.io/control-plane: }, 1 node(s) had untolerated taint {node.kubernetes.io/unreachable: }. preemption: 0/3 nodes are available: 1 No preemption victims found for incoming pod, 2 Preemption is not helpful for scheduling..
kubescape       9m17s       Warning   FailedScheduling       pod/kubescape-exporter-29595170-p562c                                                    0/3 nodes are available: 1 Insufficient cpu, 1 node(s) had untolerated taint {node-role.kubernetes.io/control-plane: }, 1 node(s) had untolerated taint {node.kubernetes.io/unreachable: }. preemption: 0/3 nodes are available: 1 No preemption victims found for incoming pod, 2 Preemption is not helpful for scheduling..
kubescape       9m17s       Warning   FailedScheduling       pod/kubescape-exporter-29595175-dmcbl                                                    0/3 nodes are available: 1 Insufficient cpu, 1 node(s) had untolerated taint {node-role.kubernetes.io/control-plane: }, 1 node(s) had untolerated taint {node.kubernetes.io/unreachable: }. preemption: 0/3 nodes are available: 1 No preemption victims found for incoming pod, 2 Preemption is not helpful for scheduling..
kubescape       9m17s       Warning   FailedScheduling       pod/kubescape-exporter-29595180-68m2r                                                    0/3 nodes are available: 1 Insufficient cpu, 1 node(s) had untolerated taint {node-role.kubernetes.io/control-plane: }, 1 node(s) had untolerated taint {node.kubernetes.io/unreachable: }. preemption: 0/3 nodes are available: 1 No preemption victims found for incoming pod, 2 Preemption is not helpful for scheduling..
kubescape       9m17s       Warning   FailedScheduling       pod/kubescape-exporter-29595185-thdr2                                                    0/3 nodes are available: 1 Insufficient cpu, 1 node(s) had untolerated taint {node-role.kubernetes.io/control-plane: }, 1 node(s) had untolerated taint {node.kubernetes.io/unreachable: }. preemption: 0/3 nodes are available: 1 No preemption victims found for incoming pod, 2 Preemption is not helpful for scheduling..
kubescape       9m17s       Warning   FailedScheduling       pod/kubescape-exporter-29595190-8cfjw                                                    0/3 nodes are available: 1 Insufficient cpu, 1 node(s) had untolerated taint {node-role.kubernetes.io/control-plane: }, 1 node(s) had untolerated taint {node.kubernetes.io/unreachable: }. preemption: 0/3 nodes are available: 1 No preemption victims found for incoming pod, 2 Preemption is not helpful for scheduling..
kubescape       9m17s       Warning   FailedScheduling       pod/kubescape-exporter-29595195-lkcrr                                                    0/3 nodes are available: 1 Insufficient cpu, 1 node(s) had untolerated taint {node-role.kubernetes.io/control-plane: }, 1 node(s) had untolerated taint {node.kubernetes.io/unreachable: }. preemption: 0/3 nodes are available: 1 No preemption victims found for incoming pod, 2 Preemption is not helpful for scheduling..
kubescape       9m17s       Warning   FailedScheduling       pod/kubescape-exporter-29595200-fqz7m                                                    0/3 nodes are available: 1 Insufficient cpu, 1 node(s) had untolerated taint {node-role.kubernetes.io/control-plane: }, 1 node(s) had untolerated taint {node.kubernetes.io/unreachable: }. preemption: 0/3 nodes are available: 1 No preemption victims found for incoming pod, 2 Preemption is not helpful for scheduling..
kubescape       9m17s       Warning   FailedScheduling       pod/kubescape-exporter-29595205-xpjwj                                                    0/3 nodes are available: 1 Insufficient cpu, 1 node(s) had untolerated taint {node-role.kubernetes.io/control-plane: }, 1 node(s) had untolerated taint {node.kubernetes.io/unreachable: }. preemption: 0/3 nodes are available: 1 No preemption victims found for incoming pod, 2 Preemption is not helpful for scheduling..
kubescape       9m17s       Warning   FailedScheduling       pod/kubescape-exporter-29595210-2tc5g                                                    0/3 nodes are available: 1 Insufficient cpu, 1 node(s) had untolerated taint {node-role.kubernetes.io/control-plane: }, 1 node(s) had untolerated taint {node.kubernetes.io/unreachable: }. preemption: 0/3 nodes are available: 1 No preemption victims found for incoming pod, 2 Preemption is not helpful for scheduling..
kubescape       9m17s       Warning   FailedScheduling       pod/kubescape-exporter-29595215-vgvpp                                                    0/3 nodes are available: 1 Insufficient cpu, 1 node(s) had untolerated taint {node-role.kubernetes.io/control-plane: }, 1 node(s) had untolerated taint {node.kubernetes.io/unreachable: }. preemption: 0/3 nodes are available: 1 No preemption victims found for incoming pod, 2 Preemption is not helpful for scheduling..
kubescape       9m17s       Warning   FailedScheduling       pod/kubescape-exporter-29595220-8h4xf                                                    0/3 nodes are available: 1 Insufficient cpu, 1 node(s) had untolerated taint {node-role.kubernetes.io/control-plane: }, 1 node(s) had untolerated taint {node.kubernetes.io/unreachable: }. preemption: 0/3 nodes are available: 1 No preemption victims found for incoming pod, 2 Preemption is not helpful for scheduling..
kubescape       9m17s       Warning   FailedScheduling       pod/kubescape-exporter-29595225-xj6zp                                                    0/3 nodes are available: 1 Insufficient cpu, 1 node(s) had untolerated taint {node-role.kubernetes.io/control-plane: }, 1 node(s) had untolerated taint {node.kubernetes.io/unreachable: }. preemption: 0/3 nodes are available: 1 No preemption victims found for incoming pod, 2 Preemption is not helpful for scheduling..
kubescape       9m17s       Warning   FailedScheduling       pod/kubescape-exporter-29595230-t2b5j                                                    0/3 nodes are available: 1 Insufficient cpu, 1 node(s) had untolerated taint {node-role.kubernetes.io/control-plane: }, 1 node(s) had untolerated taint {node.kubernetes.io/unreachable: }. preemption: 0/3 nodes are available: 1 No preemption victims found for incoming pod, 2 Preemption is not helpful for scheduling..
kubescape       9m17s       Warning   FailedScheduling       pod/kubescape-exporter-29595235-z4gjf                                                    0/3 nodes are available: 1 Insufficient cpu, 1 node(s) had untolerated taint {node-role.kubernetes.io/control-plane: }, 1 node(s) had untolerated taint {node.kubernetes.io/unreachable: }. preemption: 0/3 nodes are available: 1 No preemption victims found for incoming pod, 2 Preemption is not helpful for scheduling..
kubescape       9m17s       Warning   FailedScheduling       pod/kubescape-exporter-29595240-dgqln                                                    0/3 nodes are available: 1 Insufficient cpu, 1 node(s) had untolerated taint {node-role.kubernetes.io/control-plane: }, 1 node(s) had untolerated taint {node.kubernetes.io/unreachable: }. preemption: 0/3 nodes are available: 1 No preemption victims found for incoming pod, 2 Preemption is not helpful for scheduling..
kubescape       9m17s       Warning   FailedScheduling       pod/kubescape-exporter-29595245-m8xv9                                                    0/3 nodes are available: 1 Insufficient cpu, 1 node(s) had untolerated taint {node-role.kubernetes.io/control-plane: }, 1 node(s) had untolerated taint {node.kubernetes.io/unreachable: }. preemption: 0/3 nodes are available: 1 No preemption victims found for incoming pod, 2 Preemption is not helpful for scheduling..
kubescape       9m17s       Warning   FailedScheduling       pod/kubescape-exporter-29595250-9sdb5                                                    0/3 nodes are available: 1 Insufficient cpu, 1 node(s) had untolerated taint {node-role.kubernetes.io/control-plane: }, 1 node(s) had untolerated taint {node.kubernetes.io/unreachable: }. preemption: 0/3 nodes are available: 1 No preemption victims found for incoming pod, 2 Preemption is not helpful for scheduling..
kubescape       9m17s       Warning   FailedScheduling       pod/kubescape-exporter-29595255-6gdgq                                                    0/3 nodes are available: 1 Insufficient cpu, 1 node(s) had untolerated taint {node-role.kubernetes.io/control-plane: }, 1 node(s) had untolerated taint {node.kubernetes.io/unreachable: }. preemption: 0/3 nodes are available: 1 No preemption victims found for incoming pod, 2 Preemption is not helpful for scheduling..
kubescape       9m17s       Warning   FailedScheduling       pod/kubescape-exporter-29595260-tj5rd                                                    0/3 nodes are available: 1 Insufficient cpu, 1 node(s) had untolerated taint {node-role.kubernetes.io/control-plane: }, 1 node(s) had untolerated taint {node.kubernetes.io/unreachable: }. preemption: 0/3 nodes are available: 1 No preemption victims found for incoming pod, 2 Preemption is not helpful for scheduling..
kubescape       9m17s       Warning   FailedScheduling       pod/kubescape-exporter-29595265-gvg2m                                                    0/3 nodes are available: 1 Insufficient cpu, 1 node(s) had untolerated taint {node-role.kubernetes.io/control-plane: }, 1 node(s) had untolerated taint {node.kubernetes.io/unreachable: }. preemption: 0/3 nodes are available: 1 No preemption victims found for incoming pod, 2 Preemption is not helpful for scheduling..
kubescape       9m17s       Warning   FailedScheduling       pod/kubescape-exporter-29595270-4h8dd                                                    0/3 nodes are available: 1 Insufficient cpu, 1 node(s) had untolerated taint {node-role.kubernetes.io/control-plane: }, 1 node(s) had untolerated taint {node.kubernetes.io/unreachable: }. preemption: 0/3 nodes are available: 1 No preemption victims found for incoming pod, 2 Preemption is not helpful for scheduling..
kubescape       9m17s       Warning   FailedScheduling       pod/kubescape-exporter-29595275-zx5c5                                                    0/3 nodes are available: 1 Insufficient cpu, 1 node(s) had untolerated taint {node-role.kubernetes.io/control-plane: }, 1 node(s) had untolerated taint {node.kubernetes.io/unreachable: }. preemption: 0/3 nodes are available: 1 No preemption victims found for incoming pod, 2 Preemption is not helpful for scheduling..
kubescape       9m16s       Warning   FailedScheduling       pod/kubescape-exporter-29595280-xjtwt                                                    0/3 nodes are available: 1 Insufficient cpu, 1 node(s) had untolerated taint {node-role.kubernetes.io/control-plane: }, 1 node(s) had untolerated taint {node.kubernetes.io/unreachable: }. preemption: 0/3 nodes are available: 1 No preemption victims found for incoming pod, 2 Preemption is not helpful for scheduling..
kubescape       9m17s       Warning   FailedScheduling       pod/kubescape-exporter-29595285-4zwmg                                                    0/3 nodes are available: 1 Insufficient cpu, 1 node(s) had untolerated taint {node-role.kubernetes.io/control-plane: }, 1 node(s) had untolerated taint {node.kubernetes.io/unreachable: }. preemption: 0/3 nodes are available: 1 No preemption victims found for incoming pod, 2 Preemption is not helpful for scheduling..
kubescape       9m17s       Warning   FailedScheduling       pod/kubescape-exporter-29595290-nvtn9                                                    0/3 nodes are available: 1 Insufficient cpu, 1 node(s) had untolerated taint {node-role.kubernetes.io/control-plane: }, 1 node(s) had untolerated taint {node.kubernetes.io/unreachable: }. preemption: 0/3 nodes are available: 1 No preemption victims found for incoming pod, 2 Preemption is not helpful for scheduling..
kubescape       9m17s       Warning   FailedScheduling       pod/kubescape-exporter-29595295-bvd5d                                                    0/3 nodes are available: 1 Insufficient cpu, 1 node(s) had untolerated taint {node-role.kubernetes.io/control-plane: }, 1 node(s) had untolerated taint {node.kubernetes.io/unreachable: }. preemption: 0/3 nodes are available: 1 No preemption victims found for incoming pod, 2 Preemption is not helpful for scheduling..
kubescape       9m17s       Warning   FailedScheduling       pod/kubescape-exporter-29595300-j5gk4                                                    0/3 nodes are available: 1 Insufficient cpu, 1 node(s) had untolerated taint {node-role.kubernetes.io/control-plane: }, 1 node(s) had untolerated taint {node.kubernetes.io/unreachable: }. preemption: 0/3 nodes are available: 1 No preemption victims found for incoming pod, 2 Preemption is not helpful for scheduling..
kubescape       9m17s       Warning   FailedScheduling       pod/kubescape-exporter-29595305-mjxlp                                                    0/3 nodes are available: 1 Insufficient cpu, 1 node(s) had untolerated taint {node-role.kubernetes.io/control-plane: }, 1 node(s) had untolerated taint {node.kubernetes.io/unreachable: }. preemption: 0/3 nodes are available: 1 No preemption victims found for incoming pod, 2 Preemption is not helpful for scheduling..
kubescape       9m17s       Warning   FailedScheduling       pod/kubescape-exporter-29595310-g6cx6                                                    0/3 nodes are available: 1 Insufficient cpu, 1 node(s) had untolerated taint {node-role.kubernetes.io/control-plane: }, 1 node(s) had untolerated taint {node.kubernetes.io/unreachable: }. preemption: 0/3 nodes are available: 1 No preemption victims found for incoming pod, 2 Preemption is not helpful for scheduling..
kubescape       9m17s       Warning   FailedScheduling       pod/kubescape-exporter-29595315-nhwh6                                                    0/3 nodes are available: 1 Insufficient cpu, 1 node(s) had untolerated taint {node-role.kubernetes.io/control-plane: }, 1 node(s) had untolerated taint {node.kubernetes.io/unreachable: }. preemption: 0/3 nodes are available: 1 No preemption victims found for incoming pod, 2 Preemption is not helpful for scheduling..
kubescape       9m17s       Warning   FailedScheduling       pod/kubescape-exporter-29595320-hzjkr                                                    0/3 nodes are available: 1 Insufficient cpu, 1 node(s) had untolerated taint {node-role.kubernetes.io/control-plane: }, 1 node(s) had untolerated taint {node.kubernetes.io/unreachable: }. preemption: 0/3 nodes are available: 1 No preemption victims found for incoming pod, 2 Preemption is not helpful for scheduling..
kubescape       9m17s       Warning   FailedScheduling       pod/kubescape-exporter-29595325-jgqgt                                                    0/3 nodes are available: 1 Insufficient cpu, 1 node(s) had untolerated taint {node-role.kubernetes.io/control-plane: }, 1 node(s) had untolerated taint {node.kubernetes.io/unreachable: }. preemption: 0/3 nodes are available: 1 No preemption victims found for incoming pod, 2 Preemption is not helpful for scheduling..
kubescape       9m17s       Warning   FailedScheduling       pod/kubescape-exporter-29595330-d55xf                                                    0/3 nodes are available: 1 Insufficient cpu, 1 node(s) had untolerated taint {node-role.kubernetes.io/control-plane: }, 1 node(s) had untolerated taint {node.kubernetes.io/unreachable: }. preemption: 0/3 nodes are available: 1 No preemption victims found for incoming pod, 2 Preemption is not helpful for scheduling..
kubescape       9m17s       Warning   FailedScheduling       pod/kubescape-exporter-29595335-swqz4                                                    0/3 nodes are available: 1 Insufficient cpu, 1 node(s) had untolerated taint {node-role.kubernetes.io/control-plane: }, 1 node(s) had untolerated taint {node.kubernetes.io/unreachable: }. preemption: 0/3 nodes are available: 1 No preemption victims found for incoming pod, 2 Preemption is not helpful for scheduling..
kubescape       9m17s       Warning   FailedScheduling       pod/kubescape-exporter-29595340-rwrcm                                                    0/3 nodes are available: 1 Insufficient cpu, 1 node(s) had untolerated taint {node-role.kubernetes.io/control-plane: }, 1 node(s) had untolerated taint {node.kubernetes.io/unreachable: }. preemption: 0/3 nodes are available: 1 No preemption victims found for incoming pod, 2 Preemption is not helpful for scheduling..
kubescape       9m17s       Warning   FailedScheduling       pod/kubescape-exporter-29595345-kp7d7                                                    0/3 nodes are available: 1 Insufficient cpu, 1 node(s) had untolerated taint {node-role.kubernetes.io/control-plane: }, 1 node(s) had untolerated taint {node.kubernetes.io/unreachable: }. preemption: 0/3 nodes are available: 1 No preemption victims found for incoming pod, 2 Preemption is not helpful for scheduling..
kubescape       9m17s       Warning   FailedScheduling       pod/kubescape-exporter-29595350-wqpcj                                                    0/3 nodes are available: 1 Insufficient cpu, 1 node(s) had untolerated taint {node-role.kubernetes.io/control-plane: }, 1 node(s) had untolerated taint {node.kubernetes.io/unreachable: }. preemption: 0/3 nodes are available: 1 No preemption victims found for incoming pod, 2 Preemption is not helpful for scheduling..
kubescape       9m17s       Warning   FailedScheduling       pod/kubescape-exporter-29595355-m2rdp                                                    0/3 nodes are available: 1 Insufficient cpu, 1 node(s) had untolerated taint {node-role.kubernetes.io/control-plane: }, 1 node(s) had untolerated taint {node.kubernetes.io/unreachable: }. preemption: 0/3 nodes are available: 1 No preemption victims found for incoming pod, 2 Preemption is not helpful for scheduling..
kubescape       9m17s       Warning   FailedScheduling       pod/kubescape-exporter-29595360-bktth                                                    0/3 nodes are available: 1 Insufficient cpu, 1 node(s) had untolerated taint {node-role.kubernetes.io/control-plane: }, 1 node(s) had untolerated taint {node.kubernetes.io/unreachable: }. preemption: 0/3 nodes are available: 1 No preemption victims found for incoming pod, 2 Preemption is not helpful for scheduling..
kubescape       9m17s       Warning   FailedScheduling       pod/kubescape-exporter-29595365-8ngmq                                                    0/3 nodes are available: 1 Insufficient cpu, 1 node(s) had untolerated taint {node-role.kubernetes.io/control-plane: }, 1 node(s) had untolerated taint {node.kubernetes.io/unreachable: }. preemption: 0/3 nodes are available: 1 No preemption victims found for incoming pod, 2 Preemption is not helpful for scheduling..
kubescape       9m17s       Warning   FailedScheduling       pod/kubescape-exporter-29595370-q4h7q                                                    0/3 nodes are available: 1 Insufficient cpu, 1 node(s) had untolerated taint {node-role.kubernetes.io/control-plane: }, 1 node(s) had untolerated taint {node.kubernetes.io/unreachable: }. preemption: 0/3 nodes are available: 1 No preemption victims found for incoming pod, 2 Preemption is not helpful for scheduling..
kubescape       9m17s       Warning   FailedScheduling       pod/kubescape-exporter-29595375-sz28g                                                    0/3 nodes are available: 1 Insufficient cpu, 1 node(s) had untolerated taint {node-role.kubernetes.io/control-plane: }, 1 node(s) had untolerated taint {node.kubernetes.io/unreachable: }. preemption: 0/3 nodes are available: 1 No preemption victims found for incoming pod, 2 Preemption is not helpful for scheduling..
kubescape       9m17s       Warning   FailedScheduling       pod/kubescape-exporter-29595380-sswwd                                                    0/3 nodes are available: 1 Insufficient cpu, 1 node(s) had untolerated taint {node-role.kubernetes.io/control-plane: }, 1 node(s) had untolerated taint {node.kubernetes.io/unreachable: }. preemption: 0/3 nodes are available: 1 No preemption victims found for incoming pod, 2 Preemption is not helpful for scheduling..
kubescape       9m17s       Warning   FailedScheduling       pod/kubescape-exporter-29595385-lsb4p                                                    0/3 nodes are available: 1 Insufficient cpu, 1 node(s) had untolerated taint {node-role.kubernetes.io/control-plane: }, 1 node(s) had untolerated taint {node.kubernetes.io/unreachable: }. preemption: 0/3 nodes are available: 1 No preemption victims found for incoming pod, 2 Preemption is not helpful for scheduling..
kubescape       9m16s       Warning   FailedScheduling       pod/kubescape-exporter-29594775-l2wvd                                                    0/3 nodes are available: 1 Insufficient cpu, 1 node(s) had untolerated taint {node-role.kubernetes.io/control-plane: }, 1 node(s) had untolerated taint {node.kubernetes.io/unreachable: }. preemption: 0/3 nodes are available: 1 No preemption victims found for incoming pod, 2 Preemption is not helpful for scheduling..
free5gc         9m16s       Warning   FailedScheduling       pod/free5gc-free5gc-nssf-nssf-5c6c8779bf-zqhhd                                           0/3 nodes are available: 1 Insufficient cpu, 1 node(s) had untolerated taint {node-role.kubernetes.io/control-plane: }, 1 node(s) had untolerated taint {node.kubernetes.io/unreachable: }. preemption: 0/3 nodes are available: 1 No preemption victims found for incoming pod, 2 Preemption is not helpful for scheduling..
kubescape       9m16s       Warning   FailedScheduling       pod/kubescape-exporter-29595695-6cktw                                                    0/3 nodes are available: 1 Insufficient cpu, 1 node(s) had untolerated taint {node-role.kubernetes.io/control-plane: }, 1 node(s) had untolerated taint {node.kubernetes.io/unreachable: }. preemption: 0/3 nodes are available: 1 No preemption victims found for incoming pod, 2 Preemption is not helpful for scheduling..
kubescape       9m17s       Warning   FailedScheduling       pod/kubescape-exporter-29595405-5lfsb                                                    0/3 nodes are available: 1 Insufficient cpu, 1 node(s) had untolerated taint {node-role.kubernetes.io/control-plane: }, 1 node(s) had untolerated taint {node.kubernetes.io/unreachable: }. preemption: 0/3 nodes are available: 1 No preemption victims found for incoming pod, 2 Preemption is not helpful for scheduling..
kubescape       9m17s       Warning   FailedScheduling       pod/kubescape-exporter-29595410-r2mwn                                                    0/3 nodes are available: 1 Insufficient cpu, 1 node(s) had untolerated taint {node-role.kubernetes.io/control-plane: }, 1 node(s) had untolerated taint {node.kubernetes.io/unreachable: }. preemption: 0/3 nodes are available: 1 No preemption victims found for incoming pod, 2 Preemption is not helpful for scheduling..
kubescape       9m17s       Warning   FailedScheduling       pod/kubescape-exporter-29595415-f9j44                                                    0/3 nodes are available: 1 Insufficient cpu, 1 node(s) had untolerated taint {node-role.kubernetes.io/control-plane: }, 1 node(s) had untolerated taint {node.kubernetes.io/unreachable: }. preemption: 0/3 nodes are available: 1 No preemption victims found for incoming pod, 2 Preemption is not helpful for scheduling..
kubescape       9m17s       Warning   FailedScheduling       pod/kubescape-exporter-29595420-26dsf                                                    0/3 nodes are available: 1 Insufficient cpu, 1 node(s) had untolerated taint {node-role.kubernetes.io/control-plane: }, 1 node(s) had untolerated taint {node.kubernetes.io/unreachable: }. preemption: 0/3 nodes are available: 1 No preemption victims found for incoming pod, 2 Preemption is not helpful for scheduling..
kubescape       9m17s       Warning   FailedScheduling       pod/kubescape-exporter-29595425-22gcz                                                    0/3 nodes are available: 1 Insufficient cpu, 1 node(s) had untolerated taint {node-role.kubernetes.io/control-plane: }, 1 node(s) had untolerated taint {node.kubernetes.io/unreachable: }. preemption: 0/3 nodes are available: 1 No preemption victims found for incoming pod, 2 Preemption is not helpful for scheduling..
kubescape       9m17s       Warning   FailedScheduling       pod/kubescape-exporter-29595430-2pwzz                                                    0/3 nodes are available: 1 Insufficient cpu, 1 node(s) had untolerated taint {node-role.kubernetes.io/control-plane: }, 1 node(s) had untolerated taint {node.kubernetes.io/unreachable: }. preemption: 0/3 nodes are available: 1 No preemption victims found for incoming pod, 2 Preemption is not helpful for scheduling..
kubescape       9m17s       Warning   FailedScheduling       pod/kubescape-exporter-29595435-t4x25                                                    0/3 nodes are available: 1 Insufficient cpu, 1 node(s) had untolerated taint {node-role.kubernetes.io/control-plane: }, 1 node(s) had untolerated taint {node.kubernetes.io/unreachable: }. preemption: 0/3 nodes are available: 1 No preemption victims found for incoming pod, 2 Preemption is not helpful for scheduling..
kubescape       9m17s       Warning   FailedScheduling       pod/kubescape-exporter-29595440-xmnlk                                                    0/3 nodes are available: 1 Insufficient cpu, 1 node(s) had untolerated taint {node-role.kubernetes.io/control-plane: }, 1 node(s) had untolerated taint {node.kubernetes.io/unreachable: }. preemption: 0/3 nodes are available: 1 No preemption victims found for incoming pod, 2 Preemption is not helpful for scheduling..
kubescape       9m17s       Warning   FailedScheduling       pod/kubescape-exporter-29595445-tqgkb                                                    0/3 nodes are available: 1 Insufficient cpu, 1 node(s) had untolerated taint {node-role.kubernetes.io/control-plane: }, 1 node(s) had untolerated taint {node.kubernetes.io/unreachable: }. preemption: 0/3 nodes are available: 1 No preemption victims found for incoming pod, 2 Preemption is not helpful for scheduling..
kubescape       9m17s       Warning   FailedScheduling       pod/kubescape-exporter-29595450-qqmpk                                                    0/3 nodes are available: 1 Insufficient cpu, 1 node(s) had untolerated taint {node-role.kubernetes.io/control-plane: }, 1 node(s) had untolerated taint {node.kubernetes.io/unreachable: }. preemption: 0/3 nodes are available: 1 No preemption victims found for incoming pod, 2 Preemption is not helpful for scheduling..
kubescape       9m17s       Warning   FailedScheduling       pod/kubescape-exporter-29595455-4lmh7                                                    0/3 nodes are available: 1 Insufficient cpu, 1 node(s) had untolerated taint {node-role.kubernetes.io/control-plane: }, 1 node(s) had untolerated taint {node.kubernetes.io/unreachable: }. preemption: 0/3 nodes are available: 1 No preemption victims found for incoming pod, 2 Preemption is not helpful for scheduling..
kubescape       9m17s       Warning   FailedScheduling       pod/kubescape-exporter-29595460-5m2wd                                                    0/3 nodes are available: 1 Insufficient cpu, 1 node(s) had untolerated taint {node-role.kubernetes.io/control-plane: }, 1 node(s) had untolerated taint {node.kubernetes.io/unreachable: }. preemption: 0/3 nodes are available: 1 No preemption victims found for incoming pod, 2 Preemption is not helpful for scheduling..
kubescape       9m17s       Warning   FailedScheduling       pod/kubescape-exporter-29595395-b9n77                                                    0/3 nodes are available: 1 Insufficient cpu, 1 node(s) had untolerated taint {node-role.kubernetes.io/control-plane: }, 1 node(s) had untolerated taint {node.kubernetes.io/unreachable: }. preemption: 0/3 nodes are available: 1 No preemption victims found for incoming pod, 2 Preemption is not helpful for scheduling..
kubescape       9m17s       Warning   FailedScheduling       pod/kubescape-exporter-29595470-fgt7v                                                    0/3 nodes are available: 1 Insufficient cpu, 1 node(s) had untolerated taint {node-role.kubernetes.io/control-plane: }, 1 node(s) had untolerated taint {node.kubernetes.io/unreachable: }. preemption: 0/3 nodes are available: 1 No preemption victims found for incoming pod, 2 Preemption is not helpful for scheduling..
kubescape       9m17s       Warning   FailedScheduling       pod/kubescape-exporter-29595475-ftbc9                                                    0/3 nodes are available: 1 Insufficient cpu, 1 node(s) had untolerated taint {node-role.kubernetes.io/control-plane: }, 1 node(s) had untolerated taint {node.kubernetes.io/unreachable: }. preemption: 0/3 nodes are available: 1 No preemption victims found for incoming pod, 2 Preemption is not helpful for scheduling..
kubescape       9m17s       Warning   FailedScheduling       pod/kubescape-exporter-29595480-55zbk                                                    0/3 nodes are available: 1 Insufficient cpu, 1 node(s) had untolerated taint {node-role.kubernetes.io/control-plane: }, 1 node(s) had untolerated taint {node.kubernetes.io/unreachable: }. preemption: 0/3 nodes are available: 1 No preemption victims found for incoming pod, 2 Preemption is not helpful for scheduling..
kubescape       9m17s       Warning   FailedScheduling       pod/kubescape-exporter-29595485-9vgf5                                                    0/3 nodes are available: 1 Insufficient cpu, 1 node(s) had untolerated taint {node-role.kubernetes.io/control-plane: }, 1 node(s) had untolerated taint {node.kubernetes.io/unreachable: }. preemption: 0/3 nodes are available: 1 No preemption victims found for incoming pod, 2 Preemption is not helpful for scheduling..
kubescape       9m17s       Warning   FailedScheduling       pod/kubescape-exporter-29595490-g4gj9                                                    0/3 nodes are available: 1 Insufficient cpu, 1 node(s) had untolerated taint {node-role.kubernetes.io/control-plane: }, 1 node(s) had untolerated taint {node.kubernetes.io/unreachable: }. preemption: 0/3 nodes are available: 1 No preemption victims found for incoming pod, 2 Preemption is not helpful for scheduling..
kubescape       9m17s       Warning   FailedScheduling       pod/kubescape-exporter-29595495-xrq9c                                                    0/3 nodes are available: 1 Insufficient cpu, 1 node(s) had untolerated taint {node-role.kubernetes.io/control-plane: }, 1 node(s) had untolerated taint {node.kubernetes.io/unreachable: }. preemption: 0/3 nodes are available: 1 No preemption victims found for incoming pod, 2 Preemption is not helpful for scheduling..
kubescape       9m17s       Warning   FailedScheduling       pod/kubescape-exporter-29595500-trvxk                                                    0/3 nodes are available: 1 Insufficient cpu, 1 node(s) had untolerated taint {node-role.kubernetes.io/control-plane: }, 1 node(s) had untolerated taint {node.kubernetes.io/unreachable: }. preemption: 0/3 nodes are available: 1 No preemption victims found for incoming pod, 2 Preemption is not helpful for scheduling..
kubescape       9m17s       Warning   FailedScheduling       pod/kubescape-exporter-29595505-7pgbm                                                    0/3 nodes are available: 1 Insufficient cpu, 1 node(s) had untolerated taint {node-role.kubernetes.io/control-plane: }, 1 node(s) had untolerated taint {node.kubernetes.io/unreachable: }. preemption: 0/3 nodes are available: 1 No preemption victims found for incoming pod, 2 Preemption is not helpful for scheduling..
kubescape       9m17s       Warning   FailedScheduling       pod/kubescape-exporter-29595510-vbxwt                                                    0/3 nodes are available: 1 Insufficient cpu, 1 node(s) had untolerated taint {node-role.kubernetes.io/control-plane: }, 1 node(s) had untolerated taint {node.kubernetes.io/unreachable: }. preemption: 0/3 nodes are available: 1 No preemption victims found for incoming pod, 2 Preemption is not helpful for scheduling..
kubescape       9m17s       Warning   FailedScheduling       pod/kubescape-exporter-29595515-s5xr9                                                    0/3 nodes are available: 1 Insufficient cpu, 1 node(s) had untolerated taint {node-role.kubernetes.io/control-plane: }, 1 node(s) had untolerated taint {node.kubernetes.io/unreachable: }. preemption: 0/3 nodes are available: 1 No preemption victims found for incoming pod, 2 Preemption is not helpful for scheduling..
kubescape       9m17s       Warning   FailedScheduling       pod/kubescape-exporter-29595520-rtkfw                                                    0/3 nodes are available: 1 Insufficient cpu, 1 node(s) had untolerated taint {node-role.kubernetes.io/control-plane: }, 1 node(s) had untolerated taint {node.kubernetes.io/unreachable: }. preemption: 0/3 nodes are available: 1 No preemption victims found for incoming pod, 2 Preemption is not helpful for scheduling..
kubescape       9m17s       Warning   FailedScheduling       pod/kubescape-exporter-29595525-f89c5                                                    0/3 nodes are available: 1 Insufficient cpu, 1 node(s) had untolerated taint {node-role.kubernetes.io/control-plane: }, 1 node(s) had untolerated taint {node.kubernetes.io/unreachable: }. preemption: 0/3 nodes are available: 1 No preemption victims found for incoming pod, 2 Preemption is not helpful for scheduling..
kubescape       9m17s       Warning   FailedScheduling       pod/kubescape-exporter-29595530-w95qj                                                    0/3 nodes are available: 1 Insufficient cpu, 1 node(s) had untolerated taint {node-role.kubernetes.io/control-plane: }, 1 node(s) had untolerated taint {node.kubernetes.io/unreachable: }. preemption: 0/3 nodes are available: 1 No preemption victims found for incoming pod, 2 Preemption is not helpful for scheduling..
kubescape       9m17s       Warning   FailedScheduling       pod/kubescape-exporter-29595535-5lwzq                                                    0/3 nodes are available: 1 Insufficient cpu, 1 node(s) had untolerated taint {node-role.kubernetes.io/control-plane: }, 1 node(s) had untolerated taint {node.kubernetes.io/unreachable: }. preemption: 0/3 nodes are available: 1 No preemption victims found for incoming pod, 2 Preemption is not helpful for scheduling..
kubescape       9m17s       Warning   FailedScheduling       pod/kubescape-exporter-29595540-szpzz                                                    0/3 nodes are available: 1 Insufficient cpu, 1 node(s) had untolerated taint {node-role.kubernetes.io/control-plane: }, 1 node(s) had untolerated taint {node.kubernetes.io/unreachable: }. preemption: 0/3 nodes are available: 1 No preemption victims found for incoming pod, 2 Preemption is not helpful for scheduling..
kubescape       9m17s       Warning   FailedScheduling       pod/kubescape-exporter-29595545-wn2np                                                    0/3 nodes are available: 1 Insufficient cpu, 1 node(s) had untolerated taint {node-role.kubernetes.io/control-plane: }, 1 node(s) had untolerated taint {node.kubernetes.io/unreachable: }. preemption: 0/3 nodes are available: 1 No preemption victims found for incoming pod, 2 Preemption is not helpful for scheduling..
kubescape       9m16s       Warning   FailedScheduling       pod/kubescape-exporter-29595550-lqxb2                                                    0/3 nodes are available: 1 Insufficient cpu, 1 node(s) had untolerated taint {node-role.kubernetes.io/control-plane: }, 1 node(s) had untolerated taint {node.kubernetes.io/unreachable: }. preemption: 0/3 nodes are available: 1 No preemption victims found for incoming pod, 2 Preemption is not helpful for scheduling..
kubescape       9m16s       Warning   FailedScheduling       pod/kubescape-exporter-29595555-phtdn                                                    0/3 nodes are available: 1 Insufficient cpu, 1 node(s) had untolerated taint {node-role.kubernetes.io/control-plane: }, 1 node(s) had untolerated taint {node.kubernetes.io/unreachable: }. preemption: 0/3 nodes are available: 1 No preemption victims found for incoming pod, 2 Preemption is not helpful for scheduling..
kubescape       9m16s       Warning   FailedScheduling       pod/kubescape-exporter-29595560-lgbjc                                                    0/3 nodes are available: 1 Insufficient cpu, 1 node(s) had untolerated taint {node-role.kubernetes.io/control-plane: }, 1 node(s) had untolerated taint {node.kubernetes.io/unreachable: }. preemption: 0/3 nodes are available: 1 No preemption victims found for incoming pod, 2 Preemption is not helpful for scheduling..
kubescape       9m16s       Warning   FailedScheduling       pod/kubescape-exporter-29595565-pfwpr                                                    0/3 nodes are available: 1 Insufficient cpu, 1 node(s) had untolerated taint {node-role.kubernetes.io/control-plane: }, 1 node(s) had untolerated taint {node.kubernetes.io/unreachable: }. preemption: 0/3 nodes are available: 1 No preemption victims found for incoming pod, 2 Preemption is not helpful for scheduling..
kubescape       9m16s       Warning   FailedScheduling       pod/kubescape-exporter-29595570-rcfq6                                                    0/3 nodes are available: 1 Insufficient cpu, 1 node(s) had untolerated taint {node-role.kubernetes.io/control-plane: }, 1 node(s) had untolerated taint {node.kubernetes.io/unreachable: }. preemption: 0/3 nodes are available: 1 No preemption victims found for incoming pod, 2 Preemption is not helpful for scheduling..
kubescape       9m16s       Warning   FailedScheduling       pod/kubescape-exporter-29595575-p2z8n                                                    0/3 nodes are available: 1 Insufficient cpu, 1 node(s) had untolerated taint {node-role.kubernetes.io/control-plane: }, 1 node(s) had untolerated taint {node.kubernetes.io/unreachable: }. preemption: 0/3 nodes are available: 1 No preemption victims found for incoming pod, 2 Preemption is not helpful for scheduling..
kubescape       9m16s       Warning   FailedScheduling       pod/kubescape-exporter-29595580-8scpr                                                    0/3 nodes are available: 1 Insufficient cpu, 1 node(s) had untolerated taint {node-role.kubernetes.io/control-plane: }, 1 node(s) had untolerated taint {node.kubernetes.io/unreachable: }. preemption: 0/3 nodes are available: 1 No preemption victims found for incoming pod, 2 Preemption is not helpful for scheduling..
kubescape       9m16s       Warning   FailedScheduling       pod/kubescape-exporter-29595585-cjv6b                                                    0/3 nodes are available: 1 Insufficient cpu, 1 node(s) had untolerated taint {node-role.kubernetes.io/control-plane: }, 1 node(s) had untolerated taint {node.kubernetes.io/unreachable: }. preemption: 0/3 nodes are available: 1 No preemption victims found for incoming pod, 2 Preemption is not helpful for scheduling..
kubescape       9m16s       Warning   FailedScheduling       pod/kubescape-exporter-29595590-2h675                                                    0/3 nodes are available: 1 Insufficient cpu, 1 node(s) had untolerated taint {node-role.kubernetes.io/control-plane: }, 1 node(s) had untolerated taint {node.kubernetes.io/unreachable: }. preemption: 0/3 nodes are available: 1 No preemption victims found for incoming pod, 2 Preemption is not helpful for scheduling..
kubescape       9m16s       Warning   FailedScheduling       pod/kubescape-exporter-29595595-fffnf                                                    0/3 nodes are available: 1 Insufficient cpu, 1 node(s) had untolerated taint {node-role.kubernetes.io/control-plane: }, 1 node(s) had untolerated taint {node.kubernetes.io/unreachable: }. preemption: 0/3 nodes are available: 1 No preemption victims found for incoming pod, 2 Preemption is not helpful for scheduling..
kubescape       9m16s       Warning   FailedScheduling       pod/kubescape-exporter-29595600-mbllv                                                    0/3 nodes are available: 1 Insufficient cpu, 1 node(s) had untolerated taint {node-role.kubernetes.io/control-plane: }, 1 node(s) had untolerated taint {node.kubernetes.io/unreachable: }. preemption: 0/3 nodes are available: 1 No preemption victims found for incoming pod, 2 Preemption is not helpful for scheduling..
kubescape       9m16s       Warning   FailedScheduling       pod/kubescape-exporter-29595605-7rg57                                                    0/3 nodes are available: 1 Insufficient cpu, 1 node(s) had untolerated taint {node-role.kubernetes.io/control-plane: }, 1 node(s) had untolerated taint {node.kubernetes.io/unreachable: }. preemption: 0/3 nodes are available: 1 No preemption victims found for incoming pod, 2 Preemption is not helpful for scheduling..
kubescape       9m16s       Warning   FailedScheduling       pod/kubescape-exporter-29595610-7sdfw                                                    0/3 nodes are available: 1 Insufficient cpu, 1 node(s) had untolerated taint {node-role.kubernetes.io/control-plane: }, 1 node(s) had untolerated taint {node.kubernetes.io/unreachable: }. preemption: 0/3 nodes are available: 1 No preemption victims found for incoming pod, 2 Preemption is not helpful for scheduling..
kubescape       9m16s       Warning   FailedScheduling       pod/kubescape-exporter-29595615-hscf5                                                    0/3 nodes are available: 1 Insufficient cpu, 1 node(s) had untolerated taint {node-role.kubernetes.io/control-plane: }, 1 node(s) had untolerated taint {node.kubernetes.io/unreachable: }. preemption: 0/3 nodes are available: 1 No preemption victims found for incoming pod, 2 Preemption is not helpful for scheduling..
kubescape       9m16s       Warning   FailedScheduling       pod/kubescape-exporter-29595620-qzncc                                                    0/3 nodes are available: 1 Insufficient cpu, 1 node(s) had untolerated taint {node-role.kubernetes.io/control-plane: }, 1 node(s) had untolerated taint {node.kubernetes.io/unreachable: }. preemption: 0/3 nodes are available: 1 No preemption victims found for incoming pod, 2 Preemption is not helpful for scheduling..
kubescape       9m16s       Warning   FailedScheduling       pod/kubescape-exporter-29595625-6hcrx                                                    0/3 nodes are available: 1 Insufficient cpu, 1 node(s) had untolerated taint {node-role.kubernetes.io/control-plane: }, 1 node(s) had untolerated taint {node.kubernetes.io/unreachable: }. preemption: 0/3 nodes are available: 1 No preemption victims found for incoming pod, 2 Preemption is not helpful for scheduling..
kubescape       9m16s       Warning   FailedScheduling       pod/kubescape-exporter-29595630-b7tzg                                                    0/3 nodes are available: 1 Insufficient cpu, 1 node(s) had untolerated taint {node-role.kubernetes.io/control-plane: }, 1 node(s) had untolerated taint {node.kubernetes.io/unreachable: }. preemption: 0/3 nodes are available: 1 No preemption victims found for incoming pod, 2 Preemption is not helpful for scheduling..
kubescape       9m16s       Warning   FailedScheduling       pod/kubescape-exporter-29595635-66d84                                                    0/3 nodes are available: 1 Insufficient cpu, 1 node(s) had untolerated taint {node-role.kubernetes.io/control-plane: }, 1 node(s) had untolerated taint {node.kubernetes.io/unreachable: }. preemption: 0/3 nodes are available: 1 No preemption victims found for incoming pod, 2 Preemption is not helpful for scheduling..
kubescape       9m16s       Warning   FailedScheduling       pod/kubescape-exporter-29595640-t7s74                                                    0/3 nodes are available: 1 Insufficient cpu, 1 node(s) had untolerated taint {node-role.kubernetes.io/control-plane: }, 1 node(s) had untolerated taint {node.kubernetes.io/unreachable: }. preemption: 0/3 nodes are available: 1 No preemption victims found for incoming pod, 2 Preemption is not helpful for scheduling..
kubescape       9m16s       Warning   FailedScheduling       pod/kubescape-exporter-29595645-n5cmp                                                    0/3 nodes are available: 1 Insufficient cpu, 1 node(s) had untolerated taint {node-role.kubernetes.io/control-plane: }, 1 node(s) had untolerated taint {node.kubernetes.io/unreachable: }. preemption: 0/3 nodes are available: 1 No preemption victims found for incoming pod, 2 Preemption is not helpful for scheduling..
kubescape       9m16s       Warning   FailedScheduling       pod/kubescape-exporter-29595650-9gl5p                                                    0/3 nodes are available: 1 Insufficient cpu, 1 node(s) had untolerated taint {node-role.kubernetes.io/control-plane: }, 1 node(s) had untolerated taint {node.kubernetes.io/unreachable: }. preemption: 0/3 nodes are available: 1 No preemption victims found for incoming pod, 2 Preemption is not helpful for scheduling..
kubescape       9m16s       Warning   FailedScheduling       pod/kubescape-exporter-29595655-twr2h                                                    0/3 nodes are available: 1 Insufficient cpu, 1 node(s) had untolerated taint {node-role.kubernetes.io/control-plane: }, 1 node(s) had untolerated taint {node.kubernetes.io/unreachable: }. preemption: 0/3 nodes are available: 1 No preemption victims found for incoming pod, 2 Preemption is not helpful for scheduling..
kubescape       9m16s       Warning   FailedScheduling       pod/kubescape-exporter-29595660-4l6w8                                                    0/3 nodes are available: 1 Insufficient cpu, 1 node(s) had untolerated taint {node-role.kubernetes.io/control-plane: }, 1 node(s) had untolerated taint {node.kubernetes.io/unreachable: }. preemption: 0/3 nodes are available: 1 No preemption victims found for incoming pod, 2 Preemption is not helpful for scheduling..
kubescape       9m16s       Warning   FailedScheduling       pod/kubescape-exporter-29595665-s2dkp                                                    0/3 nodes are available: 1 Insufficient cpu, 1 node(s) had untolerated taint {node-role.kubernetes.io/control-plane: }, 1 node(s) had untolerated taint {node.kubernetes.io/unreachable: }. preemption: 0/3 nodes are available: 1 No preemption victims found for incoming pod, 2 Preemption is not helpful for scheduling..
kubescape       9m16s       Warning   FailedScheduling       pod/kubescape-exporter-29595670-2lqfz                                                    0/3 nodes are available: 1 Insufficient cpu, 1 node(s) had untolerated taint {node-role.kubernetes.io/control-plane: }, 1 node(s) had untolerated taint {node.kubernetes.io/unreachable: }. preemption: 0/3 nodes are available: 1 No preemption victims found for incoming pod, 2 Preemption is not helpful for scheduling..
kubescape       9m16s       Warning   FailedScheduling       pod/kubescape-exporter-29595675-5p2jm                                                    0/3 nodes are available: 1 Insufficient cpu, 1 node(s) had untolerated taint {node-role.kubernetes.io/control-plane: }, 1 node(s) had untolerated taint {node.kubernetes.io/unreachable: }. preemption: 0/3 nodes are available: 1 No preemption victims found for incoming pod, 2 Preemption is not helpful for scheduling..
kubescape       9m16s       Warning   FailedScheduling       pod/kubescape-exporter-29595680-nzz4c                                                    0/3 nodes are available: 1 Insufficient cpu, 1 node(s) had untolerated taint {node-role.kubernetes.io/control-plane: }, 1 node(s) had untolerated taint {node.kubernetes.io/unreachable: }. preemption: 0/3 nodes are available: 1 No preemption victims found for incoming pod, 2 Preemption is not helpful for scheduling..
kubescape       9m16s       Warning   FailedScheduling       pod/kubescape-exporter-29595685-hm2q6                                                    0/3 nodes are available: 1 Insufficient cpu, 1 node(s) had untolerated taint {node-role.kubernetes.io/control-plane: }, 1 node(s) had untolerated taint {node.kubernetes.io/unreachable: }. preemption: 0/3 nodes are available: 1 No preemption victims found for incoming pod, 2 Preemption is not helpful for scheduling..
kubescape       9m16s       Warning   FailedScheduling       pod/kubescape-exporter-29595690-dgs9j                                                    0/3 nodes are available: 1 Insufficient cpu, 1 node(s) had untolerated taint {node-role.kubernetes.io/control-plane: }, 1 node(s) had untolerated taint {node.kubernetes.io/unreachable: }. preemption: 0/3 nodes are available: 1 No preemption victims found for incoming pod, 2 Preemption is not helpful for scheduling..
kubescape       9m17s       Warning   FailedScheduling       pod/kubescape-exporter-29595400-mfdgf                                                    0/3 nodes are available: 1 Insufficient cpu, 1 node(s) had untolerated taint {node-role.kubernetes.io/control-plane: }, 1 node(s) had untolerated taint {node.kubernetes.io/unreachable: }. preemption: 0/3 nodes are available: 1 No preemption victims found for incoming pod, 2 Preemption is not helpful for scheduling..
kubescape       9m16s       Warning   FailedScheduling       pod/kubescape-exporter-29595700-8vqvk                                                    0/3 nodes are available: 1 Insufficient cpu, 1 node(s) had untolerated taint {node-role.kubernetes.io/control-plane: }, 1 node(s) had untolerated taint {node.kubernetes.io/unreachable: }. preemption: 0/3 nodes are available: 1 No preemption victims found for incoming pod, 2 Preemption is not helpful for scheduling..
kubescape       9m16s       Warning   FailedScheduling       pod/kubescape-exporter-29595705-sn96t                                                    0/3 nodes are available: 1 Insufficient cpu, 1 node(s) had untolerated taint {node-role.kubernetes.io/control-plane: }, 1 node(s) had untolerated taint {node.kubernetes.io/unreachable: }. preemption: 0/3 nodes are available: 1 No preemption victims found for incoming pod, 2 Preemption is not helpful for scheduling..
kubescape       9m16s       Warning   FailedScheduling       pod/kubescape-exporter-29595710-j9cgc                                                    0/3 nodes are available: 1 Insufficient cpu, 1 node(s) had untolerated taint {node-role.kubernetes.io/control-plane: }, 1 node(s) had untolerated taint {node.kubernetes.io/unreachable: }. preemption: 0/3 nodes are available: 1 No preemption victims found for incoming pod, 2 Preemption is not helpful for scheduling..
kubescape       9m16s       Warning   FailedScheduling       pod/kubescape-exporter-29595715-t8rcl                                                    0/3 nodes are available: 1 Insufficient cpu, 1 node(s) had untolerated taint {node-role.kubernetes.io/control-plane: }, 1 node(s) had untolerated taint {node.kubernetes.io/unreachable: }. preemption: 0/3 nodes are available: 1 No preemption victims found for incoming pod, 2 Preemption is not helpful for scheduling..
kubescape       57m         Warning   FailedScheduling       pod/kubescape-exporter-29595720-trg4r                                                    0/3 nodes are available: 1 Insufficient cpu, 1 node(s) had untolerated taint {node-role.kubernetes.io/control-plane: }, 1 node(s) had untolerated taint {node.kubernetes.io/unreachable: }. preemption: 0/3 nodes are available: 1 No preemption victims found for incoming pod, 2 Preemption is not helpful for scheduling..
kubescape       9m16s       Warning   FailedScheduling       pod/kubescape-exporter-29595720-trg4r                                                    0/3 nodes are available: 1 Insufficient cpu, 1 node(s) had untolerated taint {node-role.kubernetes.io/control-plane: }, 1 node(s) had untolerated taint {node.kubernetes.io/unreachable: }. preemption: 0/3 nodes are available: 1 No preemption victims found for incoming pod, 2 Preemption is not helpful for scheduling..
trivy-system    15m         Warning   FailedScheduling       pod/scan-vulnerabilityreport-7d59678b4f-x466d                                            0/3 nodes are available: 1 Insufficient cpu, 1 node(s) had untolerated taint {node-role.kubernetes.io/control-plane: }, 1 node(s) had untolerated taint {node.kubernetes.io/unreachable: }. preemption: 0/3 nodes are available: 1 No preemption victims found for incoming pod, 2 Preemption is not helpful for scheduling..
kubescape       52m         Warning   FailedScheduling       pod/kubescape-exporter-29595725-ckl8n                                                    0/3 nodes are available: 1 Insufficient cpu, 1 node(s) had untolerated taint {node-role.kubernetes.io/control-plane: }, 1 node(s) had untolerated taint {node.kubernetes.io/unreachable: }. preemption: 0/3 nodes are available: 1 No preemption victims found for incoming pod, 2 Preemption is not helpful for scheduling..
kubescape       9m16s       Warning   FailedScheduling       pod/kubescape-exporter-29595725-ckl8n                                                    0/3 nodes are available: 1 Insufficient cpu, 1 node(s) had untolerated taint {node-role.kubernetes.io/control-plane: }, 1 node(s) had untolerated taint {node.kubernetes.io/unreachable: }. preemption: 0/3 nodes are available: 1 No preemption victims found for incoming pod, 2 Preemption is not helpful for scheduling..
trivy-system    25m         Warning   FailedScheduling       pod/scan-vulnerabilityreport-7c9ddd97bf-fg65z                                            skip schedule deleting pod: trivy-system/scan-vulnerabilityreport-7c9ddd97bf-fg65z
kubescape       47m         Warning   FailedScheduling       pod/kubescape-exporter-29595730-28r7g                                                    0/3 nodes are available: 1 Insufficient cpu, 1 node(s) had untolerated taint {node-role.kubernetes.io/control-plane: }, 1 node(s) had untolerated taint {node.kubernetes.io/unreachable: }. preemption: 0/3 nodes are available: 1 No preemption victims found for incoming pod, 2 Preemption is not helpful for scheduling..
kubescape       9m16s       Warning   FailedScheduling       pod/kubescape-exporter-29595730-28r7g                                                    0/3 nodes are available: 1 Insufficient cpu, 1 node(s) had untolerated taint {node-role.kubernetes.io/control-plane: }, 1 node(s) had untolerated taint {node.kubernetes.io/unreachable: }. preemption: 0/3 nodes are available: 1 No preemption victims found for incoming pod, 2 Preemption is not helpful for scheduling..
trivy-system    29m         Warning   FailedScheduling       pod/scan-vulnerabilityreport-7c9ddd97bf-fg65z                                            0/3 nodes are available: 1 Insufficient cpu, 1 node(s) had untolerated taint {node-role.kubernetes.io/control-plane: }, 1 node(s) had untolerated taint {node.kubernetes.io/unreachable: }. preemption: 0/3 nodes are available: 1 No preemption victims found for incoming pod, 2 Preemption is not helpful for scheduling..
kubescape       42m         Warning   FailedScheduling       pod/kubescape-exporter-29595735-wbn76                                                    0/3 nodes are available: 1 Insufficient cpu, 1 node(s) had untolerated taint {node-role.kubernetes.io/control-plane: }, 1 node(s) had untolerated taint {node.kubernetes.io/unreachable: }. preemption: 0/3 nodes are available: 1 No preemption victims found for incoming pod, 2 Preemption is not helpful for scheduling..
kubescape       9m16s       Warning   FailedScheduling       pod/kubescape-exporter-29595735-wbn76                                                    0/3 nodes are available: 1 Insufficient cpu, 1 node(s) had untolerated taint {node-role.kubernetes.io/control-plane: }, 1 node(s) had untolerated taint {node.kubernetes.io/unreachable: }. preemption: 0/3 nodes are available: 1 No preemption victims found for incoming pod, 2 Preemption is not helpful for scheduling..
trivy-system    35m         Warning   FailedScheduling       pod/scan-vulnerabilityreport-7c9ddd97bf-fg65z                                            0/3 nodes are available: 1 Insufficient cpu, 1 node(s) had untolerated taint {node-role.kubernetes.io/control-plane: }, 1 node(s) had untolerated taint {node.kubernetes.io/unreachable: }. preemption: 0/3 nodes are available: 1 No preemption victims found for incoming pod, 2 Preemption is not helpful for scheduling..
kubescape       37m         Warning   FailedScheduling       pod/kubescape-exporter-29595740-2n28f                                                    0/3 nodes are available: 1 Insufficient cpu, 1 node(s) had untolerated taint {node-role.kubernetes.io/control-plane: }, 1 node(s) had untolerated taint {node.kubernetes.io/unreachable: }. preemption: 0/3 nodes are available: 1 No preemption victims found for incoming pod, 2 Preemption is not helpful for scheduling..
kubescape       9m16s       Warning   FailedScheduling       pod/kubescape-exporter-29595740-2n28f                                                    0/3 nodes are available: 1 Insufficient cpu, 1 node(s) had untolerated taint {node-role.kubernetes.io/control-plane: }, 1 node(s) had untolerated taint {node.kubernetes.io/unreachable: }. preemption: 0/3 nodes are available: 1 No preemption victims found for incoming pod, 2 Preemption is not helpful for scheduling..
trivy-system    13s         Warning   FailedScheduling       pod/scan-vulnerabilityreport-7bf46c5ff8-pfj67                                            0/3 nodes are available: 1 Insufficient cpu, 1 node(s) had untolerated taint {node-role.kubernetes.io/control-plane: }, 1 node(s) had untolerated taint {node.kubernetes.io/unreachable: }. preemption: 0/3 nodes are available: 1 No preemption victims found for incoming pod, 2 Preemption is not helpful for scheduling..
kubescape       32m         Warning   FailedScheduling       pod/kubescape-exporter-29595745-pr6js                                                    0/3 nodes are available: 1 Insufficient cpu, 1 node(s) had untolerated taint {node-role.kubernetes.io/control-plane: }, 1 node(s) had untolerated taint {node.kubernetes.io/unreachable: }. preemption: 0/3 nodes are available: 1 No preemption victims found for incoming pod, 2 Preemption is not helpful for scheduling..
kubescape       9m16s       Warning   FailedScheduling       pod/kubescape-exporter-29595745-pr6js                                                    0/3 nodes are available: 1 Insufficient cpu, 1 node(s) had untolerated taint {node-role.kubernetes.io/control-plane: }, 1 node(s) had untolerated taint {node.kubernetes.io/unreachable: }. preemption: 0/3 nodes are available: 1 No preemption victims found for incoming pod, 2 Preemption is not helpful for scheduling..
trivy-system    5m40s       Warning   FailedScheduling       pod/scan-vulnerabilityreport-7bf46c5ff8-pfj67                                            0/3 nodes are available: 1 Insufficient cpu, 1 node(s) had untolerated taint {node-role.kubernetes.io/control-plane: }, 1 node(s) had untolerated taint {node.kubernetes.io/unreachable: }. preemption: 0/3 nodes are available: 1 No preemption victims found for incoming pod, 2 Preemption is not helpful for scheduling..
kubescape       27m         Warning   FailedScheduling       pod/kubescape-exporter-29595750-l9s8r                                                    0/3 nodes are available: 1 Insufficient cpu, 1 node(s) had untolerated taint {node-role.kubernetes.io/control-plane: }, 1 node(s) had untolerated taint {node.kubernetes.io/unreachable: }. preemption: 0/3 nodes are available: 1 No preemption victims found for incoming pod, 2 Preemption is not helpful for scheduling..
kubescape       9m16s       Warning   FailedScheduling       pod/kubescape-exporter-29595750-l9s8r                                                    0/3 nodes are available: 1 Insufficient cpu, 1 node(s) had untolerated taint {node-role.kubernetes.io/control-plane: }, 1 node(s) had untolerated taint {node.kubernetes.io/unreachable: }. preemption: 0/3 nodes are available: 1 No preemption victims found for incoming pod, 2 Preemption is not helpful for scheduling..
trivy-system    35m         Warning   FailedScheduling       pod/scan-vulnerabilityreport-77f7dd7f54-tm62v                                            skip schedule deleting pod: trivy-system/scan-vulnerabilityreport-77f7dd7f54-tm62v
kubescape       22m         Warning   FailedScheduling       pod/kubescape-exporter-29595755-knrdh                                                    0/3 nodes are available: 1 Insufficient cpu, 1 node(s) had untolerated taint {node-role.kubernetes.io/control-plane: }, 1 node(s) had untolerated taint {node.kubernetes.io/unreachable: }. preemption: 0/3 nodes are available: 1 No preemption victims found for incoming pod, 2 Preemption is not helpful for scheduling..
kubescape       9m16s       Warning   FailedScheduling       pod/kubescape-exporter-29595755-knrdh                                                    0/3 nodes are available: 1 Insufficient cpu, 1 node(s) had untolerated taint {node-role.kubernetes.io/control-plane: }, 1 node(s) had untolerated taint {node.kubernetes.io/unreachable: }. preemption: 0/3 nodes are available: 1 No preemption victims found for incoming pod, 2 Preemption is not helpful for scheduling..
trivy-system    39m         Warning   FailedScheduling       pod/scan-vulnerabilityreport-77f7dd7f54-tm62v                                            0/3 nodes are available: 1 Insufficient cpu, 1 node(s) had untolerated taint {node-role.kubernetes.io/control-plane: }, 1 node(s) had untolerated taint {node.kubernetes.io/unreachable: }. preemption: 0/3 nodes are available: 1 No preemption victims found for incoming pod, 2 Preemption is not helpful for scheduling..
kubescape       17m         Warning   FailedScheduling       pod/kubescape-exporter-29595760-l76ch                                                    0/3 nodes are available: 1 Insufficient cpu, 1 node(s) had untolerated taint {node-role.kubernetes.io/control-plane: }, 1 node(s) had untolerated taint {node.kubernetes.io/unreachable: }. preemption: 0/3 nodes are available: 1 No preemption victims found for incoming pod, 2 Preemption is not helpful for scheduling..
kubescape       9m15s       Warning   FailedScheduling       pod/kubescape-exporter-29595760-l76ch                                                    0/3 nodes are available: 1 Insufficient cpu, 1 node(s) had untolerated taint {node-role.kubernetes.io/control-plane: }, 1 node(s) had untolerated taint {node.kubernetes.io/unreachable: }. preemption: 0/3 nodes are available: 1 No preemption victims found for incoming pod, 2 Preemption is not helpful for scheduling..
trivy-system    45m         Warning   FailedScheduling       pod/scan-vulnerabilityreport-77f7dd7f54-tm62v                                            0/3 nodes are available: 1 Insufficient cpu, 1 node(s) had untolerated taint {node-role.kubernetes.io/control-plane: }, 1 node(s) had untolerated taint {node.kubernetes.io/unreachable: }. preemption: 0/3 nodes are available: 1 No preemption victims found for incoming pod, 2 Preemption is not helpful for scheduling..
kubescape       12m         Warning   FailedScheduling       pod/kubescape-exporter-29595765-bb4zs                                                    0/3 nodes are available: 1 Insufficient cpu, 1 node(s) had untolerated taint {node-role.kubernetes.io/control-plane: }, 1 node(s) had untolerated taint {node.kubernetes.io/unreachable: }. preemption: 0/3 nodes are available: 1 No preemption victims found for incoming pod, 2 Preemption is not helpful for scheduling..
kubescape       4m13s       Warning   FailedScheduling       pod/kubescape-exporter-29595765-bb4zs                                                    0/3 nodes are available: 1 Insufficient cpu, 1 node(s) had untolerated taint {node-role.kubernetes.io/control-plane: }, 1 node(s) had untolerated taint {node.kubernetes.io/unreachable: }. preemption: 0/3 nodes are available: 1 No preemption victims found for incoming pod, 2 Preemption is not helpful for scheduling..
trivy-system    35m         Warning   FailedScheduling       pod/scan-vulnerabilityreport-77f79dcdbf-zvkv2                                            skip schedule deleting pod: trivy-system/scan-vulnerabilityreport-77f79dcdbf-zvkv2
kubescape       7m3s        Warning   FailedScheduling       pod/kubescape-exporter-29595770-jpxs9                                                    0/3 nodes are available: 1 Insufficient cpu, 1 node(s) had untolerated taint {node-role.kubernetes.io/control-plane: }, 1 node(s) had untolerated taint {node.kubernetes.io/unreachable: }. preemption: 0/3 nodes are available: 1 No preemption victims found for incoming pod, 2 Preemption is not helpful for scheduling..
kubescape       103s        Warning   FailedScheduling       pod/kubescape-exporter-29595770-jpxs9                                                    0/3 nodes are available: 1 Insufficient cpu, 1 node(s) had untolerated taint {node-role.kubernetes.io/control-plane: }, 1 node(s) had untolerated taint {node.kubernetes.io/unreachable: }. preemption: 0/3 nodes are available: 1 No preemption victims found for incoming pod, 2 Preemption is not helpful for scheduling..
trivy-system    39m         Warning   FailedScheduling       pod/scan-vulnerabilityreport-77f79dcdbf-zvkv2                                            0/3 nodes are available: 1 Insufficient cpu, 1 node(s) had untolerated taint {node-role.kubernetes.io/control-plane: }, 1 node(s) had untolerated taint {node.kubernetes.io/unreachable: }. preemption: 0/3 nodes are available: 1 No preemption victims found for incoming pod, 2 Preemption is not helpful for scheduling..
kubescape       2m4s        Warning   FailedScheduling       pod/kubescape-exporter-29595775-w8jdb                                                    0/3 nodes are available: 1 Insufficient cpu, 1 node(s) had untolerated taint {node-role.kubernetes.io/control-plane: }, 1 node(s) had untolerated taint {node.kubernetes.io/unreachable: }. preemption: 0/3 nodes are available: 1 No preemption victims found for incoming pod, 2 Preemption is not helpful for scheduling..
trivy-system    45m         Warning   FailedScheduling       pod/scan-vulnerabilityreport-77f79dcdbf-zvkv2                                            0/3 nodes are available: 1 Insufficient cpu, 1 node(s) had untolerated taint {node-role.kubernetes.io/control-plane: }, 1 node(s) had untolerated taint {node.kubernetes.io/unreachable: }. preemption: 0/3 nodes are available: 1 No preemption victims found for incoming pod, 2 Preemption is not helpful for scheduling..
trivy-system    15m         Warning   FailedScheduling       pod/scan-vulnerabilityreport-74b9cf67dd-llgpd                                            skip schedule deleting pod: trivy-system/scan-vulnerabilityreport-74b9cf67dd-llgpd
kubescape       9m16s       Warning   FailedScheduling       pod/kubevuln-58b477c895-25bfr                                                            0/3 nodes are available: 1 Insufficient cpu, 1 Insufficient memory, 1 node(s) had untolerated taint {node-role.kubernetes.io/control-plane: }, 1 node(s) had untolerated taint {node.kubernetes.io/unreachable: }. preemption: 0/3 nodes are available: 1 No preemption victims found for incoming pod, 2 Preemption is not helpful for scheduling..
trivy-system    19m         Warning   FailedScheduling       pod/scan-vulnerabilityreport-74b9cf67dd-llgpd                                            0/3 nodes are available: 1 Insufficient cpu, 1 node(s) had untolerated taint {node-role.kubernetes.io/control-plane: }, 1 node(s) had untolerated taint {node.kubernetes.io/unreachable: }. preemption: 0/3 nodes are available: 1 No preemption victims found for incoming pod, 2 Preemption is not helpful for scheduling..
trivy-system    25m         Warning   FailedScheduling       pod/scan-vulnerabilityreport-74b9cf67dd-llgpd                                            0/3 nodes are available: 1 Insufficient cpu, 1 node(s) had untolerated taint {node-role.kubernetes.io/control-plane: }, 1 node(s) had untolerated taint {node.kubernetes.io/unreachable: }. preemption: 0/3 nodes are available: 1 No preemption victims found for incoming pod, 2 Preemption is not helpful for scheduling..
trivy-system    45m         Warning   FailedScheduling       pod/scan-vulnerabilityreport-67c5cf994-lgwts                                             skip schedule deleting pod: trivy-system/scan-vulnerabilityreport-67c5cf994-lgwts
trivy-system    49m         Warning   FailedScheduling       pod/scan-vulnerabilityreport-67c5cf994-lgwts                                             0/3 nodes are available: 1 Insufficient cpu, 1 node(s) had untolerated taint {node-role.kubernetes.io/control-plane: }, 1 node(s) had untolerated taint {node.kubernetes.io/unreachable: }. preemption: 0/3 nodes are available: 1 No preemption victims found for incoming pod, 2 Preemption is not helpful for scheduling..
logging         57m         Normal    Scheduled              pod/trivy-elk-exporter-29595720-shrgc                                                    Successfully assigned logging/trivy-elk-exporter-29595720-shrgc to k8s-node-1
trivy-system    55m         Warning   FailedScheduling       pod/scan-vulnerabilityreport-67c5cf994-lgwts                                             0/3 nodes are available: 1 Insufficient cpu, 1 node(s) had untolerated taint {node-role.kubernetes.io/control-plane: }, 1 node(s) had untolerated taint {node.kubernetes.io/unreachable: }. preemption: 0/3 nodes are available: 1 No preemption victims found for incoming pod, 2 Preemption is not helpful for scheduling..
trivy-system    13s         Warning   FailedScheduling       pod/scan-vulnerabilityreport-666f6856cf-5kh2z                                            0/3 nodes are available: 1 Insufficient cpu, 1 node(s) had untolerated taint {node-role.kubernetes.io/control-plane: }, 1 node(s) had untolerated taint {node.kubernetes.io/unreachable: }. preemption: 0/3 nodes are available: 1 No preemption victims found for incoming pod, 2 Preemption is not helpful for scheduling..
trivy-system    5m42s       Warning   FailedScheduling       pod/scan-vulnerabilityreport-666f6856cf-5kh2z                                            0/3 nodes are available: 1 Insufficient cpu, 1 node(s) had untolerated taint {node-role.kubernetes.io/control-plane: }, 1 node(s) had untolerated taint {node.kubernetes.io/unreachable: }. preemption: 0/3 nodes are available: 1 No preemption victims found for incoming pod, 2 Preemption is not helpful for scheduling..
trivy-system    25m         Warning   FailedScheduling       pod/scan-vulnerabilityreport-654f4f6d7f-g2t88                                            skip schedule deleting pod: trivy-system/scan-vulnerabilityreport-654f4f6d7f-g2t88
trivy-system    29m         Warning   FailedScheduling       pod/scan-vulnerabilityreport-654f4f6d7f-g2t88                                            0/3 nodes are available: 1 Insufficient cpu, 1 node(s) had untolerated taint {node-role.kubernetes.io/control-plane: }, 1 node(s) had untolerated taint {node.kubernetes.io/unreachable: }. preemption: 0/3 nodes are available: 1 No preemption victims found for incoming pod, 2 Preemption is not helpful for scheduling..
trivy-system    35m         Warning   FailedScheduling       pod/scan-vulnerabilityreport-654f4f6d7f-g2t88                                            0/3 nodes are available: 1 Insufficient cpu, 1 node(s) had untolerated taint {node-role.kubernetes.io/control-plane: }, 1 node(s) had untolerated taint {node.kubernetes.io/unreachable: }. preemption: 0/3 nodes are available: 1 No preemption victims found for incoming pod, 2 Preemption is not helpful for scheduling..
trivy-system    46m         Warning   FailedScheduling       pod/scan-vulnerabilityreport-649c4d6ddb-b7n8q                                            skip schedule deleting pod: trivy-system/scan-vulnerabilityreport-649c4d6ddb-b7n8q
trivy-system    49m         Warning   FailedScheduling       pod/scan-vulnerabilityreport-649c4d6ddb-b7n8q                                            0/3 nodes are available: 1 Insufficient cpu, 1 node(s) had untolerated taint {node-role.kubernetes.io/control-plane: }, 1 node(s) had untolerated taint {node.kubernetes.io/unreachable: }. preemption: 0/3 nodes are available: 1 No preemption victims found for incoming pod, 2 Preemption is not helpful for scheduling..
logging         47m         Normal    Scheduled              pod/trivy-elk-exporter-29595730-qt457                                                    Successfully assigned logging/trivy-elk-exporter-29595730-qt457 to k8s-node-1
trivy-system    56m         Warning   FailedScheduling       pod/scan-vulnerabilityreport-649c4d6ddb-b7n8q                                            0/3 nodes are available: 1 Insufficient cpu, 1 node(s) had untolerated taint {node-role.kubernetes.io/control-plane: }, 1 node(s) had untolerated taint {node.kubernetes.io/unreachable: }. preemption: 0/3 nodes are available: 1 No preemption victims found for incoming pod, 2 Preemption is not helpful for scheduling..
trivy-system    2m43s       Warning   FailedScheduling       pod/node-collector-694c47444-xsrd6                                                       0/3 nodes are available: 1 node(s) didn't match Pod's node affinity/selector, 1 node(s) had untolerated taint {node-role.kubernetes.io/control-plane: }, 1 node(s) had untolerated taint {node.kubernetes.io/unreachable: }. preemption: 0/3 nodes are available: 3 Preemption is not helpful for scheduling..
trivy-system    7m46s       Warning   FailedScheduling       pod/node-collector-694c47444-xsrd6                                                       0/3 nodes are available: 1 node(s) didn't match Pod's node affinity/selector, 1 node(s) had untolerated taint {node-role.kubernetes.io/control-plane: }, 1 node(s) had untolerated taint {node.kubernetes.io/unreachable: }. preemption: 0/3 nodes are available: 3 Preemption is not helpful for scheduling..
trivy-system    28m         Warning   FailedScheduling       pod/node-collector-694c47444-t4t5p                                                       skip schedule deleting pod: trivy-system/node-collector-694c47444-t4t5p
trivy-system    33m         Warning   FailedScheduling       pod/node-collector-694c47444-t4t5p                                                       0/3 nodes are available: 1 node(s) didn't match Pod's node affinity/selector, 1 node(s) had untolerated taint {node-role.kubernetes.io/control-plane: }, 1 node(s) had untolerated taint {node.kubernetes.io/unreachable: }. preemption: 0/3 nodes are available: 3 Preemption is not helpful for scheduling..
trivy-system    38m         Warning   FailedScheduling       pod/node-collector-694c47444-t4t5p                                                       0/3 nodes are available: 1 node(s) didn't match Pod's node affinity/selector, 1 node(s) had untolerated taint {node-role.kubernetes.io/control-plane: }, 1 node(s) had untolerated taint {node.kubernetes.io/unreachable: }. preemption: 0/3 nodes are available: 3 Preemption is not helpful for scheduling..
trivy-system    59m         Warning   FailedScheduling       pod/node-collector-694c47444-hsdhh                                                       skip schedule deleting pod: trivy-system/node-collector-694c47444-hsdhh
trivy-system    8m3s        Warning   FailedScheduling       pod/node-collector-694c47444-gmn9v                                                       skip schedule deleting pod: trivy-system/node-collector-694c47444-gmn9v
logging         37m         Normal    Scheduled              pod/trivy-elk-exporter-29595740-d8nx7                                                    Successfully assigned logging/trivy-elk-exporter-29595740-d8nx7 to k8s-node-1
trivy-system    12m         Warning   FailedScheduling       pod/node-collector-694c47444-gmn9v                                                       0/3 nodes are available: 1 node(s) didn't match Pod's node affinity/selector, 1 node(s) had untolerated taint {node-role.kubernetes.io/control-plane: }, 1 node(s) had untolerated taint {node.kubernetes.io/unreachable: }. preemption: 0/3 nodes are available: 3 Preemption is not helpful for scheduling..
trivy-system    18m         Warning   FailedScheduling       pod/node-collector-694c47444-gmn9v                                                       0/3 nodes are available: 1 node(s) didn't match Pod's node affinity/selector, 1 node(s) had untolerated taint {node-role.kubernetes.io/control-plane: }, 1 node(s) had untolerated taint {node.kubernetes.io/unreachable: }. preemption: 0/3 nodes are available: 3 Preemption is not helpful for scheduling..
trivy-system    18m         Warning   FailedScheduling       pod/node-collector-694c47444-c82fq                                                       skip schedule deleting pod: trivy-system/node-collector-694c47444-c82fq
trivy-system    23m         Warning   FailedScheduling       pod/node-collector-694c47444-c82fq                                                       0/3 nodes are available: 1 node(s) didn't match Pod's node affinity/selector, 1 node(s) had untolerated taint {node-role.kubernetes.io/control-plane: }, 1 node(s) had untolerated taint {node.kubernetes.io/unreachable: }. preemption: 0/3 nodes are available: 3 Preemption is not helpful for scheduling..
trivy-system    28m         Warning   FailedScheduling       pod/node-collector-694c47444-c82fq                                                       0/3 nodes are available: 1 node(s) didn't match Pod's node affinity/selector, 1 node(s) had untolerated taint {node-role.kubernetes.io/control-plane: }, 1 node(s) had untolerated taint {node.kubernetes.io/unreachable: }. preemption: 0/3 nodes are available: 3 Preemption is not helpful for scheduling..
trivy-system    38m         Warning   FailedScheduling       pod/node-collector-694c47444-4hqw6                                                       skip schedule deleting pod: trivy-system/node-collector-694c47444-4hqw6
trivy-system    43m         Warning   FailedScheduling       pod/node-collector-694c47444-4hqw6                                                       0/3 nodes are available: 1 node(s) didn't match Pod's node affinity/selector, 1 node(s) had untolerated taint {node-role.kubernetes.io/control-plane: }, 1 node(s) had untolerated taint {node.kubernetes.io/unreachable: }. preemption: 0/3 nodes are available: 3 Preemption is not helpful for scheduling..
trivy-system    48m         Warning   FailedScheduling       pod/node-collector-694c47444-4hqw6                                                       0/3 nodes are available: 1 node(s) didn't match Pod's node affinity/selector, 1 node(s) had untolerated taint {node-role.kubernetes.io/control-plane: }, 1 node(s) had untolerated taint {node.kubernetes.io/unreachable: }. preemption: 0/3 nodes are available: 3 Preemption is not helpful for scheduling..
logging         27m         Normal    Scheduled              pod/trivy-elk-exporter-29595750-m82sq                                                    Successfully assigned logging/trivy-elk-exporter-29595750-m82sq to k8s-node-1
trivy-system    49m         Warning   FailedScheduling       pod/node-collector-694c47444-227fd                                                       skip schedule deleting pod: trivy-system/node-collector-694c47444-227fd
trivy-system    53m         Warning   FailedScheduling       pod/node-collector-694c47444-227fd                                                       0/3 nodes are available: 1 node(s) didn't match Pod's node affinity/selector, 1 node(s) had untolerated taint {node-role.kubernetes.io/control-plane: }, 1 node(s) had untolerated taint {node.kubernetes.io/unreachable: }. preemption: 0/3 nodes are available: 3 Preemption is not helpful for scheduling..
trivy-system    59m         Warning   FailedScheduling       pod/node-collector-694c47444-227fd                                                       0/3 nodes are available: 1 node(s) didn't match Pod's node affinity/selector, 1 node(s) had untolerated taint {node-role.kubernetes.io/control-plane: }, 1 node(s) had untolerated taint {node.kubernetes.io/unreachable: }. preemption: 0/3 nodes are available: 3 Preemption is not helpful for scheduling..
logging         7m3s        Normal    Scheduled              pod/trivy-elk-exporter-29595770-6vftz                                                    Successfully assigned logging/trivy-elk-exporter-29595770-6vftz to k8s-node-1
logging         17m         Normal    Scheduled              pod/trivy-elk-exporter-29595760-nhsl9                                                    Successfully assigned logging/trivy-elk-exporter-29595760-nhsl9 to k8s-node-1
logging         60m         Warning   BackoffLimitExceeded   job/trivy-elk-exporter-29595710                                                          Job has reached the specified backoff limit
logging         60m         Normal    SawCompletedJob        cronjob/trivy-elk-exporter                                                               Saw completed job: trivy-elk-exporter-29595710, status: Failed
logging         60m         Normal    SuccessfulDelete       cronjob/trivy-elk-exporter                                                               Deleted job trivy-elk-exporter-29595680
logging         60m         Normal    SuccessfulDelete       job/trivy-elk-exporter-29595710                                                          Deleted pod: trivy-elk-exporter-29595710-l4xkf
trivy-system    59m         Normal    SuccessfulDelete       job/node-collector-694c47444                                                             Deleted pod: node-collector-694c47444-hsdhh
trivy-system    59m         Warning   DeadlineExceeded       job/node-collector-694c47444                                                             Job was active longer than specified deadline
trivy-system    59m         Normal    SuccessfulCreate       job/node-collector-694c47444                                                             Created pod: node-collector-694c47444-227fd
kubescape       57m         Normal    SuccessfulCreate       job/kubescape-exporter-29595720                                                          Created pod: kubescape-exporter-29595720-trg4r
logging         57m         Normal    SuccessfulCreate       job/trivy-elk-exporter-29595720                                                          Created pod: trivy-elk-exporter-29595720-shrgc
logging         57m         Normal    AddedInterface         pod/trivy-elk-exporter-29595720-shrgc                                                    Add eth0 [192.168.109.101/32] from k8s-pod-network
trivy-system    56m         Warning   DeadlineExceeded       job/scan-vulnerabilityreport-8585759d76                                                  Job was active longer than specified deadline
trivy-system    56m         Normal    SuccessfulDelete       job/scan-vulnerabilityreport-8585759d76                                                  Deleted pod: scan-vulnerabilityreport-8585759d76-bxrqt
trivy-system    56m         Normal    SuccessfulDelete       job/scan-vulnerabilityreport-c7b79b858                                                   Deleted pod: scan-vulnerabilityreport-c7b79b858-5cqj8
trivy-system    56m         Warning   DeadlineExceeded       job/scan-vulnerabilityreport-c7b79b858                                                   Job was active longer than specified deadline
trivy-system    56m         Normal    SuccessfulCreate       job/scan-vulnerabilityreport-649c4d6ddb                                                  Created pod: scan-vulnerabilityreport-649c4d6ddb-b7n8q
trivy-system    55m         Normal    SuccessfulCreate       job/scan-vulnerabilityreport-67c5cf994                                                   Created pod: scan-vulnerabilityreport-67c5cf994-lgwts
logging         54m         Normal    Pulled                 pod/trivy-elk-exporter-29595720-shrgc                                                    Container image "alpine:3.19" already present on machine
logging         54m         Normal    Created                pod/trivy-elk-exporter-29595720-shrgc                                                    Created container exporter
logging         54m         Normal    Started                pod/trivy-elk-exporter-29595720-shrgc                                                    Started container exporter
kubescape       52m         Normal    SuccessfulCreate       job/kubescape-exporter-29595725                                                          Created pod: kubescape-exporter-29595725-ckl8n
logging         51m         Warning   BackOff                pod/trivy-elk-exporter-29595720-shrgc                                                    Back-off restarting failed container exporter in pod trivy-elk-exporter-29595720-shrgc_logging(c2ee04c6-90aa-41f4-ad03-1258267a0d93)
logging         49m         Normal    SuccessfulDelete       job/trivy-elk-exporter-29595720                                                          Deleted pod: trivy-elk-exporter-29595720-shrgc
logging         49m         Normal    SuccessfulDelete       cronjob/trivy-elk-exporter                                                               Deleted job trivy-elk-exporter-29595690
logging         49m         Normal    SawCompletedJob        cronjob/trivy-elk-exporter                                                               Saw completed job: trivy-elk-exporter-29595720, status: Failed
logging         49m         Warning   BackoffLimitExceeded   job/trivy-elk-exporter-29595720                                                          Job has reached the specified backoff limit
kube-system     49m         Warning   Unhealthy              pod/kube-apiserver-k8s-master                                                            Readiness probe failed: HTTP probe failed with statuscode: 500
trivy-system    49m         Normal    SuccessfulDelete       job/node-collector-694c47444                                                             Deleted pod: node-collector-694c47444-227fd
trivy-system    49m         Warning   DeadlineExceeded       job/node-collector-694c47444                                                             Job was active longer than specified deadline
trivy-system    48m         Normal    SuccessfulCreate       job/node-collector-694c47444                                                             Created pod: node-collector-694c47444-4hqw6
logging         47m         Normal    SuccessfulCreate       job/trivy-elk-exporter-29595730                                                          Created pod: trivy-elk-exporter-29595730-qt457
kubescape       47m         Normal    SuccessfulCreate       job/kubescape-exporter-29595730                                                          Created pod: kubescape-exporter-29595730-28r7g
logging         47m         Normal    AddedInterface         pod/trivy-elk-exporter-29595730-qt457                                                    Add eth0 [192.168.109.82/32] from k8s-pod-network
trivy-system    46m         Normal    SuccessfulDelete       job/scan-vulnerabilityreport-649c4d6ddb                                                  Deleted pod: scan-vulnerabilityreport-649c4d6ddb-b7n8q
trivy-system    46m         Warning   DeadlineExceeded       job/scan-vulnerabilityreport-649c4d6ddb                                                  Job was active longer than specified deadline
trivy-system    45m         Normal    SuccessfulDelete       job/scan-vulnerabilityreport-67c5cf994                                                   Deleted pod: scan-vulnerabilityreport-67c5cf994-lgwts
trivy-system    45m         Warning   DeadlineExceeded       job/scan-vulnerabilityreport-67c5cf994                                                   Job was active longer than specified deadline
trivy-system    45m         Normal    SuccessfulCreate       job/scan-vulnerabilityreport-77f7dd7f54                                                  Created pod: scan-vulnerabilityreport-77f7dd7f54-tm62v
trivy-system    45m         Normal    SuccessfulCreate       job/scan-vulnerabilityreport-77f79dcdbf                                                  Created pod: scan-vulnerabilityreport-77f79dcdbf-zvkv2
logging         44m         Normal    Created                pod/trivy-elk-exporter-29595730-qt457                                                    Created container exporter
logging         44m         Normal    Pulled                 pod/trivy-elk-exporter-29595730-qt457                                                    Container image "alpine:3.19" already present on machine
logging         44m         Normal    Started                pod/trivy-elk-exporter-29595730-qt457                                                    Started container exporter
kubescape       42m         Normal    SuccessfulCreate       job/kubescape-exporter-29595735                                                          Created pod: kubescape-exporter-29595735-wbn76
logging         41m         Warning   BackOff                pod/trivy-elk-exporter-29595730-qt457                                                    Back-off restarting failed container exporter in pod trivy-elk-exporter-29595730-qt457_logging(6a8721e7-a935-4474-9742-1a0eb0545897)
logging         40m         Normal    SuccessfulDelete       job/trivy-elk-exporter-29595730                                                          Deleted pod: trivy-elk-exporter-29595730-qt457
logging         40m         Normal    SawCompletedJob        cronjob/trivy-elk-exporter                                                               Saw completed job: trivy-elk-exporter-29595730, status: Failed
logging         40m         Warning   BackoffLimitExceeded   job/trivy-elk-exporter-29595730                                                          Job has reached the specified backoff limit
logging         40m         Normal    SuccessfulDelete       cronjob/trivy-elk-exporter                                                               Deleted job trivy-elk-exporter-29595700
trivy-system    38m         Warning   DeadlineExceeded       job/node-collector-694c47444                                                             Job was active longer than specified deadline
trivy-system    38m         Normal    SuccessfulDelete       job/node-collector-694c47444                                                             Deleted pod: node-collector-694c47444-4hqw6
trivy-system    38m         Normal    SuccessfulCreate       job/node-collector-694c47444                                                             Created pod: node-collector-694c47444-t4t5p
kubescape       37m         Normal    SuccessfulCreate       job/kubescape-exporter-29595740                                                          Created pod: kubescape-exporter-29595740-2n28f
logging         37m         Normal    SuccessfulCreate       job/trivy-elk-exporter-29595740                                                          Created pod: trivy-elk-exporter-29595740-d8nx7
logging         37m         Normal    AddedInterface         pod/trivy-elk-exporter-29595740-d8nx7                                                    Add eth0 [192.168.109.87/32] from k8s-pod-network
trivy-system    35m         Warning   DeadlineExceeded       job/scan-vulnerabilityreport-77f7dd7f54                                                  Job was active longer than specified deadline
trivy-system    35m         Normal    SuccessfulDelete       job/scan-vulnerabilityreport-77f7dd7f54                                                  Deleted pod: scan-vulnerabilityreport-77f7dd7f54-tm62v
trivy-system    35m         Warning   DeadlineExceeded       job/scan-vulnerabilityreport-77f79dcdbf                                                  Job was active longer than specified deadline
trivy-system    35m         Normal    SuccessfulDelete       job/scan-vulnerabilityreport-77f79dcdbf                                                  Deleted pod: scan-vulnerabilityreport-77f79dcdbf-zvkv2
trivy-system    35m         Normal    SuccessfulCreate       job/scan-vulnerabilityreport-654f4f6d7f                                                  Created pod: scan-vulnerabilityreport-654f4f6d7f-g2t88
trivy-system    35m         Normal    SuccessfulCreate       job/scan-vulnerabilityreport-7c9ddd97bf                                                  Created pod: scan-vulnerabilityreport-7c9ddd97bf-fg65z
trivy-system    35m         Normal    SuccessfulCreate       job/scan-vulnerabilityreport-f8bcff7cd                                                   Created pod: scan-vulnerabilityreport-f8bcff7cd-vqtxj
logging         34m         Normal    Created                pod/trivy-elk-exporter-29595740-d8nx7                                                    Created container exporter
logging         34m         Normal    Pulled                 pod/trivy-elk-exporter-29595740-d8nx7                                                    Container image "alpine:3.19" already present on machine
logging         34m         Normal    Started                pod/trivy-elk-exporter-29595740-d8nx7                                                    Started container exporter
kubescape       32m         Normal    SuccessfulCreate       job/kubescape-exporter-29595745                                                          Created pod: kubescape-exporter-29595745-pr6js
logging         32m         Warning   BackOff                pod/trivy-elk-exporter-29595740-d8nx7                                                    Back-off restarting failed container exporter in pod trivy-elk-exporter-29595740-d8nx7_logging(21b3c474-0243-4d79-b367-0bc50721b990)
logging         30m         Normal    SawCompletedJob        cronjob/trivy-elk-exporter                                                               Saw completed job: trivy-elk-exporter-29595740, status: Failed
logging         30m         Normal    SuccessfulDelete       job/trivy-elk-exporter-29595740                                                          Deleted pod: trivy-elk-exporter-29595740-d8nx7
logging         30m         Warning   BackoffLimitExceeded   job/trivy-elk-exporter-29595740                                                          Job has reached the specified backoff limit
logging         30m         Normal    SuccessfulDelete       cronjob/trivy-elk-exporter                                                               Deleted job trivy-elk-exporter-29595710
trivy-system    28m         Normal    SuccessfulDelete       job/node-collector-694c47444                                                             Deleted pod: node-collector-694c47444-t4t5p
trivy-system    28m         Warning   DeadlineExceeded       job/node-collector-694c47444                                                             Job was active longer than specified deadline
trivy-system    28m         Normal    SuccessfulCreate       job/node-collector-694c47444                                                             Created pod: node-collector-694c47444-c82fq
logging         27m         Normal    SuccessfulCreate       job/trivy-elk-exporter-29595750                                                          Created pod: trivy-elk-exporter-29595750-m82sq
kubescape       27m         Normal    SuccessfulCreate       job/kubescape-exporter-29595750                                                          Created pod: kubescape-exporter-29595750-l9s8r
logging         27m         Normal    AddedInterface         pod/trivy-elk-exporter-29595750-m82sq                                                    Add eth0 [192.168.109.96/32] from k8s-pod-network
trivy-system    25m         Warning   DeadlineExceeded       job/scan-vulnerabilityreport-654f4f6d7f                                                  Job was active longer than specified deadline
trivy-system    25m         Normal    SuccessfulDelete       job/scan-vulnerabilityreport-654f4f6d7f                                                  Deleted pod: scan-vulnerabilityreport-654f4f6d7f-g2t88
trivy-system    25m         Normal    SuccessfulDelete       job/scan-vulnerabilityreport-f8bcff7cd                                                   Deleted pod: scan-vulnerabilityreport-f8bcff7cd-vqtxj
trivy-system    25m         Warning   DeadlineExceeded       job/scan-vulnerabilityreport-7c9ddd97bf                                                  Job was active longer than specified deadline
trivy-system    25m         Normal    SuccessfulDelete       job/scan-vulnerabilityreport-7c9ddd97bf                                                  Deleted pod: scan-vulnerabilityreport-7c9ddd97bf-fg65z
trivy-system    25m         Warning   DeadlineExceeded       job/scan-vulnerabilityreport-f8bcff7cd                                                   Job was active longer than specified deadline
trivy-system    25m         Normal    SuccessfulCreate       job/scan-vulnerabilityreport-74b9cf67dd                                                  Created pod: scan-vulnerabilityreport-74b9cf67dd-llgpd
trivy-system    25m         Normal    SuccessfulCreate       job/scan-vulnerabilityreport-d778d5cc4                                                   Created pod: scan-vulnerabilityreport-d778d5cc4-277zj
logging         24m         Normal    Pulled                 pod/trivy-elk-exporter-29595750-m82sq                                                    Container image "alpine:3.19" already present on machine
logging         24m         Normal    Created                pod/trivy-elk-exporter-29595750-m82sq                                                    Created container exporter
logging         24m         Normal    Started                pod/trivy-elk-exporter-29595750-m82sq                                                    Started container exporter
kubescape       22m         Warning   BackOff                pod/node-agent-z5lxn                                                                     Back-off restarting failed container node-agent in pod node-agent-z5lxn_kubescape(166492b7-49ca-46f3-a6a5-b2d5e65beffe)
kubescape       22m         Normal    SuccessfulCreate       job/kubescape-exporter-29595755                                                          Created pod: kubescape-exporter-29595755-knrdh
logging         21m         Warning   BackOff                pod/trivy-elk-exporter-29595750-m82sq                                                    Back-off restarting failed container exporter in pod trivy-elk-exporter-29595750-m82sq_logging(a45f12f5-0f1d-4d92-a09c-4355ba037c17)
logging         19m         Normal    SuccessfulDelete       job/trivy-elk-exporter-29595750                                                          Deleted pod: trivy-elk-exporter-29595750-m82sq
logging         19m         Normal    SawCompletedJob        cronjob/trivy-elk-exporter                                                               Saw completed job: trivy-elk-exporter-29595750, status: Failed
logging         19m         Warning   BackoffLimitExceeded   job/trivy-elk-exporter-29595750                                                          Job has reached the specified backoff limit
logging         19m         Normal    SuccessfulDelete       cronjob/trivy-elk-exporter                                                               Deleted job trivy-elk-exporter-29595720
trivy-system    18m         Normal    SuccessfulDelete       job/node-collector-694c47444                                                             Deleted pod: node-collector-694c47444-c82fq
trivy-system    18m         Warning   DeadlineExceeded       job/node-collector-694c47444                                                             Job was active longer than specified deadline
trivy-system    18m         Normal    SuccessfulCreate       job/node-collector-694c47444                                                             Created pod: node-collector-694c47444-gmn9v
kubescape       17m         Normal    SuccessfulCreate       job/kubescape-exporter-29595760                                                          Created pod: kubescape-exporter-29595760-l76ch
logging         17m         Normal    SuccessfulCreate       job/trivy-elk-exporter-29595760                                                          Created pod: trivy-elk-exporter-29595760-nhsl9
logging         17m         Normal    AddedInterface         pod/trivy-elk-exporter-29595760-nhsl9                                                    Add eth0 [192.168.109.70/32] from k8s-pod-network
falco           16m         Warning   Unhealthy              pod/falco-falcosidekick-64544d9f9c-dh9dh                                                 Liveness probe failed: Get "http://192.168.109.75:2801/ping": context deadline exceeded (Client.Timeout exceeded while awaiting headers)
trivy-system    15m         Normal    SuccessfulDelete       job/scan-vulnerabilityreport-74b9cf67dd                                                  Deleted pod: scan-vulnerabilityreport-74b9cf67dd-llgpd
trivy-system    15m         Normal    SuccessfulDelete       job/scan-vulnerabilityreport-d778d5cc4                                                   Deleted pod: scan-vulnerabilityreport-d778d5cc4-277zj
trivy-system    15m         Warning   DeadlineExceeded       job/scan-vulnerabilityreport-d778d5cc4                                                   Job was active longer than specified deadline
trivy-system    15m         Warning   DeadlineExceeded       job/scan-vulnerabilityreport-74b9cf67dd                                                  Job was active longer than specified deadline
trivy-system    15m         Normal    SuccessfulCreate       job/scan-vulnerabilityreport-8585759d76                                                  Created pod: scan-vulnerabilityreport-8585759d76-d2tg9
trivy-system    15m         Normal    SuccessfulCreate       job/scan-vulnerabilityreport-7d59678b4f                                                  Created pod: scan-vulnerabilityreport-7d59678b4f-x466d
free5gc         15m         Warning   Unhealthy              pod/free5gc-free5gc-nrf-nrf-76f6d8d9c8-fsstf                                             Readiness probe failed: Get "http://192.168.109.114:8000/": context deadline exceeded (Client.Timeout exceeded while awaiting headers)
falco           15m         Warning   Unhealthy              pod/falco-falcosidekick-64544d9f9c-tdjtd                                                 Liveness probe failed: Get "http://192.168.109.124:2801/ping": context deadline exceeded (Client.Timeout exceeded while awaiting headers)
falco           15m         Warning   Unhealthy              pod/falco-falcosidekick-64544d9f9c-tdjtd                                                 Readiness probe failed: Get "http://192.168.109.124:2801/ping": context deadline exceeded (Client.Timeout exceeded while awaiting headers)
logging         14m         Normal    Pulled                 pod/trivy-elk-exporter-29595760-nhsl9                                                    Container image "alpine:3.19" already present on machine
logging         14m         Normal    Created                pod/trivy-elk-exporter-29595760-nhsl9                                                    Created container exporter
logging         14m         Normal    Started                pod/trivy-elk-exporter-29595760-nhsl9                                                    Started container exporter
kubescape       12m         Normal    SuccessfulCreate       job/kubescape-exporter-29595765                                                          Created pod: kubescape-exporter-29595765-bb4zs
logging         11m         Warning   BackOff                pod/trivy-elk-exporter-29595760-nhsl9                                                    Back-off restarting failed container exporter in pod trivy-elk-exporter-29595760-nhsl9_logging(22757bf3-e376-41a9-8ea3-c40224751441)
logging         9m34s       Normal    SuccessfulDelete       job/trivy-elk-exporter-29595760                                                          Deleted pod: trivy-elk-exporter-29595760-nhsl9
logging         9m33s       Normal    SawCompletedJob        cronjob/trivy-elk-exporter                                                               Saw completed job: trivy-elk-exporter-29595760, status: Failed
logging         9m33s       Warning   BackoffLimitExceeded   job/trivy-elk-exporter-29595760                                                          Job has reached the specified backoff limit
logging         9m33s       Normal    SuccessfulDelete       cronjob/trivy-elk-exporter                                                               Deleted job trivy-elk-exporter-29595730
trivy-system    8m4s        Normal    SuccessfulDelete       job/node-collector-694c47444                                                             Deleted pod: node-collector-694c47444-gmn9v
trivy-system    8m3s        Warning   DeadlineExceeded       job/node-collector-694c47444                                                             Job was active longer than specified deadline
trivy-system    7m47s       Normal    SuccessfulCreate       job/node-collector-694c47444                                                             Created pod: node-collector-694c47444-xsrd6
kubescape       7m4s        Normal    SuccessfulCreate       job/kubescape-exporter-29595770                                                          Created pod: kubescape-exporter-29595770-jpxs9
logging         7m4s        Normal    SuccessfulCreate       job/trivy-elk-exporter-29595770                                                          Created pod: trivy-elk-exporter-29595770-6vftz
logging         6m50s       Normal    AddedInterface         pod/trivy-elk-exporter-29595770-6vftz                                                    Add eth0 [192.168.109.68/32] from k8s-pod-network
kubescape       6m14s       Warning   Unhealthy              pod/host-scanner-5ndpd                                                                   Liveness probe failed: Get "http://192.168.235.254:7888/healthz": context deadline exceeded (Client.Timeout exceeded while awaiting headers)
trivy-system    5m50s       Warning   DeadlineExceeded       job/scan-vulnerabilityreport-8585759d76                                                  Job was active longer than specified deadline
trivy-system    5m50s       Normal    SuccessfulDelete       job/scan-vulnerabilityreport-8585759d76                                                  Deleted pod: scan-vulnerabilityreport-8585759d76-d2tg9
trivy-system    5m48s       Warning   DeadlineExceeded       job/scan-vulnerabilityreport-7d59678b4f                                                  Job was active longer than specified deadline
trivy-system    5m48s       Normal    SuccessfulDelete       job/scan-vulnerabilityreport-7d59678b4f                                                  Deleted pod: scan-vulnerabilityreport-7d59678b4f-x466d
trivy-system    5m42s       Normal    SuccessfulCreate       job/scan-vulnerabilityreport-666f6856cf                                                  Created pod: scan-vulnerabilityreport-666f6856cf-5kh2z
trivy-system    5m41s       Normal    SuccessfulCreate       job/scan-vulnerabilityreport-7bf46c5ff8                                                  Created pod: scan-vulnerabilityreport-7bf46c5ff8-pfj67
logging         3m51s       Normal    Pulled                 pod/trivy-elk-exporter-29595770-6vftz                                                    Container image "alpine:3.19" already present on machine
logging         3m50s       Normal    Created                pod/trivy-elk-exporter-29595770-6vftz                                                    Created container exporter
logging         3m49s       Normal    Started                pod/trivy-elk-exporter-29595770-6vftz                                                    Started container exporter
trivy-system    3m25s       Warning   Unhealthy              pod/trivy-operator-6d946f464f-7hkcs                                                      Liveness probe failed: Get "http://192.168.109.73:9090/healthz/": context deadline exceeded (Client.Timeout exceeded while awaiting headers)
trivy-system    3m25s       Warning   Unhealthy              pod/trivy-operator-6d946f464f-7hkcs                                                      Readiness probe failed: Get "http://192.168.109.73:9090/readyz/": context deadline exceeded (Client.Timeout exceeded while awaiting headers)
kubescape       3m23s       Normal    Killing                pod/host-scanner-kg2q4                                                                   Container host-sensor failed liveness probe, will be restarted
kubescape       3m12s       Normal    Pulled                 pod/host-scanner-kg2q4                                                                   Container image "quay.io/kubescape/host-scanner:v1.0.78" already present on machine
kubescape       3m12s       Normal    Created                pod/host-scanner-kg2q4                                                                   Created container host-sensor
kubescape       3m7s        Normal    Started                pod/host-scanner-kg2q4                                                                   Started container host-sensor
kubescape       3m          Warning   Unhealthy              pod/host-scanner-kg2q4                                                                   Startup probe failed: Get "http://192.168.109.90:7888/readyz": dial tcp 192.168.109.90:7888: connect: connection refused
falco           2m59s       Normal    FailedBinding          persistentvolumeclaim/falco-falcosidekick-ui-redis-data-falco-falcosidekick-ui-redis-0   no persistent volumes available for this claim and no storage class is set
kubescape       2m33s       Warning   Unhealthy              pod/node-agent-z5lxn                                                                     Readiness probe failed: HTTP probe failed with statuscode: 500
kubescape       2m6s        Normal    SuccessfulCreate       cronjob/kubescape-exporter                                                               (combined from similar events): Created job kubescape-exporter-29595775
kube-system     2m6s        Warning   Unhealthy              pod/calico-kube-controllers-7cf4688799-srzgq                                             Readiness probe failed: command "/usr/bin/check-status -r" timed out
kubescape       2m5s        Normal    SuccessfulCreate       job/kubescape-exporter-29595775                                                          Created pod: kubescape-exporter-29595775-w8jdb
logging         106s        Warning   BackOff                pod/trivy-elk-exporter-29595770-6vftz                                                    Back-off restarting failed container exporter in pod trivy-elk-exporter-29595770-6vftz_logging(22020f83-0780-46d1-a154-f64fb6280815)
elastic-stack   95s         Warning   Unhealthy              pod/kibana-67d44874f5-slrt8                                                              Readiness probe failed: HTTP probe failed with statuscode: 503
kubescape       13s         Warning   Unhealthy              pod/host-scanner-kg2q4                                                                   Liveness probe failed: Get "http://192.168.109.90:7888/healthz": context deadline exceeded (Client.Timeout exceeded while awaiting headers)
